Workbook
Name TheDate: Comparaison!$Q$1

Sheet BBT3
A1: ID | B1: Column1 | C1: ISIN | D1: Coupon | E1: Maturity | F1: InflationLinked | G1: MASTER_FIXED_INCOME_INSTRUMENT_ID | H1: MASTER_FIXED_INCOME_ID_TYPE | I1: DATE | J1: METRIC_NAME | K1: METRIC_VALUE | L1: CR_TIME | M1: REPLICA_TIME
A2: 912797QX8 | B2: Bill | C2: US912797QX89 | D2: 0 | E2: 46184 | F2: N | G2: US912797QX89 | H2: ISIN | I2: 46177 | J2: PX_ASK | K2: 3.5632000000 | L2: 46177.921 | M2: 46177.921
A3: 912797QX8 | B3: Bill | C3: US912797QX89 | D3: 0 | E3: 46184 | F3: N | G3: US912797QX89 | H3: ISIN | I3: 46177 | J3: YLD_CNV_ASK | K3: 3.61483562 | L3: 46177.919 | M3: 46177.921
A4: 912797QX8 | B4: Bill | C4: US912797QX89 | D4: 0 | E4: 46184 | F4: N | G4: US912797QX89 | H4: ISIN | I4: 46177 | J4: YLD_YTM_BID | K4: 3.63412247 | L4: 46177.919 | M4: 46177.921
A5: 912797QX8 | B5: Bill | C5: US912797QX89 | D5: 0 | E5: 46184 | F5: N | G5: US912797QX89 | H5: ISIN | I5: 46177 | J5: PX_BID | K5: 3.5822000000 | L5: 46177.921 | M5: 46177.921
A6: 912797QX8 | B6: Bill | C6: US912797QX89 | D6: 0 | E6: 46184 | F6: N | G6: US912797QX89 | H6: ISIN | I6: 46177 | J6: YLD_YTM_ASK | K6: 3.61483562 | L6: 46177.919 | M6: 46177.921
A7: 912797QX8 | B7: Bill | C7: US912797QX89 | D7: 0 | E7: 46184 | F7: N | G7: US912797QX89 | H7: ISIN | I7: 46177 | J7: YLD_CNV_BID | K7: 3.63412247 | L7: 46177.919 | M7: 46177.921
A8: 912797RF6 | B8: Bill | C8: US912797RF64 | D8: 0 | E8: 46212 | F8: N | G8: US912797RF64 | H8: ISIN | I8: 46177 | J8: PX_BID | K8: 3.6145000000 | L8: 46177.921 | M8: 46177.921
A9: 912797RF6 | B9: Bill | C9: US912797RF64 | D9: 0 | E9: 46212 | F9: N | G9: US912797RF64 | H9: ISIN | I9: 46177 | J9: PX_ASK | K9: 3.5925000000 | L9: 46177.921 | M9: 46177.921
A10: 912797RG4 | B10: Bill | C10: US912797RG48 | D10: 0 | E10: 46240 | F10: N | G10: US912797RG48 | H10: ISIN | I10: 46177 | J10: PX_ASK | K10: 3.5986000000 | L10: 46177.921 | M10: 46177.921
A11: 912797RG4 | B11: Bill | C11: US912797RG48 | D11: 0 | E11: 46240 | F11: N | G11: US912797RG48 | H11: ISIN | I11: 46177 | J11: PX_BID | K11: 3.6232000000 | L11: 46177.921 | M11: 46177.921
A12: 912797RS8 | B12: Bill | C12: US912797RS85 | D12: 0 | E12: 46268 | F12: N | G12: US912797RS85 | H12: ISIN | I12: 46177 | J12: PX_BID | K12: 3.6267000000 | L12: 46177.921 | M12: 46177.921
A13: 912797RS8 | B13: Bill | C13: US912797RS85 | D13: 0 | E13: 46268 | F13: N | G13: US912797RS85 | H13: ISIN | I13: 46177 | J13: YLD_CNV_ASK | K13: 3.70359064 | L13: 46177.919 | M13: 46177.921
... A2445: 912834QV3 | B2445: Bond | C2445: US912834QV37 | D2445: 0 | E2445: 53646 | F2445: N | G2445: US912834QV37 | H2445: ISIN | I2445: 46177 | J2445: PX_BID | K2445: 34.5007230400 | L2445: 46177.921 | M2445: 46177.921

Sheet QW_Close
A1: ID | B1: Att | C1: Src | D1: Date | E1: Value | F1: Notes | G1: CreatedDate | H1: CreatedBy | I1: ModifiedTime | J1: ModifiedBy
A2: .TWI10 8/36 | B2: Yield | C2: QW | D2: 46177 | E2: 0.04515311 | G2: 46177.669 | H2: MARINERCAPITAL\jmannion | I2: 46177.669 | J2: MARINERCAPITAL\jmannion
A3: .TWI2 5/28 | B3: Yield | C3: QW | D3: 46177 | E3: 0 | G3: 46177.669 | H3: MARINERCAPITAL\jmannion | I3: 46177.669 | J3: MARINERCAPITAL\jmannion
A4: .TWI2 6/28 | B4: Yield | C4: QW | D4: 46177 | E4: 0.040589981 | G4: 46177.669 | H4: MARINERCAPITAL\jmannion | I4: 46177.669 | J4: MARINERCAPITAL\jmannion
A5: .TWI2 7/28 | B5: Yield | C5: QW | D5: 46177 | E5: 0.040692217 | G5: 46177.669 | H5: MARINERCAPITAL\jmannion | I5: 46177.669 | J5: MARINERCAPITAL\jmannion
A6: .TWI2 8/28 | B6: Yield | C6: QW | D6: 46177 | E6: 0.040742196 | G6: 46177.669 | H6: MARINERCAPITAL\jmannion | I6: 46177.669 | J6: MARINERCAPITAL\jmannion
A7: .TWI2 9/28 | B7: Yield | C7: QW | D7: 46177 | E7: 0.040874474 | G7: 46177.669 | H7: MARINERCAPITAL\jmannion | I7: 46177.669 | J7: MARINERCAPITAL\jmannion
A8: .TWI30 8/56 | B8: Yield | C8: QW | D8: 46177 | E8: 0.049950215 | G8: 46177.669 | H8: MARINERCAPITAL\jmannion | I8: 46177.669 | J8: MARINERCAPITAL\jmannion
A9: .TWI7 5/33 | B9: Yield | C9: QW | D9: 46177 | E9: 0 | G9: 46177.669 | H9: MARINERCAPITAL\jmannion | I9: 46177.669 | J9: MARINERCAPITAL\jmannion
A10: .TWI7 6/33 | B10: Yield | C10: QW | D10: 46177 | E10: 0.04340807 | G10: 46177.669 | H10: MARINERCAPITAL\jmannion | I10: 46177.669 | J10: MARINERCAPITAL\jmannion
A11: .TWI7 7/33 | B11: Yield | C11: QW | D11: 46177 | E11: 0.043575094 | G11: 46177.669 | H11: MARINERCAPITAL\jmannion | I11: 46177.669 | J11: MARINERCAPITAL\jmannion
A12: .TWI7 8/33 | B12: Yield | C12: QW | D12: 46177 | E12: 0.043689844 | G12: 46177.669 | H12: MARINERCAPITAL\jmannion | I12: 46177.669 | J12: MARINERCAPITAL\jmannion
A13: 3YM6 | B13: Price | C13: QW | D13: 46177 | E13: 104.98438 | F13: 3YM6 COMDTY:<Price=104.984375> | G13: 46177.778 | H13: MARINER\SilverAdm | I13: 46177.778 | J13: MARINER\SilverAdm
A14: 3YU6 | B14: Price | C14: QW | D14: 46177 | E14: 104.82812 | F14: 3YU6 COMDTY:<Price=104.828125> | G14: 46177.778 | H14: MARINER\SilverAdm | I14: 46177.778 | J14: MARINER\SilverAdm
A15: 3YZ6 | B15: Price | C15: QW | D15: 46177 | E15: 104.79688 | F15: 3YZ6 COMDTY:<Price=104.796875> | G15: 46177.778 | H15: MARINER\SilverAdm | I15: 46177.778 | J15: MARINER\SilverAdm
A16: 912797QX8 | B16: Yield | C16: QW | D16: 46177 | E16: 0.036564214 | F16: 912797QX8 @BBT3 GOVT:<DiscountAsk=0.035632|DiscountBid=0.035822> | G16: 46177.777 | H16: MARINER\SilverAdm | I16: 46177.777 | J16: MARINER\SilverAdm
A17: 912797RF6 | B17: Yield | C17: QW | D17: 46177 | E17: 0.0369347 | F17: 912797RF6 @BBT3 GOVT:<DiscountAsk=0.035925|DiscountBid=0.036145> | G17: 46177.777 | H17: MARINER\SilverAdm | I17: 46177.777 | J17: MARINER\SilverAdm
A18: 912797RG4 | B18: Yield | C18: QW | D18: 46177 | E18: 0.037064076 | F18: 912797RG4 @BBT3 GOVT:<DiscountAsk=0.035986|DiscountBid=0.036232> | G18: 46177.777 | H18: MARINER\SilverAdm | I18: 46177.777 | J18: MARINER\SilverAdm
A19: 912797RS8 | B19: Yield | C19: QW | D19: 46177 | E19: 0.037245683 | F19: 912797RS8 @BBT3 GOVT:<DiscountAsk=0.036198|DiscountBid=0.036267> | G19: 46177.777 | H19: MARINER\SilverAdm | I19: 46177.777 | J19: MARINER\SilverAdm
A20: 912797SA6 | B20: Yield | C20: QW | D20: 46177 | E20: 0.037283999 | F20: 912797SA6 @BBT3 GOVT:<DiscountAsk=0.03616|DiscountBid=0.036276> | G20: 46177.777 | H20: MARINER\SilverAdm | I20: 46177.777 | J20: MARINER\SilverAdm
A21: 912797SK4 | B21: Yield | C21: QW | D21: 46177 | E21: 0.037335535 | F21: 912797SK4 @BBT3 GOVT:<DiscountAsk=0.036142|DiscountBid=0.03629> | G21: 46177.777 | H21: MARINER\SilverAdm | I21: 46177.777 | J21: MARINER\SilverAdm
A22: 912797SU2 | B22: Yield | C22: QW | D22: 46177 | E22: 0.037547432 | F22: 912797SU2 @BBT3 GOVT:<DiscountAsk=0.036329|DiscountBid=0.0364> | G22: 46177.777 | H22: MARINER\SilverAdm | I22: 46177.777 | J22: MARINER\SilverAdm
A23: 912797TC1 | B23: Yield | C23: QW | D23: 46177 | E23: 0.03729002 | F23: 912797TC1 @BBT3 GOVT:<DiscountAsk=0.035882|DiscountBid=0.036259> | G23: 46177.777 | H23: MARINER\SilverAdm | I23: 46177.777 | J23: MARINER\SilverAdm
A24: 912797TD9 | B24: Yield | C24: QW | D24: 46177 | E24: 0.03671247 | F24: 912797TD9 @BBT3 GOVT:<DiscountAsk=0.035758|DiscountBid=0.035958> | G24: 46177.777 | H24: MARINER\SilverAdm | I24: 46177.777 | J24: MARINER\SilverAdm
... A560: 91282CQU8 | B560: Yield | C560: QW | D560: 46177 | E560: 0.041870801 | F560: 91282CQU8 @BBT3 GOVT:<PriceAsk=99.7265625|PriceBid=99.71875> | G560: 46177.777 | H560: MARINER\SilverAdm | I560: 46177.777 | J560: MARINER\SilverAdm
A561: 91282CQV6 | B561: Yield | C561: QW | D561: 46177 | E561: 0.041065 | G561: 46177.669 | H561: MARINERCAPITAL\jmannion | I561: 46177.669 | J561: MARINERCAPITAL\jmannion
A562: 9128334S6 | B562: Yield | C562: QW | D562: 46177 | E562: 0.042479415 | F562: 9128334S6 @BBT3 GOVT:<PriceAsk=80.481|PriceBid=80.277> | G562: 46177.777 | H562: MARINER\SilverAdm | I562: 46177.777 | J562: MARINER\SilverAdm
A563: 9128334T4 | B563: Yield | C563: QW | D563: 46177 | E563: 0.042824376 | F563: 9128334T4 @BBT3 GOVT:<PriceAsk=78.659|PriceBid=78.453> | G563: 46177.777 | H563: MARINER\SilverAdm | I563: 46177.777 | J563: MARINER\SilverAdm
A564: 9128334U1 | B564: Yield | C564: QW | D564: 46177 | E564: 0.043039307 | F564: 9128334U1 @BBT3 GOVT:<PriceAsk=76.916|PriceBid=76.702> | G564: 46177.777 | H564: MARINER\SilverAdm | I564: 46177.777 | J564: MARINER\SilverAdm
A565: 9128334V9 | B565: Yield | C565: QW | D565: 46177 | E565: 0.043454654 | F565: 9128334V9 @BBT3 GOVT:<PriceAsk=75.102|PriceBid=74.871> | G565: 46177.777 | H565: MARINER\SilverAdm | I565: 46177.777 | J565: MARINER\SilverAdm
A566: 9128334W7 | B566: Yield | C566: QW | D566: 46177 | E566: 0.043864237 | F566: 9128334W7 @BBT3 GOVT:<PriceAsk=73.286|PriceBid=73.075> | G566: 46177.777 | H566: MARINER\SilverAdm | I566: 46177.777 | J566: MARINER\SilverAdm
A567: 9128334X5 | B567: Yield | C567: QW | D567: 46177 | E567: 0.044279253 | F567: 9128334X5 @BBT3 GOVT:<PriceAsk=71.494|PriceBid=71.279> | G567: 46177.777 | H567: MARINER\SilverAdm | I567: 46177.777 | J567: MARINER\SilverAdm
A568: 9128334Y3 | B568: Yield | C568: QW | D568: 46177 | E568: 0.044589941 | F568: 9128334Y3 @BBT3 GOVT:<PriceAsk=69.784|PriceBid=69.549> | G568: 46177.777 | H568: MARINER\SilverAdm | I568: 46177.777 | J568: MARINER\SilverAdm
A569: 9128334Z0 | B569: Yield | C569: QW | D569: 46177 | E569: 0.044985095 | F569: 9128334Z0 @BBT3 GOVT:<PriceAsk=68.043|PriceBid=67.794> | G569: 46177.777 | H569: MARINER\SilverAdm | I569: 46177.777 | J569: MARINER\SilverAdm
A570: 9128335A4 | B570: Yield | C570: QW | D570: 46177 | E570: 0.045314436 | F570: 9128335A4 @BBT3 GOVT:<PriceAsk=66.356|PriceBid=66.1> | G570: 46177.777 | H570: MARINER\SilverAdm | I570: 46177.777 | J570: MARINER\SilverAdm
A571: 9128335B2 | B571: Yield | C571: QW | D571: 46177 | E571: 0.045690052 | F571: 9128335B2 @BBT3 GOVT:<PriceAsk=64.665|PriceBid=64.396> | G571: 46177.777 | H571: MARINER\SilverAdm | I571: 46177.777 | J571: MARINER\SilverAdm
A572: 9128337F1 | B572: Yield | C572: QW | D572: 46177 | E572: 0.046629966 | F572: 9128337F1 @BBT3 GOVT:<PriceAsk=61.224|PriceBid=60.93> | G572: 46177.777 | H572: MARINER\SilverAdm | I572: 46177.777 | J572: MARINER\SilverAdm
A573: 9128337Q7 | B573: Yield | C573: QW | D573: 46177 | E573: 0.042654548 | F573: 9128337Q7 @BBT3 GOVT:<PriceAsk=79.57|PriceBid=79.359> | G573: 46177.777 | H573: MARINER\SilverAdm | I573: 46177.777 | J573: MARINER\SilverAdm
... A731: CA013051ED53 | B731: Yield | C731: QW | D731: 46177 | E731: 0.045338629 | F731: CA013051ED53 BGN GOVT:<PriceBid=79.099|PriceAsk=79.226> | G731: 46177.777 | H731: MARINER\SilverAdm | I731: 46177.777 | J731: MARINER\SilverAdm
A732: CA135087B949 | B732: Price | C732: QW | D732: 46177 | E732: 106.55 | G732: 46177.668 | H732: MARINERCAPITAL\jmannion | I732: 46177.668 | J732: MARINERCAPITAL\jmannion
...

Sheet QW_CloseDL
A1: ID | B1: Att | C1: Src | D1: Date | E1: Value | F1: CreatedDate | G1: CreatedBy | H1: ModifiedTime | I1: ModifiedBy | J1: Notes
A2: 3YM6 | B2: Price | C2: QW | D2: 46177 | E2: 104.98438 | F2: 46177.772 | G2: MARINER\SilverAdm | H2: 46177.772 | I2: MARINER\SilverAdm | J2: DL CANVAS_FUTURES_MASTER Date=6/4/2026 PX_SETTLE = no sttl dt
A3: 3YU6 | B3: Price | C3: QW | D3: 46177 | E3: 104.82812 | F3: 46177.772 | G3: MARINER\SilverAdm | H3: 46177.772 | I3: MARINER\SilverAdm | J3: DL CANVAS_FUTURES_MASTER Date=6/4/2026 PX_SETTLE = no sttl dt
A4: 3YZ6 | B4: Price | C4: QW | D4: 46177 | E4: 104.79688 | F4: 46177.772 | G4: MARINER\SilverAdm | H4: 46177.772 | I4: MARINER\SilverAdm | J4: DL CANVAS_FUTURES_MASTER Date=6/4/2026 PX_SETTLE = no sttl dt
A5: 912797QX8 | B5: Yield | C5: QW | D5: 46177 | E5: 0.036564214 | F5: 46177.771 | G5: MARINER\SilverAdm | H5: 46177.771 | I5: MARINER\SilverAdm | J5: DL Bill input Discount = 3.57270000 PX_ASK = 3.56320000 PX_BID = 3.58220000
A6: 912797RF6 | B6: Yield | C6: QW | D6: 46177 | E6: 0.0369347 | F6: 46177.771 | G6: MARINER\SilverAdm | H6: 46177.771 | I6: MARINER\SilverAdm | J6: DL Bill input Discount = 3.60350000 PX_ASK = 3.59250000 PX_BID = 3.61450000
A7: 912797RG4 | B7: Yield | C7: QW | D7: 46177 | E7: 0.037064076 | F7: 46177.771 | G7: MARINER\SilverAdm | H7: 46177.771 | I7: MARINER\SilverAdm | J7: DL Bill input Discount = 3.61090000 PX_ASK = 3.59860000 PX_BID = 3.62320000
A8: 912797RS8 | B8: Yield | C8: QW | D8: 46177 | E8: 0.037245683 | F8: 46177.771 | G8: MARINER\SilverAdm | H8: 46177.771 | I8: MARINER\SilverAdm | J8: DL Bill input Discount = 3.62325000 PX_ASK = 3.61980000 PX_BID = 3.62670000
A9: 912797SA6 | B9: Yield | C9: QW | D9: 46177 | E9: 0.037283999 | F9: 46177.771 | G9: MARINER\SilverAdm | H9: 46177.771 | I9: MARINER\SilverAdm | J9: DL Bill input Discount = 3.62180000 PX_ASK = 3.61600000 PX_BID = 3.62760000
A10: 912797SK4 | B10: Yield | C10: QW | D10: 46177 | E10: 0.037335535 | F10: 46177.771 | G10: MARINER\SilverAdm | H10: 46177.771 | I10: MARINER\SilverAdm | J10: DL Bill input Discount = 3.62160000 PX_ASK = 3.61420000 PX_BID = 3.62900000
A11: 912797SU2 | B11: Yield | C11: QW | D11: 46177 | E11: 0.037547432 | F11: 46177.771 | G11: MARINER\SilverAdm | H11: 46177.771 | I11: MARINER\SilverAdm | J11: DL Bill input Discount = 3.63645000 PX_ASK = 3.63290000 PX_BID = 3.64000000
A12: 912797TC1 | B12: Yield | C12: QW | D12: 46177 | E12: 0.03729002 | F12: 46177.771 | G12: MARINER\SilverAdm | H12: 46177.771 | I12: MARINER\SilverAdm | J12: DL Bill input Discount = 3.60705000 PX_ASK = 3.58820000 PX_BID = 3.62590000
A13: 912797TD9 | B13: Yield | C13: QW | D13: 46177 | E13: 0.03671247 | F13: 46177.771 | G13: MARINER\SilverAdm | H13: 46177.771 | I13: MARINER\SilverAdm | J13: DL Bill input Discount = 3.58580000 PX_ASK = 3.57580000 PX_BID = 3.59580000
... A1354: XQU6 | B1354: Price | C1354: QW | D1354: 46177 | E1354: 112.7 | F1354: 46177.772 | G1354: MARINER\SilverAdm | H1354: 46177.772 | I1354: MARINER\SilverAdm | J1354: DL CANVAS_FUTURES_MASTER Date=6/4/2026 PX_SETTLE = no sttl dt

Sheet Comparaison
A1: {=_xlfn._xlws.FILTER(_xlfn.UNIQUE('BBT3'!A:A),_xlfn.UNIQUE('BBT3'!A:A)<>0)} -> ID | B1: Type | C1: ISIN | D1: Coupon | E1: Maturity | F1: InflationLinked | G1: ClodeDL Yield | H1: BBT3 Yield | I1: Close Yield | J1: Diff absolue | P1: {=_xll.qwCtxTrade()} -> ctx.46177.Close | Q1: {=_xll.qwCalAddBusDays("US",TODAY(),M3)} -> 46177
A2: 912797QX8 | B2: =IF(NOT(ISBLANK(A2)),VLOOKUP(A2,'BBT3'!A:F,2,0),"") -> Bill | C2: =IF(NOT(ISBLANK(A2)),VLOOKUP(A2,'BBT3'!A:F,3,0),"") -> US912797QX89 | D2: =IF(NOT(ISBLANK(A2)),VLOOKUP(A2,'BBT3'!A:F,4,1),"") -> 0 | E2: =IF(NOT(ISBLANK(A2)),VLOOKUP(A2,'BBT3'!A:F,5,0),"") -> 46184 | F2: =IF(NOT(ISBLANK(A2)),VLOOKUP(A2,'BBT3'!A:F,6,0),"") -> N | G2: =IF(NOT(ISBLANK(A2)),VLOOKUP(A2,QW_Close!A:J,5,0),"") -> 0.036564214 | H2: {=IF(NOT(ISBLANK(A2)),((_xlfn.XLOOKUP(1,(_bbt3[[#All],[ID]]=A2)*(_bbt3[[#All],[METRIC_NAME]]="YLD_YTM_ASK"),_bbt3[[#All],[METRIC_VALUE]])*0.5)+(_xlfn.XLOOKUP(1,(_bbt3[[#All],[ID]]=A2)*(_bbt3[[#All],[METRIC_NAME]]="YLD_YTM_BID"),_bbt3[[#All],[METRIC_VALUE]])*0.5))/100,"")} -> 0.03624479 | I2: =IF(ISNA(VLOOKUP(A2,QW_CloseDL!A:E,5,0)),0,VLOOKUP(A2,QW_CloseDL!A:E,5,0)) -> 0.036564214 | J2: =IF(ISNA(IF(NOT(ISBLANK(A2)),ABS(G2-I2),"")),0,(IF(NOT(ISBLANK(A2)),ABS(G2-I2)*10000,""))) -> 0 | Q2: Total | R2: =COUNTA(A:A) -> 607
A3: 912797RF6 | B3: =IF(NOT(ISBLANK(A3)),VLOOKUP(A3,'BBT3'!A:F,2,0),"") -> Bill | C3: =IF(NOT(ISBLANK(A3)),VLOOKUP(A3,'BBT3'!A:F,3,0),"") -> US912797RF64 | D3: =IF(NOT(ISBLANK(A3)),VLOOKUP(A3,'BBT3'!A:F,4,1),"") -> 0 | E3: =IF(NOT(ISBLANK(A3)),VLOOKUP(A3,'BBT3'!A:F,5,0),"") -> 46212 | F3: =IF(NOT(ISBLANK(A3)),VLOOKUP(A3,'BBT3'!A:F,6,0),"") -> N | G3: =IF(NOT(ISBLANK(A3)),VLOOKUP(A3,QW_Close!A:J,5,0),"") -> 0.0369347 | H3: {=IF(NOT(ISBLANK(A3)),((_xlfn.XLOOKUP(1,(_bbt3[[#All],[ID]]=A3)*(_bbt3[[#All],[METRIC_NAME]]="YLD_YTM_ASK"),_bbt3[[#All],[METRIC_VALUE]])*0.5)+(_xlfn.XLOOKUP(1,(_bbt3[[#All],[ID]]=A3)*(_bbt3[[#All],[METRIC_NAME]]="YLD_YTM_BID"),_bbt3[[#All],[METRIC_VALUE]])*0.5))/100,"")} -> #N/A | I3: =IF(ISNA(VLOOKUP(A3,QW_CloseDL!A:E,5,0)),0,VLOOKUP(A3,QW_CloseDL!A:E,5,0)) -> 0.0369347 | J3: =IF(ISNA(IF(NOT(ISBLANK(A3)),ABS(G3-I3),"")),0,(IF(NOT(ISBLANK(A3)),ABS(G3-I3)*10000,""))) -> 0 | M3: -1 | R3: {=MAX(_xlfn._xlws.FILTER(J2:J3500,ISNUMBER(J2:J3500)*(B2:B3500="Bond")))} -> 4.1568743
A4: 912797RG4 | B4: =IF(NOT(ISBLANK(A4)),VLOOKUP(A4,'BBT3'!A:F,2,0),"") -> Bill | C4: =IF(NOT(ISBLANK(A4)),VLOOKUP(A4,'BBT3'!A:F,3,0),"") -> US912797RG48 | D4: =IF(NOT(ISBLANK(A4)),VLOOKUP(A4,'BBT3'!A:F,4,1),"") -> 0 | E4: =IF(NOT(ISBLANK(A4)),VLOOKUP(A4,'BBT3'!A:F,5,0),"") -> 46240 | F4: =IF(NOT(ISBLANK(A4)),VLOOKUP(A4,'BBT3'!A:F,6,0),"") -> N | G4: =IF(NOT(ISBLANK(A4)),VLOOKUP(A4,QW_Close!A:J,5,0),"") -> 0.037064076 | H4: {=IF(NOT(ISBLANK(A4)),((_xlfn.XLOOKUP(1,(_bbt3[[#All],[ID]]=A4)*(_bbt3[[#All],[METRIC_NAME]]="YLD_YTM_ASK"),_bbt3[[#All],[METRIC_VALUE]])*0.5)+(_xlfn.XLOOKUP(1,(_bbt3[[#All],[ID]]=A4)*(_bbt3[[#All],[METRIC_NAME]]="YLD_YTM_BID"),_bbt3[[#All],[METRIC_VALUE]])*0.5))/100,"")} -> #N/A | I4: =IF(ISNA(VLOOKUP(A4,QW_CloseDL!A:E,5,0)),0,VLOOKUP(A4,QW_CloseDL!A:E,5,0)) -> 0.037064076 | J4: =IF(ISNA(IF(NOT(ISBLANK(A4)),ABS(G4-I4),"")),0,(IF(NOT(ISBLANK(A4)),ABS(G4-I4)*10000,""))) -> 0
A5: 912797RS8 | B5: =IF(NOT(ISBLANK(A5)),VLOOKUP(A5,'BBT3'!A:F,2,0),"") -> Bill | C5: =IF(NOT(ISBLANK(A5)),VLOOKUP(A5,'BBT3'!A:F,3,0),"") -> US912797RS85 | D5: =IF(NOT(ISBLANK(A5)),VLOOKUP(A5,'BBT3'!A:F,4,1),"") -> 0 | E5: =IF(NOT(ISBLANK(A5)),VLOOKUP(A5,'BBT3'!A:F,5,0),"") -> 46268 | F5: =IF(NOT(ISBLANK(A5)),VLOOKUP(A5,'BBT3'!A:F,6,0),"") -> N | G5: =IF(NOT(ISBLANK(A5)),VLOOKUP(A5,QW_Close!A:J,5,0),"") -> 0.037245683 | H5: {=IF(NOT(ISBLANK(A5)),((_xlfn.XLOOKUP(1,(_bbt3[[#All],[ID]]=A5)*(_bbt3[[#All],[METRIC_NAME]]="YLD_YTM_ASK"),_bbt3[[#All],[METRIC_VALUE]])*0.5)+(_xlfn.XLOOKUP(1,(_bbt3[[#All],[ID]]=A5)*(_bbt3[[#All],[METRIC_NAME]]="YLD_YTM_BID"),_bbt3[[#All],[METRIC_VALUE]])*0.5))/100,"")} -> 0.037071528 | I5: =IF(ISNA(VLOOKUP(A5,QW_CloseDL!A:E,5,0)),0,VLOOKUP(A5,QW_CloseDL!A:E,5,0)) -> 0.037245683 | J5: =IF(ISNA(IF(NOT(ISBLANK(A5)),ABS(G5-I5),"")),0,(IF(NOT(ISBLANK(A5)),ABS(G5-I5)*10000,""))) -> 0
A6: 912797SA6 | B6: =IF(NOT(ISBLANK(A6)),VLOOKUP(A6,'BBT3'!A:F,2,0),"") -> Bill | C6: =IF(NOT(ISBLANK(A6)),VLOOKUP(A6,'BBT3'!A:F,3,0),"") -> US912797SA68 | D6: =IF(NOT(ISBLANK(A6)),VLOOKUP(A6,'BBT3'!A:F,4,1),"") -> 0 | E6: =IF(NOT(ISBLANK(A6)),VLOOKUP(A6,'BBT3'!A:F,5,0),"") -> 46296 | F6: =IF(NOT(ISBLANK(A6)),VLOOKUP(A6,'BBT3'!A:F,6,0),"") -> N | G6: =IF(NOT(ISBLANK(A6)),VLOOKUP(A6,QW_Close!A:J,5,0),"") -> 0.037283999 | H6: {=IF(NOT(ISBLANK(A6)),((_xlfn.XLOOKUP(1,(_bbt3[[#All],[ID]]=A6)*(_bbt3[[#All],[METRIC_NAME]]="YLD_YTM_ASK"),_bbt3[[#All],[METRIC_VALUE]])*0.5)+(_xlfn.XLOOKUP(1,(_bbt3[[#All],[ID]]=A6)*(_bbt3[[#All],[METRIC_NAME]]="YLD_YTM_BID"),_bbt3[[#All],[METRIC_VALUE]])*0.5))/100,"")} -> 0.037162198 | I6: =IF(ISNA(VLOOKUP(A6,QW_CloseDL!A:E,5,0)),0,VLOOKUP(A6,QW_CloseDL!A:E,5,0)) -> 0.037283999 | J6: =IF(ISNA(IF(NOT(ISBLANK(A6)),ABS(G6-I6),"")),0,(IF(NOT(ISBLANK(A6)),ABS(G6-I6)*10000,""))) -> 0
A7: 912797SK4 | B7: =IF(NOT(ISBLANK(A7)),VLOOKUP(A7,'BBT3'!A:F,2,0),"") -> Bill | C7: =IF(NOT(ISBLANK(A7)),VLOOKUP(A7,'BBT3'!A:F,3,0),"") -> US912797SK41 | D7: =IF(NOT(ISBLANK(A7)),VLOOKUP(A7,'BBT3'!A:F,4,1),"") -> 0 | E7: =IF(NOT(ISBLANK(A7)),VLOOKUP(A7,'BBT3'!A:F,5,0),"") -> 46324 | F7: =IF(NOT(ISBLANK(A7)),VLOOKUP(A7,'BBT3'!A:F,6,0),"") -> N | G7: =IF(NOT(ISBLANK(A7)),VLOOKUP(A7,QW_Close!A:J,5,0),"") -> 0.037335535 | H7: {=IF(NOT(ISBLANK(A7)),((_xlfn.XLOOKUP(1,(_bbt3[[#All],[ID]]=A7)*(_bbt3[[#All],[METRIC_NAME]]="YLD_YTM_ASK"),_bbt3[[#All],[METRIC_VALUE]])*0.5)+(_xlfn.XLOOKUP(1,(_bbt3[[#All],[ID]]=A7)*(_bbt3[[#All],[METRIC_NAME]]="YLD_YTM_BID"),_bbt3[[#All],[METRIC_VALUE]])*0.5))/100,"")} -> 0.037266356 | I7: =IF(ISNA(VLOOKUP(A7,QW_CloseDL!A:E,5,0)),0,VLOOKUP(A7,QW_CloseDL!A:E,5,0)) -> 0.037335535 | J7: =IF(ISNA(IF(NOT(ISBLANK(A7)),ABS(G7-I7),"")),0,(IF(NOT(ISBLANK(A7)),ABS(G7-I7)*10000,""))) -> 0
A8: 912797SU2 | B8: =IF(NOT(ISBLANK(A8)),VLOOKUP(A8,'BBT3'!A:F,2,0),"") -> Bill | C8: =IF(NOT(ISBLANK(A8)),VLOOKUP(A8,'BBT3'!A:F,3,0),"") -> US912797SU23 | D8: =IF(NOT(ISBLANK(A8)),VLOOKUP(A8,'BBT3'!A:F,4,1),"") -> 0 | E8: =IF(NOT(ISBLANK(A8)),VLOOKUP(A8,'BBT3'!A:F,5,0),"") -> 46353 | F8: =IF(NOT(ISBLANK(A8)),VLOOKUP(A8,'BBT3'!A:F,6,0),"") -> N | G8: =IF(NOT(ISBLANK(A8)),VLOOKUP(A8,QW_Close!A:J,5,0),"") -> 0.037547432 | H8: {=IF(NOT(ISBLANK(A8)),((_xlfn.XLOOKUP(1,(_bbt3[[#All],[ID]]=A8)*(_bbt3[[#All],[METRIC_NAME]]="YLD_YTM_ASK"),_bbt3[[#All],[METRIC_VALUE]])*0.5)+(_xlfn.XLOOKUP(1,(_bbt3[[#All],[ID]]=A8)*(_bbt3[[#All],[METRIC_NAME]]="YLD_YTM_BID"),_bbt3[[#All],[METRIC_VALUE]])*0.5))/100,"")} -> 0.037533042 | I8: =IF(ISNA(VLOOKUP(A8,QW_CloseDL!A:E,5,0)),0,VLOOKUP(A8,QW_CloseDL!A:E,5,0)) -> 0.037547432 | J8: =IF(ISNA(IF(NOT(ISBLANK(A8)),ABS(G8-I8),"")),0,(IF(NOT(ISBLANK(A8)),ABS(G8-I8)*10000,""))) -> 0
A9: 912797TC1 | B9: =IF(NOT(ISBLANK(A9)),VLOOKUP(A9,'BBT3'!A:F,2,0),"") -> Bill | C9: =IF(NOT(ISBLANK(A9)),VLOOKUP(A9,'BBT3'!A:F,3,0),"") -> US912797TC16 | D9: =IF(NOT(ISBLANK(A9)),VLOOKUP(A9,'BBT3'!A:F,4,1),"") -> 0 | E9: =IF(NOT(ISBLANK(A9)),VLOOKUP(A9,'BBT3'!A:F,5,0),"") -> 46380 | F9: =IF(NOT(ISBLANK(A9)),VLOOKUP(A9,'BBT3'!A:F,6,0),"") -> N | G9: =IF(NOT(ISBLANK(A9)),VLOOKUP(A9,QW_Close!A:J,5,0),"") -> 0.03729002 | H9: {=IF(NOT(ISBLANK(A9)),((_xlfn.XLOOKUP(1,(_bbt3[[#All],[ID]]=A9)*(_bbt3[[#All],[METRIC_NAME]]="YLD_YTM_ASK"),_bbt3[[#All],[METRIC_VALUE]])*0.5)+(_xlfn.XLOOKUP(1,(_bbt3[[#All],[ID]]=A9)*(_bbt3[[#All],[METRIC_NAME]]="YLD_YTM_BID"),_bbt3[[#All],[METRIC_VALUE]])*0.5))/100,"")} -> 0.03725997 | I9: =IF(ISNA(VLOOKUP(A9,QW_CloseDL!A:E,5,0)),0,VLOOKUP(A9,QW_CloseDL!A:E,5,0)) -> 0.03729002 | J9: =IF(ISNA(IF(NOT(ISBLANK(A9)),ABS(G9-I9),"")),0,(IF(NOT(ISBLANK(A9)),ABS(G9-I9)*10000,""))) -> 0
A10: 912797TD9 | B10: =IF(NOT(ISBLANK(A10)),VLOOKUP(A10,'BBT3'!A:F,2,0),"") -> Bill | C10: =IF(NOT(ISBLANK(A10)),VLOOKUP(A10,'BBT3'!A:F,3,0),"") -> US912797TD98 | D10: =IF(NOT(ISBLANK(A10)),VLOOKUP(A10,'BBT3'!A:F,4,1),"") -> 0 | E10: =IF(NOT(ISBLANK(A10)),VLOOKUP(A10,'BBT3'!A:F,5,0),"") -> 46191 | F10: =IF(NOT(ISBLANK(A10)),VLOOKUP(A10,'BBT3'!A:F,6,0),"") -> N | G10: =IF(NOT(ISBLANK(A10)),VLOOKUP(A10,QW_Close!A:J,5,0),"") -> 0.03671247 | H10: {=IF(NOT(ISBLANK(A10)),((_xlfn.XLOOKUP(1,(_bbt3[[#All],[ID]]=A10)*(_bbt3[[#All],[METRIC_NAME]]="YLD_YTM_ASK"),_bbt3[[#All],[METRIC_VALUE]])*0.5)+(_xlfn.XLOOKUP(1,(_bbt3[[#All],[ID]]=A10)*(_bbt3[[#All],[METRIC_NAME]]="YLD_YTM_BID"),_bbt3[[#All],[METRIC_VALUE]])*0.5))/100,"")} -> #N/A | I10: =IF(ISNA(VLOOKUP(A10,QW_CloseDL!A:E,5,0)),0,VLOOKUP(A10,QW_CloseDL!A:E,5,0)) -> 0.03671247 | J10: =IF(ISNA(IF(NOT(ISBLANK(A10)),ABS(G10-I10),"")),0,(IF(NOT(ISBLANK(A10)),ABS(G10-I10)*10000,""))) -> 0
A11: 912797TE7 | B11: =IF(NOT(ISBLANK(A11)),VLOOKUP(A11,'BBT3'!A:F,2,0),"") -> Bill | C11: =IF(NOT(ISBLANK(A11)),VLOOKUP(A11,'BBT3'!A:F,3,0),"") -> US912797TE71 | D11: =IF(NOT(ISBLANK(A11)),VLOOKUP(A11,'BBT3'!A:F,4,1),"") -> 0 | E11: =IF(NOT(ISBLANK(A11)),VLOOKUP(A11,'BBT3'!A:F,5,0),"") -> 46198 | F11: =IF(NOT(ISBLANK(A11)),VLOOKUP(A11,'BBT3'!A:F,6,0),"") -> N | G11: =IF(NOT(ISBLANK(A11)),VLOOKUP(A11,QW_Close!A:J,5,0),"") -> 0.036699024 | H11: {=IF(NOT(ISBLANK(A11)),((_xlfn.XLOOKUP(1,(_bbt3[[#All],[ID]]=A11)*(_bbt3[[#All],[METRIC_NAME]]="YLD_YTM_ASK"),_bbt3[[#All],[METRIC_VALUE]])*0.5)+(_xlfn.XLOOKUP(1,(_bbt3[[#All],[ID]]=A11)*(_bbt3[[#All],[METRIC_NAME]]="YLD_YTM_BID"),_bbt3[[#All],[METRIC_VALUE]])*0.5))/100,"")} -> 0.036402641 | I11: =IF(ISNA(VLOOKUP(A11,QW_CloseDL!A:E,5,0)),0,VLOOKUP(A11,QW_CloseDL!A:E,5,0)) -> 0.036699024 | J11: =IF(ISNA(IF(NOT(ISBLANK(A11)),ABS(G11-I11),"")),0,(IF(NOT(ISBLANK(A11)),ABS(G11-I11)*10000,""))) -> 0
A12: 912797TF4 | B12: =IF(NOT(ISBLANK(A12)),VLOOKUP(A12,'BBT3'!A:F,2,0),"") -> Bill | C12: =IF(NOT(ISBLANK(A12)),VLOOKUP(A12,'BBT3'!A:F,3,0),"") -> US912797TF47 | D12: =IF(NOT(ISBLANK(A12)),VLOOKUP(A12,'BBT3'!A:F,4,1),"") -> 0 | E12: =IF(NOT(ISBLANK(A12)),VLOOKUP(A12,'BBT3'!A:F,5,0),"") -> 46205 | F12: =IF(NOT(ISBLANK(A12)),VLOOKUP(A12,'BBT3'!A:F,6,0),"") -> N | G12: =IF(NOT(ISBLANK(A12)),VLOOKUP(A12,QW_Close!A:J,5,0),"") -> 0.036848616 | H12: {=IF(NOT(ISBLANK(A12)),((_xlfn.XLOOKUP(1,(_bbt3[[#All],[ID]]=A12)*(_bbt3[[#All],[METRIC_NAME]]="YLD_YTM_ASK"),_bbt3[[#All],[METRIC_VALUE]])*0.5)+(_xlfn.XLOOKUP(1,(_bbt3[[#All],[ID]]=A12)*(_bbt3[[#All],[METRIC_NAME]]="YLD_YTM_BID"),_bbt3[[#All],[METRIC_VALUE]])*0.5))/100,"")} -> #N/A | I12: =IF(ISNA(VLOOKUP(A12,QW_CloseDL!A:E,5,0)),0,VLOOKUP(A12,QW_CloseDL!A:E,5,0)) -> 0.036848616 | J12: =IF(ISNA(IF(NOT(ISBLANK(A12)),ABS(G12-I12),"")),0,(IF(NOT(ISBLANK(A12)),ABS(G12-I12)*10000,""))) -> 0
A13: 912797TM9 | B13: =IF(NOT(ISBLANK(A13)),VLOOKUP(A13,'BBT3'!A:F,2,0),"") -> Bill | C13: =IF(NOT(ISBLANK(A13)),VLOOKUP(A13,'BBT3'!A:F,3,0),"") -> US912797TM97 | D13: =IF(NOT(ISBLANK(A13)),VLOOKUP(A13,'BBT3'!A:F,4,1),"") -> 0 | E13: =IF(NOT(ISBLANK(A13)),VLOOKUP(A13,'BBT3'!A:F,5,0),"") -> 46408 | F13: =IF(NOT(ISBLANK(A13)),VLOOKUP(A13,'BBT3'!A:F,6,0),"") -> N | G13: =IF(NOT(ISBLANK(A13)),VLOOKUP(A13,QW_Close!A:J,5,0),"") -> 0.037145095 | H13: {=IF(NOT(ISBLANK(A13)),((_xlfn.XLOOKUP(1,(_bbt3[[#All],[ID]]=A13)*(_bbt3[[#All],[METRIC_NAME]]="YLD_YTM_ASK"),_bbt3[[#All],[METRIC_VALUE]])*0.5)+(_xlfn.XLOOKUP(1,(_bbt3[[#All],[ID]]=A13)*(_bbt3[[#All],[METRIC_NAME]]="YLD_YTM_BID"),_bbt3[[#All],[METRIC_VALUE]])*0.5))/100,"")} -> #N/A | I13: =IF(ISNA(VLOOKUP(A13,QW_CloseDL!A:E,5,0)),0,VLOOKUP(A13,QW_CloseDL!A:E,5,0)) -> 0.037145095 | J13: =IF(ISNA(IF(NOT(ISBLANK(A13)),ABS(G13-I13),"")),0,(IF(NOT(ISBLANK(A13)),ABS(G13-I13)*10000,""))) -> 0 | P13: {=_xlfn._xlws.FILTER(A2:A3000,(J2:J3000>R3*10%)*(D2:D3000>0))} -> 912810FD5 | Q13: =VLOOKUP(P13,A:B,2,0) -> Bond | R13: =VLOOKUP(P13,A:E,4,0) -> 3.625 | S13: =VLOOKUP(P13,A:J,10,0) -> 4.1568743 | T13: =VLOOKUP(P13,A:J,5,0) -> 46858
A14: 912797TN7 | B14: =IF(NOT(ISBLANK(A14)),VLOOKUP(A14,'BBT3'!A:F,2,0),"") -> Bill | C14: =IF(NOT(ISBLANK(A14)),VLOOKUP(A14,'BBT3'!A:F,3,0),"") -> US912797TN70 | D14: =IF(NOT(ISBLANK(A14)),VLOOKUP(A14,'BBT3'!A:F,4,1),"") -> 0 | E14: =IF(NOT(ISBLANK(A14)),VLOOKUP(A14,'BBT3'!A:F,5,0),"") -> 46219 | F14: =IF(NOT(ISBLANK(A14)),VLOOKUP(A14,'BBT3'!A:F,6,0),"") -> N | G14: =IF(NOT(ISBLANK(A14)),VLOOKUP(A14,QW_Close!A:J,5,0),"") -> 0.037002238 | H14: {=IF(NOT(ISBLANK(A14)),((_xlfn.XLOOKUP(1,(_bbt3[[#All],[ID]]=A14)*(_bbt3[[#All],[METRIC_NAME]]="YLD_YTM_ASK"),_bbt3[[#All],[METRIC_VALUE]])*0.5)+(_xlfn.XLOOKUP(1,(_bbt3[[#All],[ID]]=A14)*(_bbt3[[#All],[METRIC_NAME]]="YLD_YTM_BID"),_bbt3[[#All],[METRIC_VALUE]])*0.5))/100,"")} -> 0.036739715 | I14: =IF(ISNA(VLOOKUP(A14,QW_CloseDL!A:E,5,0)),0,VLOOKUP(A14,QW_CloseDL!A:E,5,0)) -> 0.037002238 | J14: =IF(ISNA(IF(NOT(ISBLANK(A14)),ABS(G14-I14),"")),0,(IF(NOT(ISBLANK(A14)),ABS(G14-I14)*10000,""))) -> 0 | P14: 912810FH6 | Q14: =VLOOKUP(P14,A:B,2,0) -> Bond | R14: =VLOOKUP(P14,A:E,4,0) -> 3.875 | S14: =VLOOKUP(P14,A:J,10,0) -> 3.5023207 | T14: =VLOOKUP(P14,A:J,5,0) -> 47223
A15: 912797TP2 | B15: =IF(NOT(ISBLANK(A15)),VLOOKUP(A15,'BBT3'!A:F,2,0),"") -> Bill | C15: =IF(NOT(ISBLANK(A15)),VLOOKUP(A15,'BBT3'!A:F,3,0),"") -> US912797TP29 | D15: =IF(NOT(ISBLANK(A15)),VLOOKUP(A15,'BBT3'!A:F,4,1),"") -> 0 | E15: =IF(NOT(ISBLANK(A15)),VLOOKUP(A15,'BBT3'!A:F,5,0),"") -> 46226 | F15: =IF(NOT(ISBLANK(A15)),VLOOKUP(A15,'BBT3'!A:F,6,0),"") -> N | G15: =IF(NOT(ISBLANK(A15)),VLOOKUP(A15,QW_Close!A:J,5,0),"") -> 0.03701591 | H15: {=IF(NOT(ISBLANK(A15)),((_xlfn.XLOOKUP(1,(_bbt3[[#All],[ID]]=A15)*(_bbt3[[#All],[METRIC_NAME]]="YLD_YTM_ASK"),_bbt3[[#All],[METRIC_VALUE]])*0.5)+(_xlfn.XLOOKUP(1,(_bbt3[[#All],[ID]]=A15)*(_bbt3[[#All],[METRIC_NAME]]="YLD_YTM_BID"),_bbt3[[#All],[METRIC_VALUE]])*0.5))/100,"")} -> 0.036766132 | I15: =IF(ISNA(VLOOKUP(A15,QW_CloseDL!A:E,5,0)),0,VLOOKUP(A15,QW_CloseDL!A:E,5,0)) -> 0.03701591 | J15: =IF(ISNA(IF(NOT(ISBLANK(A15)),ABS(G15-I15),"")),0,(IF(NOT(ISBLANK(A15)),ABS(G15-I15)*10000,""))) -> 0 | P15: 912810FQ6 | Q15: =VLOOKUP(P15,A:B,2,0) -> Bond | R15: =VLOOKUP(P15,A:E,4,0) -> 3.375 | S15: =VLOOKUP(P15,A:J,10,0) -> 1.0721609 | T15: =VLOOKUP(P15,A:J,5,0) -> 48319
A16: 912797TQ0 | B16: =IF(NOT(ISBLANK(A16)),VLOOKUP(A16,'BBT3'!A:F,2,0),"") -> Bill | C16: =IF(NOT(ISBLANK(A16)),VLOOKUP(A16,'BBT3'!A:F,3,0),"") -> US912797TQ02 | D16: =IF(NOT(ISBLANK(A16)),VLOOKUP(A16,'BBT3'!A:F,4,1),"") -> 0 | E16: =IF(NOT(ISBLANK(A16)),VLOOKUP(A16,'BBT3'!A:F,5,0),"") -> 46233 | F16: =IF(NOT(ISBLANK(A16)),VLOOKUP(A16,'BBT3'!A:F,6,0),"") -> N | G16: =IF(NOT(ISBLANK(A16)),VLOOKUP(A16,QW_Close!A:J,5,0),"") -> 0.037034787 | H16: {=IF(NOT(ISBLANK(A16)),((_xlfn.XLOOKUP(1,(_bbt3[[#All],[ID]]=A16)*(_bbt3[[#All],[METRIC_NAME]]="YLD_YTM_ASK"),_bbt3[[#All],[METRIC_VALUE]])*0.5)+(_xlfn.XLOOKUP(1,(_bbt3[[#All],[ID]]=A16)*(_bbt3[[#All],[METRIC_NAME]]="YLD_YTM_BID"),_bbt3[[#All],[METRIC_VALUE]])*0.5))/100,"")} -> 0.036797713 | I16: =IF(ISNA(VLOOKUP(A16,QW_CloseDL!A:E,5,0)),0,VLOOKUP(A16,QW_CloseDL!A:E,5,0)) -> 0.037034787 | J16: =IF(ISNA(IF(NOT(ISBLANK(A16)),ABS(G16-I16),"")),0,(IF(NOT(ISBLANK(A16)),ABS(G16-I16)*10000,""))) -> 0 | P16: 0 | Q16: =VLOOKUP(P16,A:B,2,0) -> #N/A | R16: =VLOOKUP(P16,A:E,4,0) -> #N/A | S16: =VLOOKUP(P16,A:J,10,0) -> #N/A | T16: =VLOOKUP(P16,A:J,5,0) -> #N/A
A17: 912797TV9 | B17: =IF(NOT(ISBLANK(A17)),VLOOKUP(A17,'BBT3'!A:F,2,0),"") -> Bill | C17: =IF(NOT(ISBLANK(A17)),VLOOKUP(A17,'BBT3'!A:F,3,0),"") -> US912797TV96 | D17: =IF(NOT(ISBLANK(A17)),VLOOKUP(A17,'BBT3'!A:F,4,1),"") -> 0 | E17: =IF(NOT(ISBLANK(A17)),VLOOKUP(A17,'BBT3'!A:F,5,0),"") -> 46436 | F17: =IF(NOT(ISBLANK(A17)),VLOOKUP(A17,'BBT3'!A:F,6,0),"") -> N | G17: =IF(NOT(ISBLANK(A17)),VLOOKUP(A17,QW_Close!A:J,5,0),"") -> 0.037346943 | H17: {=IF(NOT(ISBLANK(A17)),((_xlfn.XLOOKUP(1,(_bbt3[[#All],[ID]]=A17)*(_bbt3[[#All],[METRIC_NAME]]="YLD_YTM_ASK"),_bbt3[[#All],[METRIC_VALUE]])*0.5)+(_xlfn.XLOOKUP(1,(_bbt3[[#All],[ID]]=A17)*(_bbt3[[#All],[METRIC_NAME]]="YLD_YTM_BID"),_bbt3[[#All],[METRIC_VALUE]])*0.5))/100,"")} -> 0.037287263 | I17: =IF(ISNA(VLOOKUP(A17,QW_CloseDL!A:E,5,0)),0,VLOOKUP(A17,QW_CloseDL!A:E,5,0)) -> 0.037346943 | J17: =IF(ISNA(IF(NOT(ISBLANK(A17)),ABS(G17-I17),"")),0,(IF(NOT(ISBLANK(A17)),ABS(G17-I17)*10000,""))) -> 0 | P17: 0 | Q17: =VLOOKUP(P17,A:B,2,0) -> #N/A | R17: =VLOOKUP(P17,A:E,4,0) -> #N/A | S17: =VLOOKUP(P17,A:J,10,0) -> #N/A | T17: =VLOOKUP(P17,A:J,5,0) -> #N/A
A18: 912797TW7 | B18: =IF(NOT(ISBLANK(A18)),VLOOKUP(A18,'BBT3'!A:F,2,0),"") -> Bill | C18: =IF(NOT(ISBLANK(A18)),VLOOKUP(A18,'BBT3'!A:F,3,0),"") -> US912797TW79 | D18: =IF(NOT(ISBLANK(A18)),VLOOKUP(A18,'BBT3'!A:F,4,1),"") -> 0 | E18: =IF(NOT(ISBLANK(A18)),VLOOKUP(A18,'BBT3'!A:F,5,0),"") -> 46247 | F18: =IF(NOT(ISBLANK(A18)),VLOOKUP(A18,'BBT3'!A:F,6,0),"") -> N | G18: =IF(NOT(ISBLANK(A18)),VLOOKUP(A18,QW_Close!A:J,5,0),"") -> 0.037132397 | H18: {=IF(NOT(ISBLANK(A18)),((_xlfn.XLOOKUP(1,(_bbt3[[#All],[ID]]=A18)*(_bbt3[[#All],[METRIC_NAME]]="YLD_YTM_ASK"),_bbt3[[#All],[METRIC_VALUE]])*0.5)+(_xlfn.XLOOKUP(1,(_bbt3[[#All],[ID]]=A18)*(_bbt3[[#All],[METRIC_NAME]]="YLD_YTM_BID"),_bbt3[[#All],[METRIC_VALUE]])*0.5))/100,"")} -> 0.036920146 | I18: =IF(ISNA(VLOOKUP(A18,QW_CloseDL!A:E,5,0)),0,VLOOKUP(A18,QW_CloseDL!A:E,5,0)) -> 0.037132397 | J18: =IF(ISNA(IF(NOT(ISBLANK(A18)),ABS(G18-I18),"")),0,(IF(NOT(ISBLANK(A18)),ABS(G18-I18)*10000,""))) -> 0 | P18: 0 | Q18: =VLOOKUP(P18,A:B,2,0) -> #N/A | R18: =VLOOKUP(P18,A:E,4,0) -> #N/A | S18: =VLOOKUP(P18,A:J,10,0) -> #N/A | T18: =VLOOKUP(P18,A:J,5,0) -> #N/A
A19: 912797TX5 | B19: =IF(NOT(ISBLANK(A19)),VLOOKUP(A19,'BBT3'!A:F,2,0),"") -> Bill | C19: =IF(NOT(ISBLANK(A19)),VLOOKUP(A19,'BBT3'!A:F,3,0),"") -> US912797TX52 | D19: =IF(NOT(ISBLANK(A19)),VLOOKUP(A19,'BBT3'!A:F,4,1),"") -> 0 | E19: =IF(NOT(ISBLANK(A19)),VLOOKUP(A19,'BBT3'!A:F,5,0),"") -> 46254 | F19: =IF(NOT(ISBLANK(A19)),VLOOKUP(A19,'BBT3'!A:F,6,0),"") -> N | G19: =IF(NOT(ISBLANK(A19)),VLOOKUP(A19,QW_Close!A:J,5,0),"") -> 0.037113915 | H19: {=IF(NOT(ISBLANK(A19)),((_xlfn.XLOOKUP(1,(_bbt3[[#All],[ID]]=A19)*(_bbt3[[#All],[METRIC_NAME]]="YLD_YTM_ASK"),_bbt3[[#All],[METRIC_VALUE]])*0.5)+(_xlfn.XLOOKUP(1,(_bbt3[[#All],[ID]]=A19)*(_bbt3[[#All],[METRIC_NAME]]="YLD_YTM_BID"),_bbt3[[#All],[METRIC_VALUE]])*0.5))/100,"")} -> #N/A | I19: =IF(ISNA(VLOOKUP(A19,QW_CloseDL!A:E,5,0)),0,VLOOKUP(A19,QW_CloseDL!A:E,5,0)) -> 0.037113915 | J19: =IF(ISNA(IF(NOT(ISBLANK(A19)),ABS(G19-I19),"")),0,(IF(NOT(ISBLANK(A19)),ABS(G19-I19)*10000,""))) -> 0 | P19: 0 | Q19: =VLOOKUP(P19,A:B,2,0) -> #N/A | R19: =VLOOKUP(P19,A:E,4,0) -> #N/A | S19: =VLOOKUP(P19,A:J,10,0) -> #N/A | T19: =VLOOKUP(P19,A:J,5,0) -> #N/A
A20: 912797TY3 | B20: =IF(NOT(ISBLANK(A20)),VLOOKUP(A20,'BBT3'!A:F,2,0),"") -> Bill | C20: =IF(NOT(ISBLANK(A20)),VLOOKUP(A20,'BBT3'!A:F,3,0),"") -> US912797TY36 | D20: =IF(NOT(ISBLANK(A20)),VLOOKUP(A20,'BBT3'!A:F,4,1),"") -> 0 | E20: =IF(NOT(ISBLANK(A20)),VLOOKUP(A20,'BBT3'!A:F,5,0),"") -> 46261 | F20: =IF(NOT(ISBLANK(A20)),VLOOKUP(A20,'BBT3'!A:F,6,0),"") -> N | G20: =IF(NOT(ISBLANK(A20)),VLOOKUP(A20,QW_Close!A:J,5,0),"") -> 0.037148512 | H20: {=IF(NOT(ISBLANK(A20)),((_xlfn.XLOOKUP(1,(_bbt3[[#All],[ID]]=A20)*(_bbt3[[#All],[METRIC_NAME]]="YLD_YTM_ASK"),_bbt3[[#All],[METRIC_VALUE]])*0.5)+(_xlfn.XLOOKUP(1,(_bbt3[[#All],[ID]]=A20)*(_bbt3[[#All],[METRIC_NAME]]="YLD_YTM_BID"),_bbt3[[#All],[METRIC_VALUE]])*0.5))/100,"")} -> #N/A | I20: =IF(ISNA(VLOOKUP(A20,QW_CloseDL!A:E,5,0)),0,VLOOKUP(A20,QW_CloseDL!A:E,5,0)) -> 0.037148512 | J20: =IF(ISNA(IF(NOT(ISBLANK(A20)),ABS(G20-I20),"")),0,(IF(NOT(ISBLANK(A20)),ABS(G20-I20)*10000,""))) -> 0 | P20: 0 | Q20: =VLOOKUP(P20,A:B,2,0) -> #N/A | R20: =VLOOKUP(P20,A:E,4,0) -> #N/A | S20: =VLOOKUP(P20,A:J,10,0) -> #N/A | T20: =VLOOKUP(P20,A:J,5,0) -> #N/A
A21: 912797TZ0 | B21: =IF(NOT(ISBLANK(A21)),VLOOKUP(A21,'BBT3'!A:F,2,0),"") -> Bill | C21: =IF(NOT(ISBLANK(A21)),VLOOKUP(A21,'BBT3'!A:F,3,0),"") -> US912797TZ01 | D21: =IF(NOT(ISBLANK(A21)),VLOOKUP(A21,'BBT3'!A:F,4,1),"") -> 0 | E21: =IF(NOT(ISBLANK(A21)),VLOOKUP(A21,'BBT3'!A:F,5,0),"") -> 46182 | F21: =IF(NOT(ISBLANK(A21)),VLOOKUP(A21,'BBT3'!A:F,6,0),"") -> N | G21: =IF(NOT(ISBLANK(A21)),VLOOKUP(A21,QW_Close!A:J,5,0),"") -> 0.036725295 | H21: {=IF(NOT(ISBLANK(A21)),((_xlfn.XLOOKUP(1,(_bbt3[[#All],[ID]]=A21)*(_bbt3[[#All],[METRIC_NAME]]="YLD_YTM_ASK"),_bbt3[[#All],[METRIC_VALUE]])*0.5)+(_xlfn.XLOOKUP(1,(_bbt3[[#All],[ID]]=A21)*(_bbt3[[#All],[METRIC_NAME]]="YLD_YTM_BID"),_bbt3[[#All],[METRIC_VALUE]])*0.5))/100,"")} -> 0.036399438 | I21: =IF(ISNA(VLOOKUP(A21,QW_CloseDL!A:E,5,0)),0,VLOOKUP(A21,QW_CloseDL!A:E,5,0)) -> 0.036725295 | J21: =IF(ISNA(IF(NOT(ISBLANK(A21)),ABS(G21-I21),"")),0,(IF(NOT(ISBLANK(A21)),ABS(G21-I21)*10000,""))) -> 0 | P21: 0 | Q21: =VLOOKUP(P21,A:B,2,0) -> #N/A | R21: =VLOOKUP(P21,A:E,4,0) -> #N/A | S21: =VLOOKUP(P21,A:J,10,0) -> #N/A | T21: =VLOOKUP(P21,A:J,5,0) -> #N/A
A22: 912797UA3 | B22: =IF(NOT(ISBLANK(A22)),VLOOKUP(A22,'BBT3'!A:F,2,0),"") -> Bill | C22: =IF(NOT(ISBLANK(A22)),VLOOKUP(A22,'BBT3'!A:F,3,0),"") -> US912797UA31 | D22: =IF(NOT(ISBLANK(A22)),VLOOKUP(A22,'BBT3'!A:F,4,1),"") -> 0 | E22: =IF(NOT(ISBLANK(A22)),VLOOKUP(A22,'BBT3'!A:F,5,0),"") -> 46189 | F22: =IF(NOT(ISBLANK(A22)),VLOOKUP(A22,'BBT3'!A:F,6,0),"") -> N | G22: =IF(NOT(ISBLANK(A22)),VLOOKUP(A22,QW_Close!A:J,5,0),"") -> 0.036747538 | H22: {=IF(NOT(ISBLANK(A22)),((_xlfn.XLOOKUP(1,(_bbt3[[#All],[ID]]=A22)*(_bbt3[[#All],[METRIC_NAME]]="YLD_YTM_ASK"),_bbt3[[#All],[METRIC_VALUE]])*0.5)+(_xlfn.XLOOKUP(1,(_bbt3[[#All],[ID]]=A22)*(_bbt3[[#All],[METRIC_NAME]]="YLD_YTM_BID"),_bbt3[[#All],[METRIC_VALUE]])*0.5))/100,"")} -> #N/A | I22: =IF(ISNA(VLOOKUP(A22,QW_CloseDL!A:E,5,0)),0,VLOOKUP(A22,QW_CloseDL!A:E,5,0)) -> 0.036747538 | J22: =IF(ISNA(IF(NOT(ISBLANK(A22)),ABS(G22-I22),"")),0,(IF(NOT(ISBLANK(A22)),ABS(G22-I22)*10000,""))) -> 0 | P22: 0 | Q22: =VLOOKUP(P22,A:B,2,0) -> #N/A | R22: =VLOOKUP(P22,A:E,4,0) -> #N/A | S22: =VLOOKUP(P22,A:J,10,0) -> #N/A | T22: =VLOOKUP(P22,A:J,5,0) -> #N/A
A23: 912797UB1 | B23: =IF(NOT(ISBLANK(A23)),VLOOKUP(A23,'BBT3'!A:F,2,0),"") -> Bill | C23: =IF(NOT(ISBLANK(A23)),VLOOKUP(A23,'BBT3'!A:F,3,0),"") -> US912797UB14 | D23: =IF(NOT(ISBLANK(A23)),VLOOKUP(A23,'BBT3'!A:F,4,1),"") -> 0 | E23: =IF(NOT(ISBLANK(A23)),VLOOKUP(A23,'BBT3'!A:F,5,0),"") -> 46196 | F23: =IF(NOT(ISBLANK(A23)),VLOOKUP(A23,'BBT3'!A:F,6,0),"") -> N | G23: =IF(NOT(ISBLANK(A23)),VLOOKUP(A23,QW_Close!A:J,5,0),"") -> 0.036771358 | H23: {=IF(NOT(ISBLANK(A23)),((_xlfn.XLOOKUP(1,(_bbt3[[#All],[ID]]=A23)*(_bbt3[[#All],[METRIC_NAME]]="YLD_YTM_ASK"),_bbt3[[#All],[METRIC_VALUE]])*0.5)+(_xlfn.XLOOKUP(1,(_bbt3[[#All],[ID]]=A23)*(_bbt3[[#All],[METRIC_NAME]]="YLD_YTM_BID"),_bbt3[[#All],[METRIC_VALUE]])*0.5))/100,"")} -> 0.03647017 | I23: =IF(ISNA(VLOOKUP(A23,QW_CloseDL!A:E,5,0)),0,VLOOKUP(A23,QW_CloseDL!A:E,5,0)) -> 0.036771358 | J23: =IF(ISNA(IF(NOT(ISBLANK(A23)),ABS(G23-I23),"")),0,(IF(NOT(ISBLANK(A23)),ABS(G23-I23)*10000,""))) -> 0 | P23: 0 | Q23: =VLOOKUP(P23,A:B,2,0) -> #N/A | R23: =VLOOKUP(P23,A:E,4,0) -> #N/A | S23: =VLOOKUP(P23,A:J,10,0) -> #N/A | T23: =VLOOKUP(P23,A:J,5,0) -> #N/A
A24: 912797UC9 | B24: =IF(NOT(ISBLANK(A24)),VLOOKUP(A24,'BBT3'!A:F,2,0),"") -> Bill | C24: =IF(NOT(ISBLANK(A24)),VLOOKUP(A24,'BBT3'!A:F,3,0),"") -> US912797UC96 | D24: =IF(NOT(ISBLANK(A24)),VLOOKUP(A24,'BBT3'!A:F,4,1),"") -> 0 | E24: =IF(NOT(ISBLANK(A24)),VLOOKUP(A24,'BBT3'!A:F,5,0),"") -> 46203 | F24: =IF(NOT(ISBLANK(A24)),VLOOKUP(A24,'BBT3'!A:F,6,0),"") -> N | G24: =IF(NOT(ISBLANK(A24)),VLOOKUP(A24,QW_Close!A:J,5,0),"") -> 0.036913732 | H24: {=IF(NOT(ISBLANK(A24)),((_xlfn.XLOOKUP(1,(_bbt3[[#All],[ID]]=A24)*(_bbt3[[#All],[METRIC_NAME]]="YLD_YTM_ASK"),_bbt3[[#All],[METRIC_VALUE]])*0.5)+(_xlfn.XLOOKUP(1,(_bbt3[[#All],[ID]]=A24)*(_bbt3[[#All],[METRIC_NAME]]="YLD_YTM_BID"),_bbt3[[#All],[METRIC_VALUE]])*0.5))/100,"")} -> 0.036623067 | I24: =IF(ISNA(VLOOKUP(A24,QW_CloseDL!A:E,5,0)),0,VLOOKUP(A24,QW_CloseDL!A:E,5,0)) -> 0.036913732 | J24: =IF(ISNA(IF(NOT(ISBLANK(A24)),ABS(G24-I24),"")),0,(IF(NOT(ISBLANK(A24)),ABS(G24-I24)*10000,""))) -> 0 | P24: 0 | Q24: =VLOOKUP(P24,A:B,2,0) -> #N/A | R24: =VLOOKUP(P24,A:E,4,0) -> #N/A | S24: =VLOOKUP(P24,A:J,10,0) -> #N/A | T24: =VLOOKUP(P24,A:J,5,0) -> #N/A
A25: 912797UD7 | B25: =IF(NOT(ISBLANK(A25)),VLOOKUP(A25,'BBT3'!A:F,2,0),"") -> Bill | C25: =IF(NOT(ISBLANK(A25)),VLOOKUP(A25,'BBT3'!A:F,3,0),"") -> US912797UD79 | D25: =IF(NOT(ISBLANK(A25)),VLOOKUP(A25,'BBT3'!A:F,4,1),"") -> 0 | E25: =IF(NOT(ISBLANK(A25)),VLOOKUP(A25,'BBT3'!A:F,5,0),"") -> 46464 | F25: =IF(NOT(ISBLANK(A25)),VLOOKUP(A25,'BBT3'!A:F,6,0),"") -> N | G25: =IF(NOT(ISBLANK(A25)),VLOOKUP(A25,QW_Close!A:J,5,0),"") -> 0.037468535 | H25: {=IF(NOT(ISBLANK(A25)),((_xlfn.XLOOKUP(1,(_bbt3[[#All],[ID]]=A25)*(_bbt3[[#All],[METRIC_NAME]]="YLD_YTM_ASK"),_bbt3[[#All],[METRIC_VALUE]])*0.5)+(_xlfn.XLOOKUP(1,(_bbt3[[#All],[ID]]=A25)*(_bbt3[[#All],[METRIC_NAME]]="YLD_YTM_BID"),_bbt3[[#All],[METRIC_VALUE]])*0.5))/100,"")} -> 0.037413772 | I25: =IF(ISNA(VLOOKUP(A25,QW_CloseDL!A:E,5,0)),0,VLOOKUP(A25,QW_CloseDL!A:E,5,0)) -> 0.037468535 | J25: =IF(ISNA(IF(NOT(ISBLANK(A25)),ABS(G25-I25),"")),0,(IF(NOT(ISBLANK(A25)),ABS(G25-I25)*10000,""))) -> 0 | P25: 0 | Q25: =VLOOKUP(P25,A:B,2,0) -> #N/A | R25: =VLOOKUP(P25,A:E,4,0) -> #N/A | S25: =VLOOKUP(P25,A:J,10,0) -> #N/A | T25: =VLOOKUP(P25,A:J,5,0) -> #N/A
A26: 912797UE5 | B26: =IF(NOT(ISBLANK(A26)),VLOOKUP(A26,'BBT3'!A:F,2,0),"") -> Bill | C26: =IF(NOT(ISBLANK(A26)),VLOOKUP(A26,'BBT3'!A:F,3,0),"") -> US912797UE52 | D26: =IF(NOT(ISBLANK(A26)),VLOOKUP(A26,'BBT3'!A:F,4,1),"") -> 0 | E26: =IF(NOT(ISBLANK(A26)),VLOOKUP(A26,'BBT3'!A:F,5,0),"") -> 46492 | F26: =IF(NOT(ISBLANK(A26)),VLOOKUP(A26,'BBT3'!A:F,6,0),"") -> N | G26: =IF(NOT(ISBLANK(A26)),VLOOKUP(A26,QW_Close!A:J,5,0),"") -> 0.037943857 | H26: {=IF(NOT(ISBLANK(A26)),((_xlfn.XLOOKUP(1,(_bbt3[[#All],[ID]]=A26)*(_bbt3[[#All],[METRIC_NAME]]="YLD_YTM_ASK"),_bbt3[[#All],[METRIC_VALUE]])*0.5)+(_xlfn.XLOOKUP(1,(_bbt3[[#All],[ID]]=A26)*(_bbt3[[#All],[METRIC_NAME]]="YLD_YTM_BID"),_bbt3[[#All],[METRIC_VALUE]])*0.5))/100,"")} -> 0.037901945 | I26: =IF(ISNA(VLOOKUP(A26,QW_CloseDL!A:E,5,0)),0,VLOOKUP(A26,QW_CloseDL!A:E,5,0)) -> 0.037943857 | J26: =IF(ISNA(IF(NOT(ISBLANK(A26)),ABS(G26-I26),"")),0,(IF(NOT(ISBLANK(A26)),ABS(G26-I26)*10000,""))) -> 0 | P26: 0 | Q26: =VLOOKUP(P26,A:B,2,0) -> #N/A | R26: =VLOOKUP(P26,A:E,4,0) -> #N/A | S26: =VLOOKUP(P26,A:J,10,0) -> #N/A | T26: =VLOOKUP(P26,A:J,5,0) -> #N/A
A27: 912797UF2 | B27: =IF(NOT(ISBLANK(A27)),VLOOKUP(A27,'BBT3'!A:F,2,0),"") -> Bill | C27: =IF(NOT(ISBLANK(A27)),VLOOKUP(A27,'BBT3'!A:F,3,0),"") -> US912797UF28 | D27: =IF(NOT(ISBLANK(A27)),VLOOKUP(A27,'BBT3'!A:F,4,1),"") -> 0 | E27: =IF(NOT(ISBLANK(A27)),VLOOKUP(A27,'BBT3'!A:F,5,0),"") -> 46275 | F27: =IF(NOT(ISBLANK(A27)),VLOOKUP(A27,'BBT3'!A:F,6,0),"") -> N | G27: =IF(NOT(ISBLANK(A27)),VLOOKUP(A27,QW_Close!A:J,5,0),"") -> 0.037137532 | H27: {=IF(NOT(ISBLANK(A27)),((_xlfn.XLOOKUP(1,(_bbt3[[#All],[ID]]=A27)*(_bbt3[[#All],[METRIC_NAME]]="YLD_YTM_ASK"),_bbt3[[#All],[METRIC_VALUE]])*0.5)+(_xlfn.XLOOKUP(1,(_bbt3[[#All],[ID]]=A27)*(_bbt3[[#All],[METRIC_NAME]]="YLD_YTM_BID"),_bbt3[[#All],[METRIC_VALUE]])*0.5))/100,"")} -> 0.03697745 | I27: =IF(ISNA(VLOOKUP(A27,QW_CloseDL!A:E,5,0)),0,VLOOKUP(A27,QW_CloseDL!A:E,5,0)) -> 0.037137532 | J27: =IF(ISNA(IF(NOT(ISBLANK(A27)),ABS(G27-I27),"")),0,(IF(NOT(ISBLANK(A27)),ABS(G27-I27)*10000,""))) -> 0 | P27: 0 | Q27: =VLOOKUP(P27,A:B,2,0) -> #N/A | R27: =VLOOKUP(P27,A:E,4,0) -> #N/A | S27: =VLOOKUP(P27,A:J,10,0) -> #N/A | T27: =VLOOKUP(P27,A:J,5,0) -> #N/A
... A127: 912810FA1 | B127: =IF(NOT(ISBLANK(A127)),VLOOKUP(A127,'BBT3'!A:F,2,0),"") -> Bond | C127: =IF(NOT(ISBLANK(A127)),VLOOKUP(A127,'BBT3'!A:F,3,0),"") -> US912810FA17 | D127: =IF(NOT(ISBLANK(A127)),VLOOKUP(A127,'BBT3'!A:F,4,1),"") -> 6.375 | E127: =IF(NOT(ISBLANK(A127)),VLOOKUP(A127,'BBT3'!A:F,5,0),"") -> 46614 | F127: =IF(NOT(ISBLANK(A127)),VLOOKUP(A127,'BBT3'!A:F,6,0),"") -> N | G127: =IF(NOT(ISBLANK(A127)),VLOOKUP(A127,QW_Close!A:J,5,0),"") -> 0.03925164 | H127: {=IF(NOT(ISBLANK(A127)),((_xlfn.XLOOKUP(1,(_bbt3[[#All],[ID]]=A127)*(_bbt3[[#All],[METRIC_NAME]]="YLD_YTM_ASK"),_bbt3[[#All],[METRIC_VALUE]])*0.5)+(_xlfn.XLOOKUP(1,(_bbt3[[#All],[ID]]=A127)*(_bbt3[[#All],[METRIC_NAME]]="YLD_YTM_BID"),_bbt3[[#All],[METRIC_VALUE]])*0.5))/100,"")} -> #N/A | I127: =IF(ISNA(VLOOKUP(A127,QW_CloseDL!A:E,5,0)),0,VLOOKUP(A127,QW_CloseDL!A:E,5,0)) -> 0.03925164 | J127: =IF(ISNA(IF(NOT(ISBLANK(A127)),ABS(G127-I127),"")),0,(IF(NOT(ISBLANK(A127)),ABS(G127-I127)*10000,""))) -> 0 | P127: 0 | Q127: =VLOOKUP(P127,A:B,2,0) -> #N/A | R127: =VLOOKUP(P127,A:E,4,0) -> #N/A | S127: =VLOOKUP(P127,A:J,10,0) -> #N/A | T127: =VLOOKUP(P127,A:J,5,0) -> #N/A
A128: 912810FB9 | B128: =IF(NOT(ISBLANK(A128)),VLOOKUP(A128,'BBT3'!A:F,2,0),"") -> Bond | C128: =IF(NOT(ISBLANK(A128)),VLOOKUP(A128,'BBT3'!A:F,3,0),"") -> US912810FB99 | D128: =IF(NOT(ISBLANK(A128)),VLOOKUP(A128,'BBT3'!A:F,4,1),"") -> 6.125 | E128: =IF(NOT(ISBLANK(A128)),VLOOKUP(A128,'BBT3'!A:F,5,0),"") -> 46706 | F128: =IF(NOT(ISBLANK(A128)),VLOOKUP(A128,'BBT3'!A:F,6,0),"") -> N | G128: =IF(NOT(ISBLANK(A128)),VLOOKUP(A128,QW_Close!A:J,5,0),"") -> 0.039686903 | H128: {=IF(NOT(ISBLANK(A128)),((_xlfn.XLOOKUP(1,(_bbt3[[#All],[ID]]=A128)*(_bbt3[[#All],[METRIC_NAME]]="YLD_YTM_ASK"),_bbt3[[#All],[METRIC_VALUE]])*0.5)+(_xlfn.XLOOKUP(1,(_bbt3[[#All],[ID]]=A128)*(_bbt3[[#All],[METRIC_NAME]]="YLD_YTM_BID"),_bbt3[[#All],[METRIC_VALUE]])*0.5))/100,"")} -> #N/A | I128: =IF(ISNA(VLOOKUP(A128,QW_CloseDL!A:E,5,0)),0,VLOOKUP(A128,QW_CloseDL!A:E,5,0)) -> 0.039686903 | J128: =IF(ISNA(IF(NOT(ISBLANK(A128)),ABS(G128-I128),"")),0,(IF(NOT(ISBLANK(A128)),ABS(G128-I128)*10000,""))) -> 0 | M128: 104.05859 | P128: 0 | Q128: =VLOOKUP(P128,A:B,2,0) -> #N/A | R128: =VLOOKUP(P128,A:E,4,0) -> #N/A | S128: =VLOOKUP(P128,A:J,10,0) -> #N/A | T128: =VLOOKUP(P128,A:J,5,0) -> #N/A
A129: 912810FD5 | B129: =IF(NOT(ISBLANK(A129)),VLOOKUP(A129,'BBT3'!A:F,2,0),"") -> Bond | C129: =IF(NOT(ISBLANK(A129)),VLOOKUP(A129,'BBT3'!A:F,3,0),"") -> US912810FD55 | D129: =IF(NOT(ISBLANK(A129)),VLOOKUP(A129,'BBT3'!A:F,4,1),"") -> 3.625 | E129: =IF(NOT(ISBLANK(A129)),VLOOKUP(A129,'BBT3'!A:F,5,0),"") -> 46858 | F129: =IF(NOT(ISBLANK(A129)),VLOOKUP(A129,'BBT3'!A:F,6,0),"") -> Y | G129: =IF(NOT(ISBLANK(A129)),VLOOKUP(A129,QW_Close!A:J,5,0),"") -> 0.013651311 | H129: {=IF(NOT(ISBLANK(A129)),((_xlfn.XLOOKUP(1,(_bbt3[[#All],[ID]]=A129)*(_bbt3[[#All],[METRIC_NAME]]="YLD_YTM_ASK"),_bbt3[[#All],[METRIC_VALUE]])*0.5)+(_xlfn.XLOOKUP(1,(_bbt3[[#All],[ID]]=A129)*(_bbt3[[#All],[METRIC_NAME]]="YLD_YTM_BID"),_bbt3[[#All],[METRIC_VALUE]])*0.5))/100,"")} -> #N/A | I129: =IF(ISNA(VLOOKUP(A129,QW_CloseDL!A:E,5,0)),0,VLOOKUP(A129,QW_CloseDL!A:E,5,0)) -> 0.014066998 | J129: =IF(ISNA(IF(NOT(ISBLANK(A129)),ABS(G129-I129),"")),0,(IF(NOT(ISBLANK(A129)),ABS(G129-I129)*10000,""))) -> 4.1568743 | K129: X | M129: {=_xll.qwYield(P1,C129,0)} -> #NUM! | P129: 0 | Q129: =VLOOKUP(P129,A:B,2,0) -> #N/A | R129: =VLOOKUP(P129,A:E,4,0) -> #N/A | S129: =VLOOKUP(P129,A:J,10,0) -> #N/A | T129: =VLOOKUP(P129,A:J,5,0) -> #N/A
A130: 912810FE3 | B130: =IF(NOT(ISBLANK(A130)),VLOOKUP(A130,'BBT3'!A:F,2,0),"") -> Bond | C130: =IF(NOT(ISBLANK(A130)),VLOOKUP(A130,'BBT3'!A:F,3,0),"") -> US912810FE39 | D130: =IF(NOT(ISBLANK(A130)),VLOOKUP(A130,'BBT3'!A:F,4,1),"") -> 5.5 | E130: =IF(NOT(ISBLANK(A130)),VLOOKUP(A130,'BBT3'!A:F,5,0),"") -> 46980 | F130: =IF(NOT(ISBLANK(A130)),VLOOKUP(A130,'BBT3'!A:F,6,0),"") -> N | G130: =IF(NOT(ISBLANK(A130)),VLOOKUP(A130,QW_Close!A:J,5,0),"") -> 0.040423886 | H130: {=IF(NOT(ISBLANK(A130)),((_xlfn.XLOOKUP(1,(_bbt3[[#All],[ID]]=A130)*(_bbt3[[#All],[METRIC_NAME]]="YLD_YTM_ASK"),_bbt3[[#All],[METRIC_VALUE]])*0.5)+(_xlfn.XLOOKUP(1,(_bbt3[[#All],[ID]]=A130)*(_bbt3[[#All],[METRIC_NAME]]="YLD_YTM_BID"),_bbt3[[#All],[METRIC_VALUE]])*0.5))/100,"")} -> #N/A | I130: =IF(ISNA(VLOOKUP(A130,QW_CloseDL!A:E,5,0)),0,VLOOKUP(A130,QW_CloseDL!A:E,5,0)) -> 0.040423886 | J130: =IF(ISNA(IF(NOT(ISBLANK(A130)),ABS(G130-I130),"")),0,(IF(NOT(ISBLANK(A130)),ABS(G130-I130)*10000,""))) -> 0 | M130: {=_xll.qwPrice(P1,C129)} -> #NUM! | P130: 0 | Q130: =VLOOKUP(P130,A:B,2,0) -> #N/A | R130: =VLOOKUP(P130,A:E,4,0) -> #N/A | S130: =VLOOKUP(P130,A:J,10,0) -> #N/A | T130: =VLOOKUP(P130,A:J,5,0) -> #N/A
A131: 912810FF0 | B131: =IF(NOT(ISBLANK(A131)),VLOOKUP(A131,'BBT3'!A:F,2,0),"") -> Bond | C131: =IF(NOT(ISBLANK(A131)),VLOOKUP(A131,'BBT3'!A:F,3,0),"") -> US912810FF04 | D131: =IF(NOT(ISBLANK(A131)),VLOOKUP(A131,'BBT3'!A:F,4,1),"") -> 5.25 | E131: =IF(NOT(ISBLANK(A131)),VLOOKUP(A131,'BBT3'!A:F,5,0),"") -> 47072 | F131: =IF(NOT(ISBLANK(A131)),VLOOKUP(A131,'BBT3'!A:F,6,0),"") -> N | G131: =IF(NOT(ISBLANK(A131)),VLOOKUP(A131,QW_Close!A:J,5,0),"") -> 0.040701133 | H131: {=IF(NOT(ISBLANK(A131)),((_xlfn.XLOOKUP(1,(_bbt3[[#All],[ID]]=A131)*(_bbt3[[#All],[METRIC_NAME]]="YLD_YTM_ASK"),_bbt3[[#All],[METRIC_VALUE]])*0.5)+(_xlfn.XLOOKUP(1,(_bbt3[[#All],[ID]]=A131)*(_bbt3[[#All],[METRIC_NAME]]="YLD_YTM_BID"),_bbt3[[#All],[METRIC_VALUE]])*0.5))/100,"")} -> #N/A | I131: =IF(ISNA(VLOOKUP(A131,QW_CloseDL!A:E,5,0)),0,VLOOKUP(A131,QW_CloseDL!A:E,5,0)) -> 0.040701133 | J131: =IF(ISNA(IF(NOT(ISBLANK(A131)),ABS(G131-I131),"")),0,(IF(NOT(ISBLANK(A131)),ABS(G131-I131)*10000,""))) -> 0 | P131: 0 | Q131: =VLOOKUP(P131,A:B,2,0) -> #N/A | R131: =VLOOKUP(P131,A:E,4,0) -> #N/A | S131: =VLOOKUP(P131,A:J,10,0) -> #N/A | T131: =VLOOKUP(P131,A:J,5,0) -> #N/A
A132: 912810FG8 | B132: =IF(NOT(ISBLANK(A132)),VLOOKUP(A132,'BBT3'!A:F,2,0),"") -> Bond | C132: =IF(NOT(ISBLANK(A132)),VLOOKUP(A132,'BBT3'!A:F,3,0),"") -> US912810FG86 | D132: =IF(NOT(ISBLANK(A132)),VLOOKUP(A132,'BBT3'!A:F,4,1),"") -> 5.25 | E132: =IF(NOT(ISBLANK(A132)),VLOOKUP(A132,'BBT3'!A:F,5,0),"") -> 47164 | F132: =IF(NOT(ISBLANK(A132)),VLOOKUP(A132,'BBT3'!A:F,6,0),"") -> N | G132: =IF(NOT(ISBLANK(A132)),VLOOKUP(A132,QW_Close!A:J,5,0),"") -> 0.039676947 | H132: {=IF(NOT(ISBLANK(A132)),((_xlfn.XLOOKUP(1,(_bbt3[[#All],[ID]]=A132)*(_bbt3[[#All],[METRIC_NAME]]="YLD_YTM_ASK"),_bbt3[[#All],[METRIC_VALUE]])*0.5)+(_xlfn.XLOOKUP(1,(_bbt3[[#All],[ID]]=A132)*(_bbt3[[#All],[METRIC_NAME]]="YLD_YTM_BID"),_bbt3[[#All],[METRIC_VALUE]])*0.5))/100,"")} -> #N/A | I132: =IF(ISNA(VLOOKUP(A132,QW_CloseDL!A:E,5,0)),0,VLOOKUP(A132,QW_CloseDL!A:E,5,0)) -> 0.039676947 | J132: =IF(ISNA(IF(NOT(ISBLANK(A132)),ABS(G132-I132),"")),0,(IF(NOT(ISBLANK(A132)),ABS(G132-I132)*10000,""))) -> 0 | P132: 0 | Q132: =VLOOKUP(P132,A:B,2,0) -> #N/A | R132: =VLOOKUP(P132,A:E,4,0) -> #N/A | S132: =VLOOKUP(P132,A:J,10,0) -> #N/A | T132: =VLOOKUP(P132,A:J,5,0) -> #N/A
A133: 912810FH6 | B133: =IF(NOT(ISBLANK(A133)),VLOOKUP(A133,'BBT3'!A:F,2,0),"") -> Bond | C133: =IF(NOT(ISBLANK(A133)),VLOOKUP(A133,'BBT3'!A:F,3,0),"") -> US912810FH69 | D133: =IF(NOT(ISBLANK(A133)),VLOOKUP(A133,'BBT3'!A:F,4,1),"") -> 3.875 | E133: =IF(NOT(ISBLANK(A133)),VLOOKUP(A133,'BBT3'!A:F,5,0),"") -> 47223 | F133: =IF(NOT(ISBLANK(A133)),VLOOKUP(A133,'BBT3'!A:F,6,0),"") -> Y | G133: =IF(NOT(ISBLANK(A133)),VLOOKUP(A133,QW_Close!A:J,5,0),"") -> 0.014917874 | H133: {=IF(NOT(ISBLANK(A133)),((_xlfn.XLOOKUP(1,(_bbt3[[#All],[ID]]=A133)*(_bbt3[[#All],[METRIC_NAME]]="YLD_YTM_ASK"),_bbt3[[#All],[METRIC_VALUE]])*0.5)+(_xlfn.XLOOKUP(1,(_bbt3[[#All],[ID]]=A133)*(_bbt3[[#All],[METRIC_NAME]]="YLD_YTM_BID"),_bbt3[[#All],[METRIC_VALUE]])*0.5))/100,"")} -> #N/A | I133: =IF(ISNA(VLOOKUP(A133,QW_CloseDL!A:E,5,0)),0,VLOOKUP(A133,QW_CloseDL!A:E,5,0)) -> 0.015268106 | J133: =IF(ISNA(IF(NOT(ISBLANK(A133)),ABS(G133-I133),"")),0,(IF(NOT(ISBLANK(A133)),ABS(G133-I133)*10000,""))) -> 3.5023207 | P133: 0 | Q133: =VLOOKUP(P133,A:B,2,0) -> #N/A | R133: =VLOOKUP(P133,A:E,4,0) -> #N/A | S133: =VLOOKUP(P133,A:J,10,0) -> #N/A | T133: =VLOOKUP(P133,A:J,5,0) -> #N/A
A134: 912810FJ2 | B134: =IF(NOT(ISBLANK(A134)),VLOOKUP(A134,'BBT3'!A:F,2,0),"") -> Bond | C134: =IF(NOT(ISBLANK(A134)),VLOOKUP(A134,'BBT3'!A:F,3,0),"") -> US912810FJ26 | D134: =IF(NOT(ISBLANK(A134)),VLOOKUP(A134,'BBT3'!A:F,4,1),"") -> 6.125 | E134: =IF(NOT(ISBLANK(A134)),VLOOKUP(A134,'BBT3'!A:F,5,0),"") -> 47345 | F134: =IF(NOT(ISBLANK(A134)),VLOOKUP(A134,'BBT3'!A:F,6,0),"") -> N | G134: =IF(NOT(ISBLANK(A134)),VLOOKUP(A134,QW_Close!A:J,5,0),"") -> 0.041067342 | H134: {=IF(NOT(ISBLANK(A134)),((_xlfn.XLOOKUP(1,(_bbt3[[#All],[ID]]=A134)*(_bbt3[[#All],[METRIC_NAME]]="YLD_YTM_ASK"),_bbt3[[#All],[METRIC_VALUE]])*0.5)+(_xlfn.XLOOKUP(1,(_bbt3[[#All],[ID]]=A134)*(_bbt3[[#All],[METRIC_NAME]]="YLD_YTM_BID"),_bbt3[[#All],[METRIC_VALUE]])*0.5))/100,"")} -> #N/A | I134: =IF(ISNA(VLOOKUP(A134,QW_CloseDL!A:E,5,0)),0,VLOOKUP(A134,QW_CloseDL!A:E,5,0)) -> 0.041067342 | J134: =IF(ISNA(IF(NOT(ISBLANK(A134)),ABS(G134-I134),"")),0,(IF(NOT(ISBLANK(A134)),ABS(G134-I134)*10000,""))) -> 0 | P134: 0 | Q134: =VLOOKUP(P134,A:B,2,0) -> #N/A | R134: =VLOOKUP(P134,A:E,4,0) -> #N/A | S134: =VLOOKUP(P134,A:J,10,0) -> #N/A | T134: =VLOOKUP(P134,A:J,5,0) -> #N/A
A135: 912810FM5 | B135: =IF(NOT(ISBLANK(A135)),VLOOKUP(A135,'BBT3'!A:F,2,0),"") -> Bond | C135: =IF(NOT(ISBLANK(A135)),VLOOKUP(A135,'BBT3'!A:F,3,0),"") -> US912810FM54 | D135: =IF(NOT(ISBLANK(A135)),VLOOKUP(A135,'BBT3'!A:F,4,1),"") -> 6.25 | E135: =IF(NOT(ISBLANK(A135)),VLOOKUP(A135,'BBT3'!A:F,5,0),"") -> 47618 | F135: =IF(NOT(ISBLANK(A135)),VLOOKUP(A135,'BBT3'!A:F,6,0),"") -> N | G135: =IF(NOT(ISBLANK(A135)),VLOOKUP(A135,QW_Close!A:J,5,0),"") -> 0.041438969 | H135: {=IF(NOT(ISBLANK(A135)),((_xlfn.XLOOKUP(1,(_bbt3[[#All],[ID]]=A135)*(_bbt3[[#All],[METRIC_NAME]]="YLD_YTM_ASK"),_bbt3[[#All],[METRIC_VALUE]])*0.5)+(_xlfn.XLOOKUP(1,(_bbt3[[#All],[ID]]=A135)*(_bbt3[[#All],[METRIC_NAME]]="YLD_YTM_BID"),_bbt3[[#All],[METRIC_VALUE]])*0.5))/100,"")} -> #N/A | I135: =IF(ISNA(VLOOKUP(A135,QW_CloseDL!A:E,5,0)),0,VLOOKUP(A135,QW_CloseDL!A:E,5,0)) -> 0.041438969 | J135: =IF(ISNA(IF(NOT(ISBLANK(A135)),ABS(G135-I135),"")),0,(IF(NOT(ISBLANK(A135)),ABS(G135-I135)*10000,""))) -> 0 | P135: 0 | Q135: =VLOOKUP(P135,A:B,2,0) -> #N/A | R135: =VLOOKUP(P135,A:E,4,0) -> #N/A | S135: =VLOOKUP(P135,A:J,10,0) -> #N/A | T135: =VLOOKUP(P135,A:J,5,0) -> #N/A
A136: 912810FP8 | B136: =IF(NOT(ISBLANK(A136)),VLOOKUP(A136,'BBT3'!A:F,2,0),"") -> Bond | C136: =IF(NOT(ISBLANK(A136)),VLOOKUP(A136,'BBT3'!A:F,3,0),"") -> US912810FP85 | D136: =IF(NOT(ISBLANK(A136)),VLOOKUP(A136,'BBT3'!A:F,4,1),"") -> 5.375 | E136: =IF(NOT(ISBLANK(A136)),VLOOKUP(A136,'BBT3'!A:F,5,0),"") -> 47894 | F136: =IF(NOT(ISBLANK(A136)),VLOOKUP(A136,'BBT3'!A:F,6,0),"") -> N | G136: =IF(NOT(ISBLANK(A136)),VLOOKUP(A136,QW_Close!A:J,5,0),"") -> 0.041490899 | H136: {=IF(NOT(ISBLANK(A136)),((_xlfn.XLOOKUP(1,(_bbt3[[#All],[ID]]=A136)*(_bbt3[[#All],[METRIC_NAME]]="YLD_YTM_ASK"),_bbt3[[#All],[METRIC_VALUE]])*0.5)+(_xlfn.XLOOKUP(1,(_bbt3[[#All],[ID]]=A136)*(_bbt3[[#All],[METRIC_NAME]]="YLD_YTM_BID"),_bbt3[[#All],[METRIC_VALUE]])*0.5))/100,"")} -> #N/A | I136: =IF(ISNA(VLOOKUP(A136,QW_CloseDL!A:E,5,0)),0,VLOOKUP(A136,QW_CloseDL!A:E,5,0)) -> 0.041490899 | J136: =IF(ISNA(IF(NOT(ISBLANK(A136)),ABS(G136-I136),"")),0,(IF(NOT(ISBLANK(A136)),ABS(G136-I136)*10000,""))) -> 0 | P136: 0 | Q136: =VLOOKUP(P136,A:B,2,0) -> #N/A | R136: =VLOOKUP(P136,A:E,4,0) -> #N/A | S136: =VLOOKUP(P136,A:J,10,0) -> #N/A | T136: =VLOOKUP(P136,A:J,5,0) -> #N/A
A137: 912810FQ6 | B137: =IF(NOT(ISBLANK(A137)),VLOOKUP(A137,'BBT3'!A:F,2,0),"") -> Bond | C137: =IF(NOT(ISBLANK(A137)),VLOOKUP(A137,'BBT3'!A:F,3,0),"") -> US912810FQ68 | D137: =IF(NOT(ISBLANK(A137)),VLOOKUP(A137,'BBT3'!A:F,4,1),"") -> 3.375 | E137: =IF(NOT(ISBLANK(A137)),VLOOKUP(A137,'BBT3'!A:F,5,0),"") -> 48319 | F137: =IF(NOT(ISBLANK(A137)),VLOOKUP(A137,'BBT3'!A:F,6,0),"") -> Y | G137: =IF(NOT(ISBLANK(A137)),VLOOKUP(A137,QW_Close!A:J,5,0),"") -> 0.017400992 | H137: {=IF(NOT(ISBLANK(A137)),((_xlfn.XLOOKUP(1,(_bbt3[[#All],[ID]]=A137)*(_bbt3[[#All],[METRIC_NAME]]="YLD_YTM_ASK"),_bbt3[[#All],[METRIC_VALUE]])*0.5)+(_xlfn.XLOOKUP(1,(_bbt3[[#All],[ID]]=A137)*(_bbt3[[#All],[METRIC_NAME]]="YLD_YTM_BID"),_bbt3[[#All],[METRIC_VALUE]])*0.5))/100,"")} -> #N/A | I137: =IF(ISNA(VLOOKUP(A137,QW_CloseDL!A:E,5,0)),0,VLOOKUP(A137,QW_CloseDL!A:E,5,0)) -> 0.017508208 | J137: =IF(ISNA(IF(NOT(ISBLANK(A137)),ABS(G137-I137),"")),0,(IF(NOT(ISBLANK(A137)),ABS(G137-I137)*10000,""))) -> 1.0721609 | P137: 0 | Q137: =VLOOKUP(P137,A:B,2,0) -> #N/A | R137: =VLOOKUP(P137,A:E,4,0) -> #N/A | S137: =VLOOKUP(P137,A:J,10,0) -> #N/A | T137: =VLOOKUP(P137,A:J,5,0) -> #N/A
A138: 912810FT0 | B138: =IF(NOT(ISBLANK(A138)),VLOOKUP(A138,'BBT3'!A:F,2,0),"") -> Bond | C138: =IF(NOT(ISBLANK(A138)),VLOOKUP(A138,'BBT3'!A:F,3,0),"") -> US912810FT08 | D138: =IF(NOT(ISBLANK(A138)),VLOOKUP(A138,'BBT3'!A:F,4,1),"") -> 4.5 | E138: =IF(NOT(ISBLANK(A138)),VLOOKUP(A138,'BBT3'!A:F,5,0),"") -> 49720 | F138: =IF(NOT(ISBLANK(A138)),VLOOKUP(A138,'BBT3'!A:F,6,0),"") -> N | G138: =IF(NOT(ISBLANK(A138)),VLOOKUP(A138,QW_Close!A:J,5,0),"") -> 0.043765776 | H138: {=IF(NOT(ISBLANK(A138)),((_xlfn.XLOOKUP(1,(_bbt3[[#All],[ID]]=A138)*(_bbt3[[#All],[METRIC_NAME]]="YLD_YTM_ASK"),_bbt3[[#All],[METRIC_VALUE]])*0.5)+(_xlfn.XLOOKUP(1,(_bbt3[[#All],[ID]]=A138)*(_bbt3[[#All],[METRIC_NAME]]="YLD_YTM_BID"),_bbt3[[#All],[METRIC_VALUE]])*0.5))/100,"")} -> #N/A | I138: =IF(ISNA(VLOOKUP(A138,QW_CloseDL!A:E,5,0)),0,VLOOKUP(A138,QW_CloseDL!A:E,5,0)) -> 0.043765776 | J138: =IF(ISNA(IF(NOT(ISBLANK(A138)),ABS(G138-I138),"")),0,(IF(NOT(ISBLANK(A138)),ABS(G138-I138)*10000,""))) -> 0 | P138: 0 | Q138: =VLOOKUP(P138,A:B,2,0) -> #N/A | R138: =VLOOKUP(P138,A:E,4,0) -> #N/A | S138: =VLOOKUP(P138,A:J,10,0) -> #N/A | T138: =VLOOKUP(P138,A:J,5,0) -> #N/A
A139: 912810PS1 | B139: =IF(NOT(ISBLANK(A139)),VLOOKUP(A139,'BBT3'!A:F,2,0),"") -> Bond | C139: =IF(NOT(ISBLANK(A139)),VLOOKUP(A139,'BBT3'!A:F,3,0),"") -> US912810PS15 | D139: =IF(NOT(ISBLANK(A139)),VLOOKUP(A139,'BBT3'!A:F,4,1),"") -> 2.375 | E139: =IF(NOT(ISBLANK(A139)),VLOOKUP(A139,'BBT3'!A:F,5,0),"") -> 46402 | F139: =IF(NOT(ISBLANK(A139)),VLOOKUP(A139,'BBT3'!A:F,6,0),"") -> Y | G139: =IF(NOT(ISBLANK(A139)),VLOOKUP(A139,QW_Close!A:J,5,0),"") -> 0.0082521879 | H139: {=IF(NOT(ISBLANK(A139)),((_xlfn.XLOOKUP(1,(_bbt3[[#All],[ID]]=A139)*(_bbt3[[#All],[METRIC_NAME]]="YLD_YTM_ASK"),_bbt3[[#All],[METRIC_VALUE]])*0.5)+(_xlfn.XLOOKUP(1,(_bbt3[[#All],[ID]]=A139)*(_bbt3[[#All],[METRIC_NAME]]="YLD_YTM_BID"),_bbt3[[#All],[METRIC_VALUE]])*0.5))/100,"")} -> #N/A | I139: =IF(ISNA(VLOOKUP(A139,QW_CloseDL!A:E,5,0)),0,VLOOKUP(A139,QW_CloseDL!A:E,5,0)) -> 0.008252086 | J139: =IF(ISNA(IF(NOT(ISBLANK(A139)),ABS(G139-I139),"")),0,(IF(NOT(ISBLANK(A139)),ABS(G139-I139)*10000,""))) -> 0.0010188631 | P139: 0 | Q139: =VLOOKUP(P139,A:B,2,0) -> #N/A | R139: =VLOOKUP(P139,A:E,4,0) -> #N/A | S139: =VLOOKUP(P139,A:J,10,0) -> #N/A | T139: =VLOOKUP(P139,A:J,5,0) -> #N/A
...

Sheet Sheet2
A1: 7 avril | B1: 912810FD5 | C1: Bond | D1: 3.625 | E1: 5.3113676 | F1: 46858
A2: 7 avril | B2: 912810FH6 | C2: Bond | D2: 3.875 | E2: 4.4163064 | F2: 47223
A3: 7 avril | B3: 912810FQ6 | C3: Bond | D3: 3.375 | E3: 1.8684145 | F3: 48319
A4: 7 avril | B4: 91282CQJ3 | C4: Bond | D4: 3.875 | E4: 2.5884364 | F4: 47223
A5: 8 avril | B5: 912810FD5 | C5: Bond | D5: 3.625 | E5: 8.3604806 | F5: 46858
A6: 8 avril | B6: 912810FH6 | C6: Bond | D6: 3.875 | E6: 4.9256543 | F6: 47223
A7: 9 avril | B7: 912810FD5 | C7: Bond | D7: 3.625 | E7: 2.4752025 | F7: 46858
A8: 9 avril | B8: 912810FH6 | C8: Bond | D8: 3.875 | E8: 2.0235517 | F8: 47223
A9: 9 avril | B9: 912810FQ6 | C9: Bond | D9: 3.375 | E9: 0.70895187 | F9: 48319
A10: 10 avril | B10: 912810FD5 | C10: Bond | D10: 3.625 | E10: 3.2498878 | F10: 46858
A11: 10 avril | B11: 912810FH6 | C11: Bond | D11: 3.875 | E11: 1.0141913 | F11: 47223
A12: 13 avril | B12: 912810FD5 | C12: Bond | D12: 3.625 | E12: 6.6969418 | F12: 46858
... A28: 29 avril | B28: 912810FQ6 | C28: Bond | D28: 3.375 | E28: 5.0500235 | F28: 48319
B29: 912810FD5 | C29: Bond | D29: 3.625 | E29: 2.7452044 | F29: 46858
B30: 912810FQ6 | C30: Bond | D30: 3.375 | E30: 2.654631 | F30: 48319
B31: 912810FD5 | C31: Bond | D31: 3.625 | E31: 2.3576115 | F31: 46858
B32: 912810FH6 | C32: Bond | D32: 3.875 | E32: 3.2204291 | F32: 47223
B33: 912810FQ6 | C33: Bond | D33: 3.375 | E33: 4.0825531 | F33: 48319
B34: 912810FD5 | C34: Bond | D34: 3.625 | E34: 8.692771 | F34: 46858
B35: 912810FH6 | C35: Bond | D35: 3.875 | E35: 5.3088344 | F35: 47223
B36: 912810FD5 | C36: Bond | D36: 3.625 | E36: 5.54865 | F36: 46858
B37: 912810FH6 | C37: Bond | D37: 3.875 | E37: 3.63414 | F37: 47223
B38: 912810FQ6 | C38: Bond | D38: 3.375 | E38: 2.0194064 | F38: 48319
