Workbook
Name TheDate: 'Bond Comparaison'!$R$1

Sheet Batch
A1: CMD | B1: Time | C1: Batch | D1: Runner | E1: Source file | F1: Input-Table | G1: Out-Table | H1: Comment
A2: AMBatch.cmd | B2: 0.22222222 | C2: CurveDefSaver | D2: QW.Security.Batch.Lib.CurveDefRunner.Run | E2: CurveDefRunner.cs | F2: Select CurveName from qwData..QWCurveDefList | G2: Select * from qwData..QWCurveDefs order by MasterDate desc | H2: For each curve from the input tab le, we extract benchmark and store all benchmarks information in QWCurveDefs
A3: AMBatch.cmd | B3: 0.22222222 | C3: BlmChecker | D3: QW.Security.Batch.Lib.BlmChecker.Run | E3: BlmChecker.cs | H3: Check if licence is up
A4: AMBatch.cmd | B4: 0.22222222 | C4: CurrentsRunner | D4: QW.Framework.Translation.Coordinator.Run | E4: CurveRunner.cs | F4: CTJPY2Y,CTJPY5Y,CTJPY10Y,CTJPY20Y,CTJPY30Y,CTJPY40Y,CT2,CT3,CT5,CT7,CT10,CT20,CT30,CTDEM2Y,CTDEM3Y,CTDEM5Y,CTDEM10Y,CTDEM30Y,CTGBP2Y,CTGBP3Y,CTGBP5Y,CTGBP10Y,CTGBP30Y,CTCAD2Y,CTCAD3Y,CTCAD5Y,CTCAD7Y,CTCAD10Y,CTCAD20Y,CTCAD30Y,CTFRF2Y,CTFRF3Y,CTFRF5Y,CTFRF10Y,CTFRF30Y,CTITL2Y,CTITL3Y,CTITL5Y,CTITL10Y,CTITL30Y,CTESP2Y,CTESP3Y,CTESP5Y,CTESP10Y,CTESP30Y,CTBEF2Y,CTBEF3Y,CTBEF5Y,CTBEF10Y,CTBEF30Y | G4: select * from qw..Currents where MasterDate = '2026-07-27' | H4: Determine the on-the-run bonds for the following static list: CTJPY2Y,CTJPY5Y,CTJPY10Y,CTJPY20Y,CTJPY30Y,CTJPY40Y,CT2,CT3,CT5,CT7,CT10,CT20,CT30,CTDEM2Y,CTDEM3Y,CTDEM5Y,CTDEM10Y,CTDEM30Y,CTGBP2Y,CTGBP3Y,CTGBP5Y,CTGBP10Y,CTGBP30Y,CTCAD2Y,CTCAD3Y,CTCAD5Y,CTCAD7Y,CTCAD10Y,CTCAD20Y,CTCAD30Y,CTFRF2Y,CTFRF3Y,CTFRF5Y,CTFRF10Y,CTFRF30Y,CTITL2Y,CTITL3Y,CTITL5Y,CTITL10Y,CTITL30Y,CTESP2Y,CTESP3Y,CTESP5Y,CTESP10Y,CTESP30Y,CTBEF2Y,CTBEF3Y,CTBEF5Y,CTBEF10Y,CTBEF30Y
A5: EODBatch.cmd | B5: 0.77083333 | C5: BlmChecker
A6: EODBatch.cmd | B6: 0.77083333 | C6: PositionRoller
A7: EODBatch.cmd | B7: 0.77083333 | C7: PriceSaverBBT3 | D7: QW.Security.Batch.Lib.YieldFromPriceSaverDL.Run | E7: YieldFromPriceSaverDL.cs | F7: select bd.ID, bd.ISIN, bbt3.* from qw..Bond bd, qwdata..REFERENCE_BLOOMBERG_WSDL_PRINT_SB_US_GOV_BBT3 bbt3 where bbt3.Date='06/08/2026' and bd.ISIN = bbt3.MASTER_FIXED_INCOME_INSTRUMENT_ID union select bl.ID, bl.ISIN, bbt3.* from qw..Bill bl, qwdata..REFERENCE_BLOOMBERG_WSDL_PRINT_SB_US_GOV_BBT3 bbt3 where bbt3.Date='06/08/2026' and bl.ISIN = bbt3.MASTER_FIXED_INCOME_INSTRUMENT_ID | G7: qwData..ClosesDL | H7: The table REFERENCE_BLOOMBERG_WSDL_PRINT_SB_US_GOV_BBT3 is refreshed around 6PMFor each USTreasuries in REFERENCE_BLOOMBERG_WSDL_PRINT_SB_US_GOV_BBT3 for the Today Date (le run se lance a 18h30, apres le rollhour qui est de 16h, donc dans DateListAware, on prend la Today Date) , we compute the yield from prices from REFERENCE_BLOOMBERG_WSDL_PRINT_SB_US_GOV_BBT3 and store it in ClosesDL
A8: EODBatch.cmd | B8: 0.77083333 | C8: PriceSaverSFBar | D8: QW.Security.Batch.Lib.YieldFromPriceSaverDL.Run | E8: YieldFromPriceSaverDL.cs | F8: select ISIN AS ID, 'PX_BID' as METRIC_NAME, BID as METRIC_VALUE, * from dev.mart.canvas_sb_foreign_gov_bid_ask WHERE PRICE_DATE = '06/08/2026' and not BID is NULL union select ISIN AS ID, 'PX_ASK' as METRIC_NAME, ASK as METRIC_VALUE, * from dev.mart.canvas_sb_foreign_gov_bid_ask WHERE PRICE_DATE = '06/08/2026' and not ASK is NULL | G8: qwData..ClosesDL | H8: For each foreign bond in dev.mart.canvas_sb_foreign_gov_bid_ask for the current Date, we compute the yield from prices from dev.mart.canvas_sb_foreign_gov_bid_ask and store it in ClosesDL
A9: EODBatch.cmd | B9: 0.77083333 | C9: PriceSaverDLIndexes | D9: QW.Security.Batch.Lib.PriceSaverSnowflake.Run | E9: PriceSaverSnowflake.cs | F9: SELECT cfm.* FROM DEV.MART.CANVAS_SB_OVERNIGHT_INDEX AS cfm WHERE DATE >= DATEADD(day, -7, '06/08/2026'::DATE) AND NOT PX_LAST IS NULL | G9: qwData..ClosesDL | H9: For each indexe in DEV.MART.CANVAS_SB_OVERNIGHT_INDEX, we compute quote from the previous 7 business day and store it in CloseDL
A10: EODBatch.cmd | B10: 0.77083333 | C10: PriceSaverDLFutures | D10: QW.Security.Batch.Lib.PriceSaverSnowflake.Run | E10: PriceSaverSnowflake.cs | F10: SELECT cfm.* FROM DEV.MART.CANVAS_FUTURES_MASTER AS cfm WHERE DATE = '06/08/2026' AND NOT px_settle IS NULL | G10: qwData..ClosesDL | H10: For each ST/LT Future in DEV.MART.CANVAS_FUTURES_MASTER for the current date, we extract from CANVAS_FUTURES_MASTER the price and other static data and populate ClosesDL
A11: EODBatch.cmd | B11: 0.77083333 | C11: BlmChecker | D11: QW.Security.Batch.Lib.BlmChecker | E11: BlmChecker.cs | H11: Check if licence is up
A12: EODBatch.cmd | B12: 0.77083333 | C12: PriceSaver | D12: QW.Security.Batch.Lib.PriceSaver.Run | E12: PriceSaver.cs | F12: select ID from qw..Bond where Maturity>'2026-06-09' and FirstCall is null and ISNULL(IsDuplicate,0)=0 and ID not like '.%' and ID not like 'AU%DLV' and ID not in (select ID from qwData..Closes where Date='2026-06-09' and Src='QW') | G12: qwData..Closes | H12: For each USTreasuries from qw..Bond for the current date, we extract the price from DABPI and qw..Bond and compute the yield and populate Closes
A13: EODBatch.cmd | B13: 0.77083333 | C13: PriceSaverB | D13: QW.Security.Batch.Lib.PriceSaver.Run | E13: PriceSaver.cs | F13: GC.USD.1,SOFR,SFR3M,EuriborFut,CORFUT | G13: qwData..Closes | H13: For each bondFuture from this query: select ID from qw..BondFuture where LastDelivery>'${TradeDate-ToString('yyyyMMdd')}, we get the price from DAPI and compute the yield and populates Closes
A14: EODBatch.cmd | B14: 0.77083333 | C14: PriceSaverC | D14: QW.Security.Batch.Lib.PriceSaver.Run | E14: PriceSaver.cs | F14: FEDL01,SOFRRATE,MUTKCALM | G14: qwData..Closes | H14: For each indexes, we extract the closing of the current day and populate Closes
A15: EODBatch.cmd | B15: 0.77083333 | C15: PriceSaverOPT | D15: QW.Security.Batch.Lib.PriceSaver.Run | E15: PriceSaver.cs | F15: select ID from qw..[Option] where Expiration>'2026-06-09' and ID in (select distinct SecID from qwTrading..Positions where SODDate = '2026-06-09' and abs(quantity) > 0 UNION select distinct SecID from qwTrading..Trades where TradeDate = '2026-06-09') | G15: qwData..Closes | H15: Does not seem to do anything
A16: EODBatch.cmd | B16: 0.77083333 | C16: ParRates | D16: QW.Security.Batch.Lib.CurveRunnerParRates.doRun | E16: CurveRunnerParRates.cs | F16: EuriborSwap,OISSwap,OISCADSwap | G16: qwData..Curves | H16: For each swaps in these curves, we compute the swap rate and populate Curves

Sheet BBT3
A1: ID | B1: Column1 | C1: ISIN | D1: Coupon | E1: Maturity | F1: InflationLinked | G1: MASTER_FIXED_INCOME_INSTRUMENT_ID | H1: MASTER_FIXED_INCOME_ID_TYPE | I1: DATE | J1: METRIC_NAME | K1: METRIC_VALUE | L1: CR_TIME | M1: REPLICA_TIME
A2: 912797RG4 | B2: Bill | C2: US912797RG48 | D2: 0 | E2: 46240 | F2: N | G2: US912797RG48 | H2: ISIN | I2: 46224 | J2: PX_BID | K2: 3.6162000000 | L2: 46224.918 | M2: 46224.92
A3: 912797RG4 | B3: Bill | C3: US912797RG48 | D3: 0 | E3: 46240 | F3: N | G3: US912797RG48 | H3: ISIN | I3: 46224 | J3: PX_ASK | K3: 3.5956000000 | L3: 46224.918 | M3: 46224.92
A4: 912797RS8 | B4: Bill | C4: US912797RS85 | D4: 0 | E4: 46268 | F4: N | G4: US912797RS85 | H4: ISIN | I4: 46224 | J4: YLD_CNV_BID | K4: 3.717 | L4: 46224.918 | M4: 46224.92
A5: 912797RS8 | B5: Bill | C5: US912797RS85 | D5: 0 | E5: 46268 | F5: N | G5: US912797RS85 | H5: ISIN | I5: 46224 | J5: PX_BID | K5: 3.6501000000 | L5: 46224.918 | M5: 46224.92
A6: 912797RS8 | B6: Bill | C6: US912797RS85 | D6: 0 | E6: 46268 | F6: N | G6: US912797RS85 | H6: ISIN | I6: 46224 | J6: YLD_CNV_ASK | K6: 3.705 | L6: 46224.918 | M6: 46224.92
A7: 912797RS8 | B7: Bill | C7: US912797RS85 | D7: 0 | E7: 46268 | F7: N | G7: US912797RS85 | H7: ISIN | I7: 46224 | J7: PX_ASK | K7: 3.6381000000 | L7: 46224.918 | M7: 46224.92
A8: 912797RS8 | B8: Bill | C8: US912797RS85 | D8: 0 | E8: 46268 | F8: N | G8: US912797RS85 | H8: ISIN | I8: 46224 | J8: YLD_YTM_BID | K8: 3.717 | L8: 46224.918 | M8: 46224.92
A9: 912797RS8 | B9: Bill | C9: US912797RS85 | D9: 0 | E9: 46268 | F9: N | G9: US912797RS85 | H9: ISIN | I9: 46224 | J9: YLD_YTM_ASK | K9: 3.705 | L9: 46224.918 | M9: 46224.92
A10: 912797SA6 | B10: Bill | C10: US912797SA68 | D10: 0 | E10: 46296 | F10: N | G10: US912797SA68 | H10: ISIN | I10: 46224 | J10: YLD_YTM_ASK | K10: 3.755 | L10: 46224.918 | M10: 46224.92
A11: 912797SA6 | B11: Bill | C11: US912797SA68 | D11: 0 | E11: 46296 | F11: N | G11: US912797SA68 | H11: ISIN | I11: 46224 | J11: YLD_CNV_BID | K11: 3.765 | L11: 46224.918 | M11: 46224.92
A12: 912797SA6 | B12: Bill | C12: US912797SA68 | D12: 0 | E12: 46296 | F12: N | G12: US912797SA68 | H12: ISIN | I12: 46224 | J12: PX_BID | K12: 3.6867000000 | L12: 46224.918 | M12: 46224.92
A13: 912797SA6 | B13: Bill | C13: US912797SA68 | D13: 0 | E13: 46296 | F13: N | G13: US912797SA68 | H13: ISIN | I13: 46224 | J13: YLD_YTM_BID | K13: 3.765 | L13: 46224.918 | M13: 46224.92
... A2545: 912834QV3 | B2545: Bond | C2545: US912834QV37 | D2545: 0 | E2545: 53646 | F2545: N | G2545: US912834QV37 | H2545: ISIN | I2545: 46224 | J2545: PX_BID | K2545: 33.6685868400 | L2545: 46224.918 | M2545: 46224.92

Sheet CloseDL - PriceSaverBBT3
A1: ID | B1: Att | C1: Src | D1: Date | E1: Value | F1: CreatedDate | G1: CreatedBy | H1: ModifiedTime | I1: ModifiedBy | J1: Notes
A2: 3YH7 | B2: Price | C2: QW | D2: 46224 | E2: 104.23828 | F2: 46224.772 | G2: MARINER\SilverAdm | H2: 46224.772 | I2: MARINER\SilverAdm | J2: DL CANVAS_FUTURES_MASTER Date=7/21/2026 PX_SETTLE = no sttl dt
A3: 3YU6 | B3: Price | C3: QW | D3: 46224 | E3: 104.33203 | F3: 46224.772 | G3: MARINER\SilverAdm | H3: 46224.772 | I3: MARINER\SilverAdm | J3: DL CANVAS_FUTURES_MASTER Date=7/21/2026 PX_SETTLE = no sttl dt
A4: 3YZ6 | B4: Price | C4: QW | D4: 46224 | E4: 104.28516 | F4: 46224.772 | G4: MARINER\SilverAdm | H4: 46224.772 | I4: MARINER\SilverAdm | J4: DL CANVAS_FUTURES_MASTER Date=7/21/2026 PX_SETTLE = no sttl dt
A5: 912797RG4 | B5: Yield | C5: QW | D5: 46224 | E5: 0.03692402 | F5: 46224.772 | G5: MARINER\SilverAdm | H5: 46224.772 | I5: MARINER\SilverAdm | J5: DL Bill input Discount = 3.60590000 PX_ASK = 3.59560000 PX_BID = 3.61620000
A6: 912797RS8 | B6: Yield | C6: QW | D6: 46224 | E6: 0.037372658 | F6: 46224.772 | G6: MARINER\SilverAdm | H6: 46224.772 | I6: MARINER\SilverAdm | J6: DL Bill input Discount = 3.64410000 PX_ASK = 3.63810000 PX_BID = 3.65010000
A7: 912797SA6 | B7: Yield | C7: QW | D7: 46224 | E7: 0.037815548 | F7: 46224.772 | G7: MARINER\SilverAdm | H7: 46224.772 | I7: MARINER\SilverAdm | J7: DL Bill input Discount = 3.68150000 PX_ASK = 3.67630000 PX_BID = 3.68670000
A8: 912797SK4 | B8: Yield | C8: QW | D8: 46224 | E8: 0.038428587 | F8: 46224.772 | G8: MARINER\SilverAdm | H8: 46224.772 | I8: MARINER\SilverAdm | J8: DL Bill input Discount = 3.73495000 PX_ASK = 3.72960000 PX_BID = 3.74030000
A9: 912797SU2 | B9: Yield | C9: QW | D9: 46224 | E9: 0.038862044 | F9: 46224.772 | G9: MARINER\SilverAdm | H9: 46224.772 | I9: MARINER\SilverAdm | J9: DL Bill input Discount = 3.77070000 PX_ASK = 3.76210000 PX_BID = 3.77930000
A10: 912797TC1 | B10: Yield | C10: QW | D10: 46224 | E10: 0.039483145 | F10: 46224.772 | G10: MARINER\SilverAdm | H10: 46224.772 | I10: MARINER\SilverAdm | J10: DL Bill input Discount = 3.82445000 PX_ASK = 3.81830000 PX_BID = 3.83060000
A11: 912797TM9 | B11: Yield | C11: QW | D11: 46224 | E11: 0.039567644 | F11: 46224.772 | G11: MARINER\SilverAdm | H11: 46224.772 | I11: MARINER\SilverAdm | J11: DL Bill input Discount = 3.82675000 PX_ASK = 3.81470000 PX_BID = 3.83880000
A12: 912797TP2 | B12: Yield | C12: QW | D12: 46224 | E12: 0.036216935 | F12: 46224.772 | G12: MARINER\SilverAdm | H12: 46224.772 | I12: MARINER\SilverAdm | J12: DL Bill input Discount = 3.53995000 PX_ASK = 3.52780000 PX_BID = 3.55210000
A13: 912797TQ0 | B13: Yield | C13: QW | D13: 46224 | E13: 0.036351425 | F13: 46224.772 | G13: MARINER\SilverAdm | H13: 46224.772 | I13: MARINER\SilverAdm | J13: DL Bill input Discount = 3.55175000 PX_ASK = 3.54230000 PX_BID = 3.56120000
... A1389: XQU6 | B1389: Price | C1389: QW | D1389: 46224 | E1389: 112.41 | F1389: 46224.772 | G1389: MARINER\SilverAdm | H1389: 46224.772 | I1389: MARINER\SilverAdm | J1389: DL CANVAS_FUTURES_MASTER Date=7/21/2026 PX_SETTLE = no sttl dt

Sheet Close - PriceSaver
A1: ID | B1: Att | C1: Src | D1: Date | E1: Value | F1: Notes | G1: CreatedDate | H1: CreatedBy | I1: ModifiedTime | J1: ModifiedBy
A2: .TWI10 8/36 | B2: Yield | C2: QW | D2: 46224 | E2: 0.046489069 | G2: 46224.77 | H2: MARINERCAPITAL\jmannion | I2: 46224.77 | J2: MARINERCAPITAL\jmannion
A3: .TWI2 7/28 | B3: Yield | C3: QW | D3: 46224 | E3: 0.042577727 | G3: 46224.77 | H3: MARINERCAPITAL\jmannion | I3: 46224.77 | J3: MARINERCAPITAL\jmannion
A4: .TWI2 8/28 | B4: Yield | C4: QW | D4: 46224 | E4: 0.042613754 | G4: 46224.77 | H4: MARINERCAPITAL\jmannion | I4: 46224.77 | J4: MARINERCAPITAL\jmannion
A5: .TWI2 9/28 | B5: Yield | C5: QW | D5: 46224 | E5: 0.042740433 | G5: 46224.77 | H5: MARINERCAPITAL\jmannion | I5: 46224.77 | J5: MARINERCAPITAL\jmannion
A6: .TWI30 8/56 | B6: Yield | C6: QW | D6: 46224 | E6: 0.05135813 | G6: 46224.77 | H6: MARINERCAPITAL\jmannion | I6: 46224.77 | J6: MARINERCAPITAL\jmannion
A7: .TWI7 7/33 | B7: Yield | C7: QW | D7: 46224 | E7: 0.044992273 | G7: 46224.77 | H7: MARINERCAPITAL\jmannion | I7: 46224.77 | J7: MARINERCAPITAL\jmannion
A8: .TWI7 8/33 | B8: Yield | C8: QW | D8: 46224 | E8: 0.04509461 | G8: 46224.77 | H8: MARINERCAPITAL\jmannion | I8: 46224.77 | J8: MARINERCAPITAL\jmannion
A9: 3YH7 | B9: Price | C9: QW | D9: 46224 | E9: 104.23828 | F9: DL CANVAS_FUTURES_MASTER Date=7/21/2026 PX_SETTLE = no sttl dt | G9: 46224.772 | H9: MARINER\SilverAdm | I9: 46224.772 | J9: MARINER\SilverAdm
A10: 3YU6 | B10: Price | C10: QW | D10: 46224 | E10: 104.33203 | F10: DL CANVAS_FUTURES_MASTER Date=7/21/2026 PX_SETTLE = no sttl dt | G10: 46224.772 | H10: MARINER\SilverAdm | I10: 46224.772 | J10: MARINER\SilverAdm
A11: 3YZ6 | B11: Price | C11: QW | D11: 46224 | E11: 104.28516 | F11: DL CANVAS_FUTURES_MASTER Date=7/21/2026 PX_SETTLE = no sttl dt | G11: 46224.772 | H11: MARINER\SilverAdm | I11: 46224.772 | J11: MARINER\SilverAdm
A12: 912797RG4 | B12: Yield | C12: QW | D12: 46224 | E12: 0.03692402 | F12: DL Bill input Discount = 3.60590000 PX_ASK = 3.59560000 PX_BID = 3.61620000 | G12: 46224.772 | H12: MARINER\SilverAdm | I12: 46224.772 | J12: MARINER\SilverAdm
A13: 912797RS8 | B13: Yield | C13: QW | D13: 46224 | E13: 0.037372658 | F13: DL Bill input Discount = 3.64410000 PX_ASK = 3.63810000 PX_BID = 3.65010000 | G13: 46224.772 | H13: MARINER\SilverAdm | I13: 46224.772 | J13: MARINER\SilverAdm
A14: 912797SA6 | B14: Yield | C14: QW | D14: 46224 | E14: 0.037815548 | F14: DL Bill input Discount = 3.68150000 PX_ASK = 3.67630000 PX_BID = 3.68670000 | G14: 46224.772 | H14: MARINER\SilverAdm | I14: 46224.772 | J14: MARINER\SilverAdm
A15: 912797SK4 | B15: Yield | C15: QW | D15: 46224 | E15: 0.038428587 | F15: DL Bill input Discount = 3.73495000 PX_ASK = 3.72960000 PX_BID = 3.74030000 | G15: 46224.772 | H15: MARINER\SilverAdm | I15: 46224.772 | J15: MARINER\SilverAdm
A16: 912797SU2 | B16: Yield | C16: QW | D16: 46224 | E16: 0.038862044 | F16: DL Bill input Discount = 3.77070000 PX_ASK = 3.76210000 PX_BID = 3.77930000 | G16: 46224.772 | H16: MARINER\SilverAdm | I16: 46224.772 | J16: MARINER\SilverAdm
A17: 912797TC1 | B17: Yield | C17: QW | D17: 46224 | E17: 0.039483145 | F17: DL Bill input Discount = 3.82445000 PX_ASK = 3.81830000 PX_BID = 3.83060000 | G17: 46224.772 | H17: MARINER\SilverAdm | I17: 46224.772 | J17: MARINER\SilverAdm
A18: 912797TM9 | B18: Yield | C18: QW | D18: 46224 | E18: 0.039567644 | F18: DL Bill input Discount = 3.82675000 PX_ASK = 3.81470000 PX_BID = 3.83880000 | G18: 46224.772 | H18: MARINER\SilverAdm | I18: 46224.772 | J18: MARINER\SilverAdm
A19: 912797TP2 | B19: Yield | C19: QW | D19: 46224 | E19: 0.036216935 | F19: DL Bill input Discount = 3.53995000 PX_ASK = 3.52780000 PX_BID = 3.55210000 | G19: 46224.772 | H19: MARINER\SilverAdm | I19: 46224.772 | J19: MARINER\SilverAdm
A20: 912797TQ0 | B20: Yield | C20: QW | D20: 46224 | E20: 0.036351425 | F20: DL Bill input Discount = 3.55175000 PX_ASK = 3.54230000 PX_BID = 3.56120000 | G20: 46224.772 | H20: MARINER\SilverAdm | I20: 46224.772 | J20: MARINER\SilverAdm
... A769: CA013051ED53 | B769: Yield | C769: QW | D769: 46224 | E769: 0.047309139 | F769: DL input prc = 76.81950000 PX_ASK = 76.89300000 PX_BID = 76.74600000 | G769: 46224.772 | H769: MARINER\SilverAdm | I769: 46224.772 | J769: MARINER\SilverAdm
A770: CA135087B949 | B770: Price | C770: QW | D770: 46224 | E770: 106.55 | G770: 46224.77 | H770: MARINERCAPITAL\jmannion | I770: 46224.77 | J770: MARINERCAPITAL\jmannion
A771: CA135087B949 | B771: Yield | C771: QW | D771: 46224 | E771: 0.018811741 | F771: DL input prc = 88.93900000 PX_ASK = 89.14300000 PX_BID = 88.73500000 | G771: 46224.772 | H771: MARINER\SilverAdm | I771: 46224.772 | J771: MARINER\SilverAdm
A772: CA135087C939 | B772: Yield | C772: QW | D772: 46224 | E772: 0.039757384 | F772: DL input prc = 75.97650000 PX_ASK = 76.02000000 PX_BID = 75.93300000 | G772: 46224.772 | H772: MARINER\SilverAdm | I772: 46224.772 | J772: MARINER\SilverAdm
A773: CA135087D358 | B773: Yield | C773: QW | D773: 46224 | E773: 0.03906662 | F773: DL input prc = 82.85450000 PX_ASK = 82.88400000 PX_BID = 82.82500000 | G773: 46224.772 | H773: MARINER\SilverAdm | I773: 46224.772 | J773: MARINER\SilverAdm
A774: CA135087F825 | B774: Yield | C774: QW | D774: 46224 | E774: 0.025406025 | F774: DL input prc = 98.69600000 PX_ASK = 98.70300000 PX_BID = 98.68900000 | G774: 46224.772 | H774: MARINER\SilverAdm | I774: 46224.772 | J774: MARINER\SilverAdm
A775: CA135087G997 | B775: Price | C775: QW | D775: 46224 | E775: 0 | G775: 46224.77 | H775: MARINERCAPITAL\jmannion | I775: 46224.77 | J775: MARINERCAPITAL\jmannion
A776: CA135087G997 | B776: Yield | C776: QW | D776: 46224 | E776: 0.018859175 | F776: DL input prc = 73.03050000 PX_ASK = 73.24300000 PX_BID = 72.81800000 | G776: 46224.772 | H776: MARINER\SilverAdm | I776: 46224.772 | J776: MARINER\SilverAdm
A777: CA135087H235 | B777: Yield | C777: QW | D777: 46224 | E777: 0.028084009 | F777: DL input prc = 98.54300000 PX_ASK = 98.54800000 PX_BID = 98.53800000 | G777: 46224.772 | H777: MARINER\SilverAdm | I777: 46224.772 | J777: MARINER\SilverAdm
A778: CA135087H722 | B778: Yield | C778: QW | D778: 46224 | E778: 0.039686066 | F778: DL input prc = 68.70400000 PX_ASK = 68.73500000 PX_BID = 68.67300000 | G778: 46224.772 | H778: MARINER\SilverAdm | I778: 46224.772 | J778: MARINER\SilverAdm
A779: CA135087J397 | B779: Yield | C779: QW | D779: 46224 | E779: 0.029167881 | F779: DL input prc = 98.18100000 PX_ASK = 98.18800000 PX_BID = 98.17400000 | G779: 46224.772 | H779: MARINER\SilverAdm | I779: 46224.772 | J779: MARINER\SilverAdm
A780: CA135087K379 | B780: Yield | C780: QW | D780: 46224 | E780: 0.030871248 | F780: DL input prc = 93.36100000 PX_ASK = 93.36800000 PX_BID = 93.35400000 | G780: 46224.772 | H780: MARINER\SilverAdm | I780: 46224.772 | J780: MARINER\SilverAdm
A781: CA135087L443 | B781: Yield | C781: QW | D781: 46224 | E781: 0.031111385 | F781: DL input prc = 89.42850000 PX_ASK = 89.43700000 PX_BID = 89.42000000 | G781: 46224.772 | H781: MARINER\SilverAdm | I781: 46224.772 | J781: MARINER\SilverAdm
A782: CA135087L930 | B782: Yield | C782: QW | D782: 46224 | E782: 0.02295871 | F782: DL input prc = 99.85500000 PX_ASK = 99.86000000 PX_BID = 99.85000000 | G782: 46224.772 | H782: MARINER\SilverAdm | I782: 46224.772 | J782: MARINER\SilverAdm
A783: CA135087M276 | B783: Yield | C783: QW | D783: 46224 | E783: 0.031735214 | F783: DL input prc = 92.51550000 PX_ASK = 92.52400000 PX_BID = 92.50700000 | G783: 46224.772 | H783: MARINER\SilverAdm | I783: 46224.772 | J783: MARINER\SilverAdm
A784: CA135087M433 | B784: Price | C784: QW | D784: 46224 | E784: 0 | G784: 46224.77 | H784: MARINERCAPITAL\jmannion | I784: 46224.77 | J784: MARINERCAPITAL\jmannion
A785: CA135087M433 | B785: Yield | C785: QW | D785: 46224 | E785: 0.018496433 | F785: DL input prc = 64.82150000 PX_ASK = 65.06800000 PX_BID = 64.57500000 | G785: 46224.772 | H785: MARINER\SilverAdm | I785: 46224.772 | J785: MARINER\SilverAdm
A786: CA135087M680 | B786: Yield | C786: QW | D786: 46224 | E786: 0.039786161 | F786: DL input prc = 63.04600000 PX_ASK = 63.07700000 PX_BID = 63.01500000 | G786: 46224.772 | H786: MARINER\SilverAdm | I786: 46224.772 | J786: MARINER\SilverAdm
A787: CA135087M847 | B787: Yield | C787: QW | D787: 46224 | E787: 0.024516748 | F787: DL input prc = 99.27450000 PX_ASK = 99.27800000 PX_BID = 99.27100000 | G787: 46224.772 | H787: MARINER\SilverAdm | I787: 46224.772 | J787: MARINER\SilverAdm
A788: CA135087N266 | B788: Yield | C788: QW | D788: 46224 | E788: 0.032155299 | F788: DL input prc = 91.61300000 PX_ASK = 91.62300000 PX_BID = 91.60300000 | G788: 46224.772 | H788: MARINER\SilverAdm | I788: 46224.772 | J788: MARINER\SilverAdm
...

Sheet Bond Comparaison
A1: {=_xlfn._xlws.FILTER(_xlfn.UNIQUE('BBT3'!A:A),_xlfn.UNIQUE('BBT3'!A:A)<>0)} -> ID | B1: Type | C1: ISIN | D1: Coupon | E1: Maturity | F1: InflationLinked | G1: IsZero | H1: Clode Yield | I1: BBT3 Yield | J1: Close DL Yield | K1: Diff absolue | L1: Computedby SilverAdmin | M1: Notes | Q1: {=_xll.qwCtxTrade()} -> ctx.46239.Live | R1: {=_xll.qwCalAddBusDays("US",TODAY(),O3)} -> 46238
A2: 912797RG4 | B2: =IF(NOT(ISBLANK(A2)),VLOOKUP(A2,'BBT3'!A:F,2,0),"") -> Bill | C2: =IF(NOT(ISBLANK(A2)),VLOOKUP(A2,'BBT3'!A:F,3,0),"") -> US912797RG48 | D2: =IF(NOT(ISBLANK(A2)),VLOOKUP(A2,'BBT3'!A:F,4,1),"") -> 0 | E2: =IF(NOT(ISBLANK(A2)),VLOOKUP(A2,'BBT3'!A:F,5,0),"") -> 46240 | F2: =IF(NOT(ISBLANK(A2)),VLOOKUP(A2,'BBT3'!A:F,6,0),"") -> N | G2: =IF(NOT(ISBLANK(A2)),IF(D2=0,"Y","N"),"") -> Y | H2: =IF(NOT(ISBLANK(A2)),VLOOKUP(A2,'Close - PriceSaver'!A:J,5,0),"") -> 0.03692402 | I2: {=IF(NOT(ISBLANK(A2)),((_xlfn.XLOOKUP(1,(_bbt3[[#All],[ID]]=A2)*(_bbt3[[#All],[METRIC_NAME]]="YLD_YTM_ASK"),_bbt3[[#All],[METRIC_VALUE]])*0.5)+(_xlfn.XLOOKUP(1,(_bbt3[[#All],[ID]]=A2)*(_bbt3[[#All],[METRIC_NAME]]="YLD_YTM_BID"),_bbt3[[#All],[METRIC_VALUE]])*0.5))/100,"")} -> #N/A | J2: =IF(ISNA(VLOOKUP(A2,'CloseDL - PriceSaverBBT3'!A:E,5,0)),0,VLOOKUP(A2,'CloseDL - PriceSaverBBT3'!A:E,5,0)) -> 0.03692402 | K2: =IF(ISNA(IF(NOT(ISBLANK(A2)),ABS(H2-J2),"")),0,(IF(NOT(ISBLANK(A2)),ABS(H2-J2)*10000,""))) -> 0 | L2: =IF(Close[[#This Row],[CreatedBy]]="MARINER\SilverAdm",1,0) -> 0 | M2: =IF(NOT(ISBLANK(A2)),VLOOKUP(A2,'Close - PriceSaver'!A:J,6,0),"") -> DL Bill input Discount = 3.60590000 PX_ASK = 3.59560000 PX_BID = 3.61620000 | R2: Total | S2: =COUNTA(A:A) -> 653
A3: 912797RS8 | B3: =IF(NOT(ISBLANK(A3)),VLOOKUP(A3,'BBT3'!A:F,2,0),"") -> Bill | C3: =IF(NOT(ISBLANK(A3)),VLOOKUP(A3,'BBT3'!A:F,3,0),"") -> US912797RS85 | D3: =IF(NOT(ISBLANK(A3)),VLOOKUP(A3,'BBT3'!A:F,4,1),"") -> 0 | E3: =IF(NOT(ISBLANK(A3)),VLOOKUP(A3,'BBT3'!A:F,5,0),"") -> 46268 | F3: =IF(NOT(ISBLANK(A3)),VLOOKUP(A3,'BBT3'!A:F,6,0),"") -> N | G3: =IF(NOT(ISBLANK(A3)),IF(D3=0,"Y","N"),"") -> Y | H3: =IF(NOT(ISBLANK(A3)),VLOOKUP(A3,'Close - PriceSaver'!A:J,5,0),"") -> 0.037372658 | I3: {=IF(NOT(ISBLANK(A3)),((_xlfn.XLOOKUP(1,(_bbt3[[#All],[ID]]=A3)*(_bbt3[[#All],[METRIC_NAME]]="YLD_YTM_ASK"),_bbt3[[#All],[METRIC_VALUE]])*0.5)+(_xlfn.XLOOKUP(1,(_bbt3[[#All],[ID]]=A3)*(_bbt3[[#All],[METRIC_NAME]]="YLD_YTM_BID"),_bbt3[[#All],[METRIC_VALUE]])*0.5))/100,"")} -> 0.03711 | J3: =IF(ISNA(VLOOKUP(A3,'CloseDL - PriceSaverBBT3'!A:E,5,0)),0,VLOOKUP(A3,'CloseDL - PriceSaverBBT3'!A:E,5,0)) -> 0.037372658 | K3: =IF(ISNA(IF(NOT(ISBLANK(A3)),ABS(H3-J3),"")),0,(IF(NOT(ISBLANK(A3)),ABS(H3-J3)*10000,""))) -> 0 | L3: =IF(Close[[#This Row],[CreatedBy]]="MARINER\SilverAdm",1,0) -> 0 | M3: =IF(NOT(ISBLANK(A3)),VLOOKUP(A3,'Close - PriceSaver'!A:J,6,0),"") -> DL Bill input Discount = 3.64410000 PX_ASK = 3.63810000 PX_BID = 3.65010000 | O3: -1 | R3: Nb of bonds to compare (Non-infla, non-bill, non-zc) | S3: {=COUNT(_xlfn._xlws.FILTER(K2:K3500,ISNUMBER(K2:K3500)*(F2:F3500="N")*(B2:B3500="Bond")*(G2:G3500="N")))} -> 352
A4: 912797SA6 | B4: =IF(NOT(ISBLANK(A4)),VLOOKUP(A4,'BBT3'!A:F,2,0),"") -> Bill | C4: =IF(NOT(ISBLANK(A4)),VLOOKUP(A4,'BBT3'!A:F,3,0),"") -> US912797SA68 | D4: =IF(NOT(ISBLANK(A4)),VLOOKUP(A4,'BBT3'!A:F,4,1),"") -> 0 | E4: =IF(NOT(ISBLANK(A4)),VLOOKUP(A4,'BBT3'!A:F,5,0),"") -> 46296 | F4: =IF(NOT(ISBLANK(A4)),VLOOKUP(A4,'BBT3'!A:F,6,0),"") -> N | G4: =IF(NOT(ISBLANK(A4)),IF(D4=0,"Y","N"),"") -> Y | H4: =IF(NOT(ISBLANK(A4)),VLOOKUP(A4,'Close - PriceSaver'!A:J,5,0),"") -> 0.037815548 | I4: {=IF(NOT(ISBLANK(A4)),((_xlfn.XLOOKUP(1,(_bbt3[[#All],[ID]]=A4)*(_bbt3[[#All],[METRIC_NAME]]="YLD_YTM_ASK"),_bbt3[[#All],[METRIC_VALUE]])*0.5)+(_xlfn.XLOOKUP(1,(_bbt3[[#All],[ID]]=A4)*(_bbt3[[#All],[METRIC_NAME]]="YLD_YTM_BID"),_bbt3[[#All],[METRIC_VALUE]])*0.5))/100,"")} -> 0.0376 | J4: =IF(ISNA(VLOOKUP(A4,'CloseDL - PriceSaverBBT3'!A:E,5,0)),0,VLOOKUP(A4,'CloseDL - PriceSaverBBT3'!A:E,5,0)) -> 0.037815548 | K4: =IF(ISNA(IF(NOT(ISBLANK(A4)),ABS(H4-J4),"")),0,(IF(NOT(ISBLANK(A4)),ABS(H4-J4)*10000,""))) -> 0 | L4: =IF(Close[[#This Row],[CreatedBy]]="MARINER\SilverAdm",1,0) -> 0 | M4: =IF(NOT(ISBLANK(A4)),VLOOKUP(A4,'Close - PriceSaver'!A:J,6,0),"") -> DL Bill input Discount = 3.68150000 PX_ASK = 3.67630000 PX_BID = 3.68670000 | S4: {=MAX(_xlfn._xlws.FILTER(K2:K3500,ISNUMBER(K2:K3500)*(F2:F3500="N")*(B2:B3500="Bond")*(G2:G3500="N")))} -> 0
A5: 912797SK4 | B5: =IF(NOT(ISBLANK(A5)),VLOOKUP(A5,'BBT3'!A:F,2,0),"") -> Bill | C5: =IF(NOT(ISBLANK(A5)),VLOOKUP(A5,'BBT3'!A:F,3,0),"") -> US912797SK41 | D5: =IF(NOT(ISBLANK(A5)),VLOOKUP(A5,'BBT3'!A:F,4,1),"") -> 0 | E5: =IF(NOT(ISBLANK(A5)),VLOOKUP(A5,'BBT3'!A:F,5,0),"") -> 46324 | F5: =IF(NOT(ISBLANK(A5)),VLOOKUP(A5,'BBT3'!A:F,6,0),"") -> N | G5: =IF(NOT(ISBLANK(A5)),IF(D5=0,"Y","N"),"") -> Y | H5: =IF(NOT(ISBLANK(A5)),VLOOKUP(A5,'Close - PriceSaver'!A:J,5,0),"") -> 0.038428587 | I5: {=IF(NOT(ISBLANK(A5)),((_xlfn.XLOOKUP(1,(_bbt3[[#All],[ID]]=A5)*(_bbt3[[#All],[METRIC_NAME]]="YLD_YTM_ASK"),_bbt3[[#All],[METRIC_VALUE]])*0.5)+(_xlfn.XLOOKUP(1,(_bbt3[[#All],[ID]]=A5)*(_bbt3[[#All],[METRIC_NAME]]="YLD_YTM_BID"),_bbt3[[#All],[METRIC_VALUE]])*0.5))/100,"")} -> 0.038265 | J5: =IF(ISNA(VLOOKUP(A5,'CloseDL - PriceSaverBBT3'!A:E,5,0)),0,VLOOKUP(A5,'CloseDL - PriceSaverBBT3'!A:E,5,0)) -> 0.038428587 | K5: =IF(ISNA(IF(NOT(ISBLANK(A5)),ABS(H5-J5),"")),0,(IF(NOT(ISBLANK(A5)),ABS(H5-J5)*10000,""))) -> 0 | L5: =IF(Close[[#This Row],[CreatedBy]]="MARINER\SilverAdm",1,0) -> 0 | M5: =IF(NOT(ISBLANK(A5)),VLOOKUP(A5,'Close - PriceSaver'!A:J,6,0),"") -> DL Bill input Discount = 3.73495000 PX_ASK = 3.72960000 PX_BID = 3.74030000 | S5: {=COUNT(_xlfn._xlws.FILTER(K2:K3500,ISNUMBER(K2:K3500)*(F2:F3500="N")*(B2:B3500="Bond")*(G2:G3500="N")*(L2:L3500=1)))} -> 0
A6: 912797SU2 | B6: =IF(NOT(ISBLANK(A6)),VLOOKUP(A6,'BBT3'!A:F,2,0),"") -> Bill | C6: =IF(NOT(ISBLANK(A6)),VLOOKUP(A6,'BBT3'!A:F,3,0),"") -> US912797SU23 | D6: =IF(NOT(ISBLANK(A6)),VLOOKUP(A6,'BBT3'!A:F,4,1),"") -> 0 | E6: =IF(NOT(ISBLANK(A6)),VLOOKUP(A6,'BBT3'!A:F,5,0),"") -> 46353 | F6: =IF(NOT(ISBLANK(A6)),VLOOKUP(A6,'BBT3'!A:F,6,0),"") -> N | G6: =IF(NOT(ISBLANK(A6)),IF(D6=0,"Y","N"),"") -> Y | H6: =IF(NOT(ISBLANK(A6)),VLOOKUP(A6,'Close - PriceSaver'!A:J,5,0),"") -> 0.038862044 | I6: {=IF(NOT(ISBLANK(A6)),((_xlfn.XLOOKUP(1,(_bbt3[[#All],[ID]]=A6)*(_bbt3[[#All],[METRIC_NAME]]="YLD_YTM_ASK"),_bbt3[[#All],[METRIC_VALUE]])*0.5)+(_xlfn.XLOOKUP(1,(_bbt3[[#All],[ID]]=A6)*(_bbt3[[#All],[METRIC_NAME]]="YLD_YTM_BID"),_bbt3[[#All],[METRIC_VALUE]])*0.5))/100,"")} -> 0.03875 | J6: =IF(ISNA(VLOOKUP(A6,'CloseDL - PriceSaverBBT3'!A:E,5,0)),0,VLOOKUP(A6,'CloseDL - PriceSaverBBT3'!A:E,5,0)) -> 0.038862044 | K6: =IF(ISNA(IF(NOT(ISBLANK(A6)),ABS(H6-J6),"")),0,(IF(NOT(ISBLANK(A6)),ABS(H6-J6)*10000,""))) -> 0 | L6: =IF(Close[[#This Row],[CreatedBy]]="MARINER\SilverAdm",1,0) -> 0 | M6: =IF(NOT(ISBLANK(A6)),VLOOKUP(A6,'Close - PriceSaver'!A:J,6,0),"") -> DL Bill input Discount = 3.77070000 PX_ASK = 3.76210000 PX_BID = 3.77930000 | S6: {=COUNT(_xlfn._xlws.FILTER(K2:K3500,ISNUMBER(K2:K3500)*(F2:F3500="N")*(B2:B3500="Bond")*(G2:G3500="N")*(L2:L3500=1)))} -> 0
A7: 912797TC1 | B7: =IF(NOT(ISBLANK(A7)),VLOOKUP(A7,'BBT3'!A:F,2,0),"") -> Bill | C7: =IF(NOT(ISBLANK(A7)),VLOOKUP(A7,'BBT3'!A:F,3,0),"") -> US912797TC16 | D7: =IF(NOT(ISBLANK(A7)),VLOOKUP(A7,'BBT3'!A:F,4,1),"") -> 0 | E7: =IF(NOT(ISBLANK(A7)),VLOOKUP(A7,'BBT3'!A:F,5,0),"") -> 46380 | F7: =IF(NOT(ISBLANK(A7)),VLOOKUP(A7,'BBT3'!A:F,6,0),"") -> N | G7: =IF(NOT(ISBLANK(A7)),IF(D7=0,"Y","N"),"") -> Y | H7: =IF(NOT(ISBLANK(A7)),VLOOKUP(A7,'Close - PriceSaver'!A:J,5,0),"") -> 0.039483145 | I7: {=IF(NOT(ISBLANK(A7)),((_xlfn.XLOOKUP(1,(_bbt3[[#All],[ID]]=A7)*(_bbt3[[#All],[METRIC_NAME]]="YLD_YTM_ASK"),_bbt3[[#All],[METRIC_VALUE]])*0.5)+(_xlfn.XLOOKUP(1,(_bbt3[[#All],[ID]]=A7)*(_bbt3[[#All],[METRIC_NAME]]="YLD_YTM_BID"),_bbt3[[#All],[METRIC_VALUE]])*0.5))/100,"")} -> 0.039425 | J7: =IF(ISNA(VLOOKUP(A7,'CloseDL - PriceSaverBBT3'!A:E,5,0)),0,VLOOKUP(A7,'CloseDL - PriceSaverBBT3'!A:E,5,0)) -> 0.039483145 | K7: =IF(ISNA(IF(NOT(ISBLANK(A7)),ABS(H7-J7),"")),0,(IF(NOT(ISBLANK(A7)),ABS(H7-J7)*10000,""))) -> 0 | L7: =IF(Close[[#This Row],[CreatedBy]]="MARINER\SilverAdm",1,0) -> 0 | M7: =IF(NOT(ISBLANK(A7)),VLOOKUP(A7,'Close - PriceSaver'!A:J,6,0),"") -> DL Bill input Discount = 3.82445000 PX_ASK = 3.81830000 PX_BID = 3.83060000
A8: 912797TM9 | B8: =IF(NOT(ISBLANK(A8)),VLOOKUP(A8,'BBT3'!A:F,2,0),"") -> Bill | C8: =IF(NOT(ISBLANK(A8)),VLOOKUP(A8,'BBT3'!A:F,3,0),"") -> US912797TM97 | D8: =IF(NOT(ISBLANK(A8)),VLOOKUP(A8,'BBT3'!A:F,4,1),"") -> 0 | E8: =IF(NOT(ISBLANK(A8)),VLOOKUP(A8,'BBT3'!A:F,5,0),"") -> 46408 | F8: =IF(NOT(ISBLANK(A8)),VLOOKUP(A8,'BBT3'!A:F,6,0),"") -> N | G8: =IF(NOT(ISBLANK(A8)),IF(D8=0,"Y","N"),"") -> Y | H8: =IF(NOT(ISBLANK(A8)),VLOOKUP(A8,'Close - PriceSaver'!A:J,5,0),"") -> 0.039567644 | I8: {=IF(NOT(ISBLANK(A8)),((_xlfn.XLOOKUP(1,(_bbt3[[#All],[ID]]=A8)*(_bbt3[[#All],[METRIC_NAME]]="YLD_YTM_ASK"),_bbt3[[#All],[METRIC_VALUE]])*0.5)+(_xlfn.XLOOKUP(1,(_bbt3[[#All],[ID]]=A8)*(_bbt3[[#All],[METRIC_NAME]]="YLD_YTM_BID"),_bbt3[[#All],[METRIC_VALUE]])*0.5))/100,"")} -> 0.039565 | J8: =IF(ISNA(VLOOKUP(A8,'CloseDL - PriceSaverBBT3'!A:E,5,0)),0,VLOOKUP(A8,'CloseDL - PriceSaverBBT3'!A:E,5,0)) -> 0.039567644 | K8: =IF(ISNA(IF(NOT(ISBLANK(A8)),ABS(H8-J8),"")),0,(IF(NOT(ISBLANK(A8)),ABS(H8-J8)*10000,""))) -> 0 | L8: =IF(Close[[#This Row],[CreatedBy]]="MARINER\SilverAdm",1,0) -> 0 | M8: =IF(NOT(ISBLANK(A8)),VLOOKUP(A8,'Close - PriceSaver'!A:J,6,0),"") -> DL Bill input Discount = 3.82675000 PX_ASK = 3.81470000 PX_BID = 3.83880000
A9: 912797TP2 | B9: =IF(NOT(ISBLANK(A9)),VLOOKUP(A9,'BBT3'!A:F,2,0),"") -> Bill | C9: =IF(NOT(ISBLANK(A9)),VLOOKUP(A9,'BBT3'!A:F,3,0),"") -> US912797TP29 | D9: =IF(NOT(ISBLANK(A9)),VLOOKUP(A9,'BBT3'!A:F,4,1),"") -> 0 | E9: =IF(NOT(ISBLANK(A9)),VLOOKUP(A9,'BBT3'!A:F,5,0),"") -> 46226 | F9: =IF(NOT(ISBLANK(A9)),VLOOKUP(A9,'BBT3'!A:F,6,0),"") -> N | G9: =IF(NOT(ISBLANK(A9)),IF(D9=0,"Y","N"),"") -> Y | H9: =IF(NOT(ISBLANK(A9)),VLOOKUP(A9,'Close - PriceSaver'!A:J,5,0),"") -> 0.036216935 | I9: {=IF(NOT(ISBLANK(A9)),((_xlfn.XLOOKUP(1,(_bbt3[[#All],[ID]]=A9)*(_bbt3[[#All],[METRIC_NAME]]="YLD_YTM_ASK"),_bbt3[[#All],[METRIC_VALUE]])*0.5)+(_xlfn.XLOOKUP(1,(_bbt3[[#All],[ID]]=A9)*(_bbt3[[#All],[METRIC_NAME]]="YLD_YTM_BID"),_bbt3[[#All],[METRIC_VALUE]])*0.5))/100,"")} -> 0.035895 | J9: =IF(ISNA(VLOOKUP(A9,'CloseDL - PriceSaverBBT3'!A:E,5,0)),0,VLOOKUP(A9,'CloseDL - PriceSaverBBT3'!A:E,5,0)) -> 0.036216935 | K9: =IF(ISNA(IF(NOT(ISBLANK(A9)),ABS(H9-J9),"")),0,(IF(NOT(ISBLANK(A9)),ABS(H9-J9)*10000,""))) -> 0 | L9: =IF(Close[[#This Row],[CreatedBy]]="MARINER\SilverAdm",1,0) -> 1 | M9: =IF(NOT(ISBLANK(A9)),VLOOKUP(A9,'Close - PriceSaver'!A:J,6,0),"") -> DL Bill input Discount = 3.53995000 PX_ASK = 3.52780000 PX_BID = 3.55210000
A10: 912797TQ0 | B10: =IF(NOT(ISBLANK(A10)),VLOOKUP(A10,'BBT3'!A:F,2,0),"") -> Bill | C10: =IF(NOT(ISBLANK(A10)),VLOOKUP(A10,'BBT3'!A:F,3,0),"") -> US912797TQ02 | D10: =IF(NOT(ISBLANK(A10)),VLOOKUP(A10,'BBT3'!A:F,4,1),"") -> 0 | E10: =IF(NOT(ISBLANK(A10)),VLOOKUP(A10,'BBT3'!A:F,5,0),"") -> 46233 | F10: =IF(NOT(ISBLANK(A10)),VLOOKUP(A10,'BBT3'!A:F,6,0),"") -> N | G10: =IF(NOT(ISBLANK(A10)),IF(D10=0,"Y","N"),"") -> Y | H10: =IF(NOT(ISBLANK(A10)),VLOOKUP(A10,'Close - PriceSaver'!A:J,5,0),"") -> 0.036351425 | I10: {=IF(NOT(ISBLANK(A10)),((_xlfn.XLOOKUP(1,(_bbt3[[#All],[ID]]=A10)*(_bbt3[[#All],[METRIC_NAME]]="YLD_YTM_ASK"),_bbt3[[#All],[METRIC_VALUE]])*0.5)+(_xlfn.XLOOKUP(1,(_bbt3[[#All],[ID]]=A10)*(_bbt3[[#All],[METRIC_NAME]]="YLD_YTM_BID"),_bbt3[[#All],[METRIC_VALUE]])*0.5))/100,"")} -> 0.03604 | J10: =IF(ISNA(VLOOKUP(A10,'CloseDL - PriceSaverBBT3'!A:E,5,0)),0,VLOOKUP(A10,'CloseDL - PriceSaverBBT3'!A:E,5,0)) -> 0.036351425 | K10: =IF(ISNA(IF(NOT(ISBLANK(A10)),ABS(H10-J10),"")),0,(IF(NOT(ISBLANK(A10)),ABS(H10-J10)*10000,""))) -> 0 | L10: =IF(Close[[#This Row],[CreatedBy]]="MARINER\SilverAdm",1,0) -> 1 | M10: =IF(NOT(ISBLANK(A10)),VLOOKUP(A10,'Close - PriceSaver'!A:J,6,0),"") -> DL Bill input Discount = 3.55175000 PX_ASK = 3.54230000 PX_BID = 3.56120000
A11: 912797TV9 | B11: =IF(NOT(ISBLANK(A11)),VLOOKUP(A11,'BBT3'!A:F,2,0),"") -> Bill | C11: =IF(NOT(ISBLANK(A11)),VLOOKUP(A11,'BBT3'!A:F,3,0),"") -> US912797TV96 | D11: =IF(NOT(ISBLANK(A11)),VLOOKUP(A11,'BBT3'!A:F,4,1),"") -> 0 | E11: =IF(NOT(ISBLANK(A11)),VLOOKUP(A11,'BBT3'!A:F,5,0),"") -> 46436 | F11: =IF(NOT(ISBLANK(A11)),VLOOKUP(A11,'BBT3'!A:F,6,0),"") -> N | G11: =IF(NOT(ISBLANK(A11)),IF(D11=0,"Y","N"),"") -> Y | H11: =IF(NOT(ISBLANK(A11)),VLOOKUP(A11,'Close - PriceSaver'!A:J,5,0),"") -> 0.03889128 | I11: {=IF(NOT(ISBLANK(A11)),((_xlfn.XLOOKUP(1,(_bbt3[[#All],[ID]]=A11)*(_bbt3[[#All],[METRIC_NAME]]="YLD_YTM_ASK"),_bbt3[[#All],[METRIC_VALUE]])*0.5)+(_xlfn.XLOOKUP(1,(_bbt3[[#All],[ID]]=A11)*(_bbt3[[#All],[METRIC_NAME]]="YLD_YTM_BID"),_bbt3[[#All],[METRIC_VALUE]])*0.5))/100,"")} -> 0.03885 | J11: =IF(ISNA(VLOOKUP(A11,'CloseDL - PriceSaverBBT3'!A:E,5,0)),0,VLOOKUP(A11,'CloseDL - PriceSaverBBT3'!A:E,5,0)) -> 0.03889128 | K11: =IF(ISNA(IF(NOT(ISBLANK(A11)),ABS(H11-J11),"")),0,(IF(NOT(ISBLANK(A11)),ABS(H11-J11)*10000,""))) -> 0 | L11: =IF(Close[[#This Row],[CreatedBy]]="MARINER\SilverAdm",1,0) -> 1 | M11: =IF(NOT(ISBLANK(A11)),VLOOKUP(A11,'Close - PriceSaver'!A:J,6,0),"") -> DL Bill input Discount = 3.75705000 PX_ASK = 3.73450000 PX_BID = 3.77960000
A12: 912797TW7 | B12: =IF(NOT(ISBLANK(A12)),VLOOKUP(A12,'BBT3'!A:F,2,0),"") -> Bill | C12: =IF(NOT(ISBLANK(A12)),VLOOKUP(A12,'BBT3'!A:F,3,0),"") -> US912797TW79 | D12: =IF(NOT(ISBLANK(A12)),VLOOKUP(A12,'BBT3'!A:F,4,1),"") -> 0 | E12: =IF(NOT(ISBLANK(A12)),VLOOKUP(A12,'BBT3'!A:F,5,0),"") -> 46247 | F12: =IF(NOT(ISBLANK(A12)),VLOOKUP(A12,'BBT3'!A:F,6,0),"") -> N | G12: =IF(NOT(ISBLANK(A12)),IF(D12=0,"Y","N"),"") -> Y | H12: =IF(NOT(ISBLANK(A12)),VLOOKUP(A12,'Close - PriceSaver'!A:J,5,0),"") -> 0.036994026 | I12: {=IF(NOT(ISBLANK(A12)),((_xlfn.XLOOKUP(1,(_bbt3[[#All],[ID]]=A12)*(_bbt3[[#All],[METRIC_NAME]]="YLD_YTM_ASK"),_bbt3[[#All],[METRIC_VALUE]])*0.5)+(_xlfn.XLOOKUP(1,(_bbt3[[#All],[ID]]=A12)*(_bbt3[[#All],[METRIC_NAME]]="YLD_YTM_BID"),_bbt3[[#All],[METRIC_VALUE]])*0.5))/100,"")} -> 0.0367 | J12: =IF(ISNA(VLOOKUP(A12,'CloseDL - PriceSaverBBT3'!A:E,5,0)),0,VLOOKUP(A12,'CloseDL - PriceSaverBBT3'!A:E,5,0)) -> 0.036994026 | K12: =IF(ISNA(IF(NOT(ISBLANK(A12)),ABS(H12-J12),"")),0,(IF(NOT(ISBLANK(A12)),ABS(H12-J12)*10000,""))) -> 0 | L12: =IF(Close[[#This Row],[CreatedBy]]="MARINER\SilverAdm",1,0) -> 1 | M12: =IF(NOT(ISBLANK(A12)),VLOOKUP(A12,'Close - PriceSaver'!A:J,6,0),"") -> DL Bill input Discount = 3.61140000 PX_ASK = 3.60170000 PX_BID = 3.62110000 | P12: ISIN | R12: Bond Type | S12: Coupon Rate | T12: Maturity | U12: Clode Yield | V12: Clode DL Yield | W12: Diff | X12: Contribution in Close
A13: 912797TX5 | B13: =IF(NOT(ISBLANK(A13)),VLOOKUP(A13,'BBT3'!A:F,2,0),"") -> Bill | C13: =IF(NOT(ISBLANK(A13)),VLOOKUP(A13,'BBT3'!A:F,3,0),"") -> US912797TX52 | D13: =IF(NOT(ISBLANK(A13)),VLOOKUP(A13,'BBT3'!A:F,4,1),"") -> 0 | E13: =IF(NOT(ISBLANK(A13)),VLOOKUP(A13,'BBT3'!A:F,5,0),"") -> 46254 | F13: =IF(NOT(ISBLANK(A13)),VLOOKUP(A13,'BBT3'!A:F,6,0),"") -> N | G13: =IF(NOT(ISBLANK(A13)),IF(D13=0,"Y","N"),"") -> Y | H13: =IF(NOT(ISBLANK(A13)),VLOOKUP(A13,'Close - PriceSaver'!A:J,5,0),"") -> 0.037155788 | I13: {=IF(NOT(ISBLANK(A13)),((_xlfn.XLOOKUP(1,(_bbt3[[#All],[ID]]=A13)*(_bbt3[[#All],[METRIC_NAME]]="YLD_YTM_ASK"),_bbt3[[#All],[METRIC_VALUE]])*0.5)+(_xlfn.XLOOKUP(1,(_bbt3[[#All],[ID]]=A13)*(_bbt3[[#All],[METRIC_NAME]]="YLD_YTM_BID"),_bbt3[[#All],[METRIC_VALUE]])*0.5))/100,"")} -> 0.03687 | J13: =IF(ISNA(VLOOKUP(A13,'CloseDL - PriceSaverBBT3'!A:E,5,0)),0,VLOOKUP(A13,'CloseDL - PriceSaverBBT3'!A:E,5,0)) -> 0.037155788 | K13: =IF(ISNA(IF(NOT(ISBLANK(A13)),ABS(H13-J13),"")),0,(IF(NOT(ISBLANK(A13)),ABS(H13-J13)*10000,""))) -> 0 | L13: =IF(Close[[#This Row],[CreatedBy]]="MARINER\SilverAdm",1,0) -> 1 | M13: =IF(NOT(ISBLANK(A13)),VLOOKUP(A13,'Close - PriceSaver'!A:J,6,0),"") -> DL Bill input Discount = 3.62575000 PX_ASK = 3.61790000 PX_BID = 3.63360000 | P13: {=_xlfn._xlws.FILTER(A2:A3500,(K2:K3500>S4*0.1%)*(G2:G3500="N")*(B2:B3500="Bond")*(F2:F3500="N"))} -> #VALUE! | Q13: =VLOOKUP(P13,A:C,3,0) -> #VALUE! | R13: =VLOOKUP(P13,A:B,2,0) -> #VALUE! | S13: =VLOOKUP(P13,A:E,4,0) -> #VALUE! | T13: =VLOOKUP(P13,A:K,5,0) -> #VALUE! | U13: =VLOOKUP(P13,A:K,8,0) -> #VALUE! | V13: =VLOOKUP(P13,A:K,10,0) -> #VALUE! | W13: =(V13-U13)*100 -> #VALUE! | X13: =VLOOKUP(P13,Close[[ID]:[CreatedBy]],8,0) -> #VALUE!
A14: 912797TY3 | B14: =IF(NOT(ISBLANK(A14)),VLOOKUP(A14,'BBT3'!A:F,2,0),"") -> Bill | C14: =IF(NOT(ISBLANK(A14)),VLOOKUP(A14,'BBT3'!A:F,3,0),"") -> US912797TY36 | D14: =IF(NOT(ISBLANK(A14)),VLOOKUP(A14,'BBT3'!A:F,4,1),"") -> 0 | E14: =IF(NOT(ISBLANK(A14)),VLOOKUP(A14,'BBT3'!A:F,5,0),"") -> 46261 | F14: =IF(NOT(ISBLANK(A14)),VLOOKUP(A14,'BBT3'!A:F,6,0),"") -> N | G14: =IF(NOT(ISBLANK(A14)),IF(D14=0,"Y","N"),"") -> Y | H14: =IF(NOT(ISBLANK(A14)),VLOOKUP(A14,'Close - PriceSaver'!A:J,5,0),"") -> 0.037284099 | I14: {=IF(NOT(ISBLANK(A14)),((_xlfn.XLOOKUP(1,(_bbt3[[#All],[ID]]=A14)*(_bbt3[[#All],[METRIC_NAME]]="YLD_YTM_ASK"),_bbt3[[#All],[METRIC_VALUE]])*0.5)+(_xlfn.XLOOKUP(1,(_bbt3[[#All],[ID]]=A14)*(_bbt3[[#All],[METRIC_NAME]]="YLD_YTM_BID"),_bbt3[[#All],[METRIC_VALUE]])*0.5))/100,"")} -> 0.03701 | J14: =IF(ISNA(VLOOKUP(A14,'CloseDL - PriceSaverBBT3'!A:E,5,0)),0,VLOOKUP(A14,'CloseDL - PriceSaverBBT3'!A:E,5,0)) -> 0.037284099 | K14: =IF(ISNA(IF(NOT(ISBLANK(A14)),ABS(H14-J14),"")),0,(IF(NOT(ISBLANK(A14)),ABS(H14-J14)*10000,""))) -> 0 | L14: =IF(Close[[#This Row],[CreatedBy]]="MARINER\SilverAdm",1,0) -> 1 | M14: =IF(NOT(ISBLANK(A14)),VLOOKUP(A14,'Close - PriceSaver'!A:J,6,0),"") -> DL Bill input Discount = 3.63685000 PX_ASK = 3.63180000 PX_BID = 3.64190000 | Q14: =VLOOKUP(P14,A:C,3,0) -> #N/A | R14: =VLOOKUP(P14,A:B,2,0) -> #N/A | S14: =VLOOKUP(P14,A:E,4,0) -> #N/A | T14: =VLOOKUP(P14,A:K,5,0) -> #N/A | U14: =VLOOKUP(P14,A:K,8,0) -> #N/A | V14: =VLOOKUP(P14,A:K,10,0) -> #N/A | W14: =(V14-U14)*100 -> #N/A | X14: =VLOOKUP(P14,Close[[ID]:[CreatedBy]],8,0) -> #N/A
A15: 912797UD7 | B15: =IF(NOT(ISBLANK(A15)),VLOOKUP(A15,'BBT3'!A:F,2,0),"") -> Bill | C15: =IF(NOT(ISBLANK(A15)),VLOOKUP(A15,'BBT3'!A:F,3,0),"") -> US912797UD79 | D15: =IF(NOT(ISBLANK(A15)),VLOOKUP(A15,'BBT3'!A:F,4,1),"") -> 0 | E15: =IF(NOT(ISBLANK(A15)),VLOOKUP(A15,'BBT3'!A:F,5,0),"") -> 46464 | F15: =IF(NOT(ISBLANK(A15)),VLOOKUP(A15,'BBT3'!A:F,6,0),"") -> N | G15: =IF(NOT(ISBLANK(A15)),IF(D15=0,"Y","N"),"") -> Y | H15: =IF(NOT(ISBLANK(A15)),VLOOKUP(A15,'Close - PriceSaver'!A:J,5,0),"") -> 0.039127954 | I15: {=IF(NOT(ISBLANK(A15)),((_xlfn.XLOOKUP(1,(_bbt3[[#All],[ID]]=A15)*(_bbt3[[#All],[METRIC_NAME]]="YLD_YTM_ASK"),_bbt3[[#All],[METRIC_VALUE]])*0.5)+(_xlfn.XLOOKUP(1,(_bbt3[[#All],[ID]]=A15)*(_bbt3[[#All],[METRIC_NAME]]="YLD_YTM_BID"),_bbt3[[#All],[METRIC_VALUE]])*0.5))/100,"")} -> 0.039065 | J15: =IF(ISNA(VLOOKUP(A15,'CloseDL - PriceSaverBBT3'!A:E,5,0)),0,VLOOKUP(A15,'CloseDL - PriceSaverBBT3'!A:E,5,0)) -> 0.039127954 | K15: =IF(ISNA(IF(NOT(ISBLANK(A15)),ABS(H15-J15),"")),0,(IF(NOT(ISBLANK(A15)),ABS(H15-J15)*10000,""))) -> 0 | L15: =IF(Close[[#This Row],[CreatedBy]]="MARINER\SilverAdm",1,0) -> 1 | M15: =IF(NOT(ISBLANK(A15)),VLOOKUP(A15,'Close - PriceSaver'!A:J,6,0),"") -> DL Bill input Discount = 3.77385000 PX_ASK = 3.75390000 PX_BID = 3.79380000 | Q15: =VLOOKUP(P15,A:C,3,0) -> #N/A | R15: =VLOOKUP(P15,A:B,2,0) -> #N/A | S15: =VLOOKUP(P15,A:E,4,0) -> #N/A | T15: =VLOOKUP(P15,A:K,5,0) -> #N/A | U15: =VLOOKUP(P15,A:K,8,0) -> #N/A | V15: =VLOOKUP(P15,A:K,10,0) -> #N/A | W15: =(V15-U15)*100 -> #N/A | X15: =VLOOKUP(P15,Close[[ID]:[CreatedBy]],8,0) -> #N/A
A16: 912797UE5 | B16: =IF(NOT(ISBLANK(A16)),VLOOKUP(A16,'BBT3'!A:F,2,0),"") -> Bill | C16: =IF(NOT(ISBLANK(A16)),VLOOKUP(A16,'BBT3'!A:F,3,0),"") -> US912797UE52 | D16: =IF(NOT(ISBLANK(A16)),VLOOKUP(A16,'BBT3'!A:F,4,1),"") -> 0 | E16: =IF(NOT(ISBLANK(A16)),VLOOKUP(A16,'BBT3'!A:F,5,0),"") -> 46492 | F16: =IF(NOT(ISBLANK(A16)),VLOOKUP(A16,'BBT3'!A:F,6,0),"") -> N | G16: =IF(NOT(ISBLANK(A16)),IF(D16=0,"Y","N"),"") -> Y | H16: =IF(NOT(ISBLANK(A16)),VLOOKUP(A16,'Close - PriceSaver'!A:J,5,0),"") -> 0.039584616 | I16: {=IF(NOT(ISBLANK(A16)),((_xlfn.XLOOKUP(1,(_bbt3[[#All],[ID]]=A16)*(_bbt3[[#All],[METRIC_NAME]]="YLD_YTM_ASK"),_bbt3[[#All],[METRIC_VALUE]])*0.5)+(_xlfn.XLOOKUP(1,(_bbt3[[#All],[ID]]=A16)*(_bbt3[[#All],[METRIC_NAME]]="YLD_YTM_BID"),_bbt3[[#All],[METRIC_VALUE]])*0.5))/100,"")} -> 0.039515 | J16: =IF(ISNA(VLOOKUP(A16,'CloseDL - PriceSaverBBT3'!A:E,5,0)),0,VLOOKUP(A16,'CloseDL - PriceSaverBBT3'!A:E,5,0)) -> 0.039584616 | K16: =IF(ISNA(IF(NOT(ISBLANK(A16)),ABS(H16-J16),"")),0,(IF(NOT(ISBLANK(A16)),ABS(H16-J16)*10000,""))) -> 0 | L16: =IF(Close[[#This Row],[CreatedBy]]="MARINER\SilverAdm",1,0) -> 1 | M16: =IF(NOT(ISBLANK(A16)),VLOOKUP(A16,'Close - PriceSaver'!A:J,6,0),"") -> DL Bill input Discount = 3.81120000 PX_ASK = 3.79100000 PX_BID = 3.83140000 | Q16: =VLOOKUP(P16,A:C,3,0) -> #N/A | R16: =VLOOKUP(P16,A:B,2,0) -> #N/A | S16: =VLOOKUP(P16,A:E,4,0) -> #N/A | T16: =VLOOKUP(P16,A:K,5,0) -> #N/A | U16: =VLOOKUP(P16,A:K,8,0) -> #N/A | V16: =VLOOKUP(P16,A:K,10,0) -> #N/A | W16: =(V16-U16)*100 -> #N/A | X16: =VLOOKUP(P16,Close[[ID]:[CreatedBy]],8,0) -> #N/A
A17: 912797UF2 | B17: =IF(NOT(ISBLANK(A17)),VLOOKUP(A17,'BBT3'!A:F,2,0),"") -> Bill | C17: =IF(NOT(ISBLANK(A17)),VLOOKUP(A17,'BBT3'!A:F,3,0),"") -> US912797UF28 | D17: =IF(NOT(ISBLANK(A17)),VLOOKUP(A17,'BBT3'!A:F,4,1),"") -> 0 | E17: =IF(NOT(ISBLANK(A17)),VLOOKUP(A17,'BBT3'!A:F,5,0),"") -> 46275 | F17: =IF(NOT(ISBLANK(A17)),VLOOKUP(A17,'BBT3'!A:F,6,0),"") -> N | G17: =IF(NOT(ISBLANK(A17)),IF(D17=0,"Y","N"),"") -> Y | H17: =IF(NOT(ISBLANK(A17)),VLOOKUP(A17,'Close - PriceSaver'!A:J,5,0),"") -> 0.037402686 | I17: {=IF(NOT(ISBLANK(A17)),((_xlfn.XLOOKUP(1,(_bbt3[[#All],[ID]]=A17)*(_bbt3[[#All],[METRIC_NAME]]="YLD_YTM_ASK"),_bbt3[[#All],[METRIC_VALUE]])*0.5)+(_xlfn.XLOOKUP(1,(_bbt3[[#All],[ID]]=A17)*(_bbt3[[#All],[METRIC_NAME]]="YLD_YTM_BID"),_bbt3[[#All],[METRIC_VALUE]])*0.5))/100,"")} -> 0.03715 | J17: =IF(ISNA(VLOOKUP(A17,'CloseDL - PriceSaverBBT3'!A:E,5,0)),0,VLOOKUP(A17,'CloseDL - PriceSaverBBT3'!A:E,5,0)) -> 0.037402686 | K17: =IF(ISNA(IF(NOT(ISBLANK(A17)),ABS(H17-J17),"")),0,(IF(NOT(ISBLANK(A17)),ABS(H17-J17)*10000,""))) -> 0 | L17: =IF(Close[[#This Row],[CreatedBy]]="MARINER\SilverAdm",1,0) -> 1 | M17: =IF(NOT(ISBLANK(A17)),VLOOKUP(A17,'Close - PriceSaver'!A:J,6,0),"") -> DL Bill input Discount = 3.64570000 PX_ASK = 3.63990000 PX_BID = 3.65150000 | Q17: =VLOOKUP(P17,A:C,3,0) -> #N/A | R17: =VLOOKUP(P17,A:B,2,0) -> #N/A | S17: =VLOOKUP(P17,A:E,4,0) -> #N/A | T17: =VLOOKUP(P17,A:K,5,0) -> #N/A | U17: =VLOOKUP(P17,A:K,8,0) -> #N/A | V17: =VLOOKUP(P17,A:K,10,0) -> #N/A | W17: =(V17-U17)*100 -> #N/A | X17: =VLOOKUP(P17,Close[[ID]:[CreatedBy]],8,0) -> #N/A
A18: 912797UG0 | B18: =IF(NOT(ISBLANK(A18)),VLOOKUP(A18,'BBT3'!A:F,2,0),"") -> Bill | C18: =IF(NOT(ISBLANK(A18)),VLOOKUP(A18,'BBT3'!A:F,3,0),"") -> US912797UG01 | D18: =IF(NOT(ISBLANK(A18)),VLOOKUP(A18,'BBT3'!A:F,4,1),"") -> 0 | E18: =IF(NOT(ISBLANK(A18)),VLOOKUP(A18,'BBT3'!A:F,5,0),"") -> 46282 | F18: =IF(NOT(ISBLANK(A18)),VLOOKUP(A18,'BBT3'!A:F,6,0),"") -> N | G18: =IF(NOT(ISBLANK(A18)),IF(D18=0,"Y","N"),"") -> Y | H18: =IF(NOT(ISBLANK(A18)),VLOOKUP(A18,'Close - PriceSaver'!A:J,5,0),"") -> 0.037350683 | I18: {=IF(NOT(ISBLANK(A18)),((_xlfn.XLOOKUP(1,(_bbt3[[#All],[ID]]=A18)*(_bbt3[[#All],[METRIC_NAME]]="YLD_YTM_ASK"),_bbt3[[#All],[METRIC_VALUE]])*0.5)+(_xlfn.XLOOKUP(1,(_bbt3[[#All],[ID]]=A18)*(_bbt3[[#All],[METRIC_NAME]]="YLD_YTM_BID"),_bbt3[[#All],[METRIC_VALUE]])*0.5))/100,"")} -> #N/A | J18: =IF(ISNA(VLOOKUP(A18,'CloseDL - PriceSaverBBT3'!A:E,5,0)),0,VLOOKUP(A18,'CloseDL - PriceSaverBBT3'!A:E,5,0)) -> 0.037350683 | K18: =IF(ISNA(IF(NOT(ISBLANK(A18)),ABS(H18-J18),"")),0,(IF(NOT(ISBLANK(A18)),ABS(H18-J18)*10000,""))) -> 0 | L18: =IF(Close[[#This Row],[CreatedBy]]="MARINER\SilverAdm",1,0) -> 1 | M18: =IF(NOT(ISBLANK(A18)),VLOOKUP(A18,'Close - PriceSaver'!A:J,6,0),"") -> DL Bill input Discount = 3.63940000 PX_ASK = 3.63170000 PX_BID = 3.64710000 | Q18: =VLOOKUP(P18,A:C,3,0) -> #N/A | R18: =VLOOKUP(P18,A:B,2,0) -> #N/A | S18: =VLOOKUP(P18,A:E,4,0) -> #N/A | T18: =VLOOKUP(P18,A:K,5,0) -> #N/A | U18: =VLOOKUP(P18,A:K,8,0) -> #N/A | V18: =VLOOKUP(P18,A:K,10,0) -> #N/A | W18: =(V18-U18)*100 -> #N/A | X18: =VLOOKUP(P18,Close[[ID]:[CreatedBy]],8,0) -> #N/A
A19: 912797UH8 | B19: =IF(NOT(ISBLANK(A19)),VLOOKUP(A19,'BBT3'!A:F,2,0),"") -> Bill | C19: =IF(NOT(ISBLANK(A19)),VLOOKUP(A19,'BBT3'!A:F,3,0),"") -> US912797UH83 | D19: =IF(NOT(ISBLANK(A19)),VLOOKUP(A19,'BBT3'!A:F,4,1),"") -> 0 | E19: =IF(NOT(ISBLANK(A19)),VLOOKUP(A19,'BBT3'!A:F,5,0),"") -> 46289 | F19: =IF(NOT(ISBLANK(A19)),VLOOKUP(A19,'BBT3'!A:F,6,0),"") -> N | G19: =IF(NOT(ISBLANK(A19)),IF(D19=0,"Y","N"),"") -> Y | H19: =IF(NOT(ISBLANK(A19)),VLOOKUP(A19,'Close - PriceSaver'!A:J,5,0),"") -> 0.037403076 | I19: {=IF(NOT(ISBLANK(A19)),((_xlfn.XLOOKUP(1,(_bbt3[[#All],[ID]]=A19)*(_bbt3[[#All],[METRIC_NAME]]="YLD_YTM_ASK"),_bbt3[[#All],[METRIC_VALUE]])*0.5)+(_xlfn.XLOOKUP(1,(_bbt3[[#All],[ID]]=A19)*(_bbt3[[#All],[METRIC_NAME]]="YLD_YTM_BID"),_bbt3[[#All],[METRIC_VALUE]])*0.5))/100,"")} -> 0.03718 | J19: =IF(ISNA(VLOOKUP(A19,'CloseDL - PriceSaverBBT3'!A:E,5,0)),0,VLOOKUP(A19,'CloseDL - PriceSaverBBT3'!A:E,5,0)) -> 0.037403076 | K19: =IF(ISNA(IF(NOT(ISBLANK(A19)),ABS(H19-J19),"")),0,(IF(NOT(ISBLANK(A19)),ABS(H19-J19)*10000,""))) -> 0 | L19: =IF(Close[[#This Row],[CreatedBy]]="MARINER\SilverAdm",1,0) -> 1 | M19: =IF(NOT(ISBLANK(A19)),VLOOKUP(A19,'Close - PriceSaver'!A:J,6,0),"") -> DL Bill input Discount = 3.64315000 PX_ASK = 3.63850000 PX_BID = 3.64780000 | Q19: =VLOOKUP(P19,A:C,3,0) -> #N/A | R19: =VLOOKUP(P19,A:B,2,0) -> #N/A | S19: =VLOOKUP(P19,A:E,4,0) -> #N/A | T19: =VLOOKUP(P19,A:K,5,0) -> #N/A | U19: =VLOOKUP(P19,A:K,8,0) -> #N/A | V19: =VLOOKUP(P19,A:K,10,0) -> #N/A | W19: =(V19-U19)*100 -> #N/A | X19: =VLOOKUP(P19,Close[[ID]:[CreatedBy]],8,0) -> #N/A
A20: 912797UJ4 | B20: =IF(NOT(ISBLANK(A20)),VLOOKUP(A20,'BBT3'!A:F,2,0),"") -> Bill | C20: =IF(NOT(ISBLANK(A20)),VLOOKUP(A20,'BBT3'!A:F,3,0),"") -> US912797UJ40 | D20: =IF(NOT(ISBLANK(A20)),VLOOKUP(A20,'BBT3'!A:F,4,1),"") -> 0 | E20: =IF(NOT(ISBLANK(A20)),VLOOKUP(A20,'BBT3'!A:F,5,0),"") -> 46303 | F20: =IF(NOT(ISBLANK(A20)),VLOOKUP(A20,'BBT3'!A:F,6,0),"") -> N | G20: =IF(NOT(ISBLANK(A20)),IF(D20=0,"Y","N"),"") -> Y | H20: =IF(NOT(ISBLANK(A20)),VLOOKUP(A20,'Close - PriceSaver'!A:J,5,0),"") -> 0.038095395 | I20: {=IF(NOT(ISBLANK(A20)),((_xlfn.XLOOKUP(1,(_bbt3[[#All],[ID]]=A20)*(_bbt3[[#All],[METRIC_NAME]]="YLD_YTM_ASK"),_bbt3[[#All],[METRIC_VALUE]])*0.5)+(_xlfn.XLOOKUP(1,(_bbt3[[#All],[ID]]=A20)*(_bbt3[[#All],[METRIC_NAME]]="YLD_YTM_BID"),_bbt3[[#All],[METRIC_VALUE]])*0.5))/100,"")} -> 0.03789 | J20: =IF(ISNA(VLOOKUP(A20,'CloseDL - PriceSaverBBT3'!A:E,5,0)),0,VLOOKUP(A20,'CloseDL - PriceSaverBBT3'!A:E,5,0)) -> 0.038095395 | K20: =IF(ISNA(IF(NOT(ISBLANK(A20)),ABS(H20-J20),"")),0,(IF(NOT(ISBLANK(A20)),ABS(H20-J20)*10000,""))) -> 0 | L20: =IF(Close[[#This Row],[CreatedBy]]="MARINER\SilverAdm",1,0) -> 1 | M20: =IF(NOT(ISBLANK(A20)),VLOOKUP(A20,'Close - PriceSaver'!A:J,6,0),"") -> DL Bill input Discount = 3.70705000 PX_ASK = 3.70350000 PX_BID = 3.71060000 | Q20: =VLOOKUP(P20,A:C,3,0) -> #N/A | R20: =VLOOKUP(P20,A:B,2,0) -> #N/A | S20: =VLOOKUP(P20,A:E,4,0) -> #N/A | T20: =VLOOKUP(P20,A:K,5,0) -> #N/A | U20: =VLOOKUP(P20,A:K,8,0) -> #N/A | V20: =VLOOKUP(P20,A:K,10,0) -> #N/A | W20: =(V20-U20)*100 -> #N/A | X20: =VLOOKUP(P20,Close[[ID]:[CreatedBy]],8,0) -> #N/A
A21: 912797UK1 | B21: =IF(NOT(ISBLANK(A21)),VLOOKUP(A21,'BBT3'!A:F,2,0),"") -> Bill | C21: =IF(NOT(ISBLANK(A21)),VLOOKUP(A21,'BBT3'!A:F,3,0),"") -> US912797UK13 | D21: =IF(NOT(ISBLANK(A21)),VLOOKUP(A21,'BBT3'!A:F,4,1),"") -> 0 | E21: =IF(NOT(ISBLANK(A21)),VLOOKUP(A21,'BBT3'!A:F,5,0),"") -> 46310 | F21: =IF(NOT(ISBLANK(A21)),VLOOKUP(A21,'BBT3'!A:F,6,0),"") -> N | G21: =IF(NOT(ISBLANK(A21)),IF(D21=0,"Y","N"),"") -> Y | H21: =IF(NOT(ISBLANK(A21)),VLOOKUP(A21,'Close - PriceSaver'!A:J,5,0),"") -> 0.038156782 | I21: {=IF(NOT(ISBLANK(A21)),((_xlfn.XLOOKUP(1,(_bbt3[[#All],[ID]]=A21)*(_bbt3[[#All],[METRIC_NAME]]="YLD_YTM_ASK"),_bbt3[[#All],[METRIC_VALUE]])*0.5)+(_xlfn.XLOOKUP(1,(_bbt3[[#All],[ID]]=A21)*(_bbt3[[#All],[METRIC_NAME]]="YLD_YTM_BID"),_bbt3[[#All],[METRIC_VALUE]])*0.5))/100,"")} -> 0.037965 | J21: =IF(ISNA(VLOOKUP(A21,'CloseDL - PriceSaverBBT3'!A:E,5,0)),0,VLOOKUP(A21,'CloseDL - PriceSaverBBT3'!A:E,5,0)) -> 0.038156782 | K21: =IF(ISNA(IF(NOT(ISBLANK(A21)),ABS(H21-J21),"")),0,(IF(NOT(ISBLANK(A21)),ABS(H21-J21)*10000,""))) -> 0 | L21: =IF(Close[[#This Row],[CreatedBy]]="MARINER\SilverAdm",1,0) -> 1 | M21: =IF(NOT(ISBLANK(A21)),VLOOKUP(A21,'Close - PriceSaver'!A:J,6,0),"") -> DL Bill input Discount = 3.71160000 PX_ASK = 3.70700000 PX_BID = 3.71620000 | Q21: =VLOOKUP(P21,A:C,3,0) -> #N/A | R21: =VLOOKUP(P21,A:B,2,0) -> #N/A | S21: =VLOOKUP(P21,A:E,4,0) -> #N/A | T21: =VLOOKUP(P21,A:K,5,0) -> #N/A | U21: =VLOOKUP(P21,A:K,8,0) -> #N/A | V21: =VLOOKUP(P21,A:K,10,0) -> #N/A | W21: =(V21-U21)*100 -> #N/A | X21: =VLOOKUP(P21,Close[[ID]:[CreatedBy]],8,0) -> #N/A
A22: 912797UL9 | B22: =IF(NOT(ISBLANK(A22)),VLOOKUP(A22,'BBT3'!A:F,2,0),"") -> Bill | C22: =IF(NOT(ISBLANK(A22)),VLOOKUP(A22,'BBT3'!A:F,3,0),"") -> US912797UL95 | D22: =IF(NOT(ISBLANK(A22)),VLOOKUP(A22,'BBT3'!A:F,4,1),"") -> 0 | E22: =IF(NOT(ISBLANK(A22)),VLOOKUP(A22,'BBT3'!A:F,5,0),"") -> 46317 | F22: =IF(NOT(ISBLANK(A22)),VLOOKUP(A22,'BBT3'!A:F,6,0),"") -> N | G22: =IF(NOT(ISBLANK(A22)),IF(D22=0,"Y","N"),"") -> Y | H22: =IF(NOT(ISBLANK(A22)),VLOOKUP(A22,'Close - PriceSaver'!A:J,5,0),"") -> 0.038313186 | I22: {=IF(NOT(ISBLANK(A22)),((_xlfn.XLOOKUP(1,(_bbt3[[#All],[ID]]=A22)*(_bbt3[[#All],[METRIC_NAME]]="YLD_YTM_ASK"),_bbt3[[#All],[METRIC_VALUE]])*0.5)+(_xlfn.XLOOKUP(1,(_bbt3[[#All],[ID]]=A22)*(_bbt3[[#All],[METRIC_NAME]]="YLD_YTM_BID"),_bbt3[[#All],[METRIC_VALUE]])*0.5))/100,"")} -> 0.03813 | J22: =IF(ISNA(VLOOKUP(A22,'CloseDL - PriceSaverBBT3'!A:E,5,0)),0,VLOOKUP(A22,'CloseDL - PriceSaverBBT3'!A:E,5,0)) -> 0.038313186 | K22: =IF(ISNA(IF(NOT(ISBLANK(A22)),ABS(H22-J22),"")),0,(IF(NOT(ISBLANK(A22)),ABS(H22-J22)*10000,""))) -> 0 | L22: =IF(Close[[#This Row],[CreatedBy]]="MARINER\SilverAdm",1,0) -> 1 | M22: =IF(NOT(ISBLANK(A22)),VLOOKUP(A22,'Close - PriceSaver'!A:J,6,0),"") -> DL Bill input Discount = 3.72525000 PX_ASK = 3.71760000 PX_BID = 3.73290000 | Q22: =VLOOKUP(P22,A:C,3,0) -> #N/A | R22: =VLOOKUP(P22,A:B,2,0) -> #N/A | S22: =VLOOKUP(P22,A:E,4,0) -> #N/A | T22: =VLOOKUP(P22,A:K,5,0) -> #N/A | U22: =VLOOKUP(P22,A:K,8,0) -> #N/A | V22: =VLOOKUP(P22,A:K,10,0) -> #N/A | W22: =(V22-U22)*100 -> #N/A | X22: =VLOOKUP(P22,Close[[ID]:[CreatedBy]],8,0) -> #N/A
A23: 912797UM7 | B23: =IF(NOT(ISBLANK(A23)),VLOOKUP(A23,'BBT3'!A:F,2,0),"") -> Bill | C23: =IF(NOT(ISBLANK(A23)),VLOOKUP(A23,'BBT3'!A:F,3,0),"") -> US912797UM78 | D23: =IF(NOT(ISBLANK(A23)),VLOOKUP(A23,'BBT3'!A:F,4,1),"") -> 0 | E23: =IF(NOT(ISBLANK(A23)),VLOOKUP(A23,'BBT3'!A:F,5,0),"") -> 46331 | F23: =IF(NOT(ISBLANK(A23)),VLOOKUP(A23,'BBT3'!A:F,6,0),"") -> N | G23: =IF(NOT(ISBLANK(A23)),IF(D23=0,"Y","N"),"") -> Y | H23: =IF(NOT(ISBLANK(A23)),VLOOKUP(A23,'Close - PriceSaver'!A:J,5,0),"") -> 0.038401009 | I23: {=IF(NOT(ISBLANK(A23)),((_xlfn.XLOOKUP(1,(_bbt3[[#All],[ID]]=A23)*(_bbt3[[#All],[METRIC_NAME]]="YLD_YTM_ASK"),_bbt3[[#All],[METRIC_VALUE]])*0.5)+(_xlfn.XLOOKUP(1,(_bbt3[[#All],[ID]]=A23)*(_bbt3[[#All],[METRIC_NAME]]="YLD_YTM_BID"),_bbt3[[#All],[METRIC_VALUE]])*0.5))/100,"")} -> 0.038245 | J23: =IF(ISNA(VLOOKUP(A23,'CloseDL - PriceSaverBBT3'!A:E,5,0)),0,VLOOKUP(A23,'CloseDL - PriceSaverBBT3'!A:E,5,0)) -> 0.038401009 | K23: =IF(ISNA(IF(NOT(ISBLANK(A23)),ABS(H23-J23),"")),0,(IF(NOT(ISBLANK(A23)),ABS(H23-J23)*10000,""))) -> 0 | L23: =IF(Close[[#This Row],[CreatedBy]]="MARINER\SilverAdm",1,0) -> 1 | M23: =IF(NOT(ISBLANK(A23)),VLOOKUP(A23,'Close - PriceSaver'!A:J,6,0),"") -> DL Bill input Discount = 3.73095000 PX_ASK = 3.72180000 PX_BID = 3.74010000 | Q23: =VLOOKUP(P23,A:C,3,0) -> #N/A | R23: =VLOOKUP(P23,A:B,2,0) -> #N/A | S23: =VLOOKUP(P23,A:E,4,0) -> #N/A | T23: =VLOOKUP(P23,A:K,5,0) -> #N/A | U23: =VLOOKUP(P23,A:K,8,0) -> #N/A | V23: =VLOOKUP(P23,A:K,10,0) -> #N/A | W23: =(V23-U23)*100 -> #N/A | X23: =VLOOKUP(P23,Close[[ID]:[CreatedBy]],8,0) -> #N/A
A24: 912797UR6 | B24: =IF(NOT(ISBLANK(A24)),VLOOKUP(A24,'BBT3'!A:F,2,0),"") -> Bill | C24: =IF(NOT(ISBLANK(A24)),VLOOKUP(A24,'BBT3'!A:F,3,0),"") -> US912797UR65 | D24: =IF(NOT(ISBLANK(A24)),VLOOKUP(A24,'BBT3'!A:F,4,1),"") -> 0 | E24: =IF(NOT(ISBLANK(A24)),VLOOKUP(A24,'BBT3'!A:F,5,0),"") -> 46231 | F24: =IF(NOT(ISBLANK(A24)),VLOOKUP(A24,'BBT3'!A:F,6,0),"") -> N | G24: =IF(NOT(ISBLANK(A24)),IF(D24=0,"Y","N"),"") -> Y | H24: =IF(NOT(ISBLANK(A24)),VLOOKUP(A24,'Close - PriceSaver'!A:J,5,0),"") -> 0.036217659 | I24: {=IF(NOT(ISBLANK(A24)),((_xlfn.XLOOKUP(1,(_bbt3[[#All],[ID]]=A24)*(_bbt3[[#All],[METRIC_NAME]]="YLD_YTM_ASK"),_bbt3[[#All],[METRIC_VALUE]])*0.5)+(_xlfn.XLOOKUP(1,(_bbt3[[#All],[ID]]=A24)*(_bbt3[[#All],[METRIC_NAME]]="YLD_YTM_BID"),_bbt3[[#All],[METRIC_VALUE]])*0.5))/100,"")} -> 0.035905 | J24: =IF(ISNA(VLOOKUP(A24,'CloseDL - PriceSaverBBT3'!A:E,5,0)),0,VLOOKUP(A24,'CloseDL - PriceSaverBBT3'!A:E,5,0)) -> 0.036217659 | K24: =IF(ISNA(IF(NOT(ISBLANK(A24)),ABS(H24-J24),"")),0,(IF(NOT(ISBLANK(A24)),ABS(H24-J24)*10000,""))) -> 0 | L24: =IF(Close[[#This Row],[CreatedBy]]="MARINER\SilverAdm",1,0) -> 1 | M24: =IF(NOT(ISBLANK(A24)),VLOOKUP(A24,'Close - PriceSaver'!A:J,6,0),"") -> DL Bill input Discount = 3.53915000 PX_ASK = 3.53170000 PX_BID = 3.54660000 | Q24: =VLOOKUP(P24,A:C,3,0) -> #N/A | R24: =VLOOKUP(P24,A:B,2,0) -> #N/A | S24: =VLOOKUP(P24,A:E,4,0) -> #N/A | T24: =VLOOKUP(P24,A:K,5,0) -> #N/A | U24: =VLOOKUP(P24,A:K,8,0) -> #N/A | V24: =VLOOKUP(P24,A:K,10,0) -> #N/A | W24: =(V24-U24)*100 -> #N/A | X24: =VLOOKUP(P24,Close[[ID]:[CreatedBy]],8,0) -> #N/A
A25: 912797US4 | B25: =IF(NOT(ISBLANK(A25)),VLOOKUP(A25,'BBT3'!A:F,2,0),"") -> Bill | C25: =IF(NOT(ISBLANK(A25)),VLOOKUP(A25,'BBT3'!A:F,3,0),"") -> US912797US49 | D25: =IF(NOT(ISBLANK(A25)),VLOOKUP(A25,'BBT3'!A:F,4,1),"") -> 0 | E25: =IF(NOT(ISBLANK(A25)),VLOOKUP(A25,'BBT3'!A:F,5,0),"") -> 46238 | F25: =IF(NOT(ISBLANK(A25)),VLOOKUP(A25,'BBT3'!A:F,6,0),"") -> N | G25: =IF(NOT(ISBLANK(A25)),IF(D25=0,"Y","N"),"") -> Y | H25: =IF(NOT(ISBLANK(A25)),VLOOKUP(A25,'Close - PriceSaver'!A:J,5,0),"") -> 0.036750206 | I25: {=IF(NOT(ISBLANK(A25)),((_xlfn.XLOOKUP(1,(_bbt3[[#All],[ID]]=A25)*(_bbt3[[#All],[METRIC_NAME]]="YLD_YTM_ASK"),_bbt3[[#All],[METRIC_VALUE]])*0.5)+(_xlfn.XLOOKUP(1,(_bbt3[[#All],[ID]]=A25)*(_bbt3[[#All],[METRIC_NAME]]="YLD_YTM_BID"),_bbt3[[#All],[METRIC_VALUE]])*0.5))/100,"")} -> 0.03644 | J25: =IF(ISNA(VLOOKUP(A25,'CloseDL - PriceSaverBBT3'!A:E,5,0)),0,VLOOKUP(A25,'CloseDL - PriceSaverBBT3'!A:E,5,0)) -> 0.036750206 | K25: =IF(ISNA(IF(NOT(ISBLANK(A25)),ABS(H25-J25),"")),0,(IF(NOT(ISBLANK(A25)),ABS(H25-J25)*10000,""))) -> 0 | L25: =IF(Close[[#This Row],[CreatedBy]]="MARINER\SilverAdm",1,0) -> 1 | M25: =IF(NOT(ISBLANK(A25)),VLOOKUP(A25,'Close - PriceSaver'!A:J,6,0),"") -> DL Bill input Discount = 3.58945000 PX_ASK = 3.58070000 PX_BID = 3.59820000 | Q25: =VLOOKUP(P25,A:C,3,0) -> #N/A | R25: =VLOOKUP(P25,A:B,2,0) -> #N/A | S25: =VLOOKUP(P25,A:E,4,0) -> #N/A | T25: =VLOOKUP(P25,A:K,5,0) -> #N/A | U25: =VLOOKUP(P25,A:K,8,0) -> #N/A | V25: =VLOOKUP(P25,A:K,10,0) -> #N/A | W25: =(V25-U25)*100 -> #N/A | X25: =VLOOKUP(P25,Close[[ID]:[CreatedBy]],8,0) -> #N/A
... A653: 912834QV3 | B653: =IF(NOT(ISBLANK(A653)),VLOOKUP(A653,'BBT3'!A:F,2,0),"") -> Bond | C653: =IF(NOT(ISBLANK(A653)),VLOOKUP(A653,'BBT3'!A:F,3,0),"") -> US912834QV37 | D653: =IF(NOT(ISBLANK(A653)),VLOOKUP(A653,'BBT3'!A:F,4,1),"") -> 0 | E653: =IF(NOT(ISBLANK(A653)),VLOOKUP(A653,'BBT3'!A:F,5,0),"") -> 53646 | F653: =IF(NOT(ISBLANK(A653)),VLOOKUP(A653,'BBT3'!A:F,6,0),"") -> N | G653: =IF(NOT(ISBLANK(A653)),IF(D653=0,"Y","N"),"") -> Y | H653: =IF(NOT(ISBLANK(A653)),VLOOKUP(A653,'Close - PriceSaver'!A:J,5,0),"") -> 0.054084487 | I653: {=IF(NOT(ISBLANK(A653)),((_xlfn.XLOOKUP(1,(_bbt3[[#All],[ID]]=A653)*(_bbt3[[#All],[METRIC_NAME]]="YLD_YTM_ASK"),_bbt3[[#All],[METRIC_VALUE]])*0.5)+(_xlfn.XLOOKUP(1,(_bbt3[[#All],[ID]]=A653)*(_bbt3[[#All],[METRIC_NAME]]="YLD_YTM_BID"),_bbt3[[#All],[METRIC_VALUE]])*0.5))/100,"")} -> #N/A | J653: =IF(ISNA(VLOOKUP(A653,'CloseDL - PriceSaverBBT3'!A:E,5,0)),0,VLOOKUP(A653,'CloseDL - PriceSaverBBT3'!A:E,5,0)) -> 0.054084487 | K653: =IF(ISNA(IF(NOT(ISBLANK(A653)),ABS(H653-J653),"")),0,(IF(NOT(ISBLANK(A653)),ABS(H653-J653)*10000,""))) -> 0 | L653: =IF(Close[[#This Row],[CreatedBy]]="MARINER\SilverAdm",1,0) -> 1 | M653: =IF(NOT(ISBLANK(A653)),VLOOKUP(A653,'Close - PriceSaver'!A:J,6,0),"") -> DL input prc = 33.81910010 PX_ASK = 33.96961336 PX_BID = 33.66858684 | Q653: =VLOOKUP(P653,A:C,3,0) -> #N/A | R653: =VLOOKUP(P653,A:B,2,0) -> #N/A | S653: =VLOOKUP(P653,A:E,4,0) -> #N/A | T653: =VLOOKUP(P653,A:K,5,0) -> #N/A | U653: =VLOOKUP(P653,A:K,8,0) -> #N/A | V653: =VLOOKUP(P653,A:K,10,0) -> #N/A | W653: =(V653-U653)*100 -> #N/A | X653: =VLOOKUP(P653,Close[[ID]:[CreatedBy]],8,0) -> #N/A
B654: =IF(NOT(ISBLANK(A654)),VLOOKUP(A654,'BBT3'!A:F,2,0),"") | C654: =IF(NOT(ISBLANK(A654)),VLOOKUP(A654,'BBT3'!A:F,3,0),"") | D654: =IF(NOT(ISBLANK(A654)),VLOOKUP(A654,'BBT3'!A:F,4,1),"") | E654: =IF(NOT(ISBLANK(A654)),VLOOKUP(A654,'BBT3'!A:F,5,0),"") | F654: =IF(NOT(ISBLANK(A654)),VLOOKUP(A654,'BBT3'!A:F,6,0),"") | G654: =IF(NOT(ISBLANK(A654)),IF(D654=0,"Y","N"),"") | H654: =IF(NOT(ISBLANK(A654)),VLOOKUP(A654,'Close - PriceSaver'!A:J,5,0),"") | I654: {=IF(NOT(ISBLANK(A654)),((_xlfn.XLOOKUP(1,(_bbt3[[#All],[ID]]=A654)*(_bbt3[[#All],[METRIC_NAME]]="YLD_YTM_ASK"),_bbt3[[#All],[METRIC_VALUE]])*0.5)+(_xlfn.XLOOKUP(1,(_bbt3[[#All],[ID]]=A654)*(_bbt3[[#All],[METRIC_NAME]]="YLD_YTM_BID"),_bbt3[[#All],[METRIC_VALUE]])*0.5))/100,"")} | J654: =IF(ISNA(VLOOKUP(A654,'CloseDL - PriceSaverBBT3'!A:E,5,0)),0,VLOOKUP(A654,'CloseDL - PriceSaverBBT3'!A:E,5,0)) -> 0 | K654: =IF(ISNA(IF(NOT(ISBLANK(A654)),ABS(H654-J654),"")),0,(IF(NOT(ISBLANK(A654)),ABS(H654-J654)*10000,""))) | L654: =IF(Close[[#This Row],[CreatedBy]]="MARINER\SilverAdm",1,0) -> 1 | M654: =IF(NOT(ISBLANK(A654)),VLOOKUP(A654,'Close - PriceSaver'!A:J,6,0),"") | Q654: =VLOOKUP(P654,A:C,3,0) -> #N/A | R654: =VLOOKUP(P654,A:B,2,0) -> #N/A | S654: =VLOOKUP(P654,A:E,4,0) -> #N/A | T654: =VLOOKUP(P654,A:K,5,0) -> #N/A | U654: =VLOOKUP(P654,A:K,8,0) -> #N/A | V654: =VLOOKUP(P654,A:K,10,0) -> #N/A | W654: =(V654-U654)*100 -> #N/A | X654: =VLOOKUP(P654,Close[[ID]:[CreatedBy]],8,0) -> #N/A
