Workbook

Sheet Summary
A2: Date | B2: Coupon | C2: WAC | D2: WAM | E2: WALA | F2: 1M CPR | H2: 3M CPR | I2: 6M CPR | J2: 12M CPR | K2: Amt Issued (M) | L2: Balance (M) | M2: # Pools
A3: 02/2026 | B3: 6.5
A4: 01/2026 | B4: 6.5 | C4: 7.297 | D4: 349 | E4: 7 | F4: 36.25 | G4: =100*(1-(1-Collateral!N2/L4)^12) -> 37.360185 | H4: 36.62 | I4: 29.74 | J4: 21.55 | K4: 18085314 | L4: 14985463 | M4: 663
A5: 12/2025 | B5: 6.5 | C5: 7.296 | D5: 350 | E5: 6 | F5: 31.79 | G5: =100*(1-(1-Collateral!N3/L5)^12) -> 32.64643 | H5: 33.87 | I5: 26.56 | K5: 17523423 | L5: 15008633 | M5: 630
A6: 11/2025 | B6: 6.5 | C6: 7.293 | D6: 351 | E6: 5 | F6: 41.48 | G6: =100*(1-(1-Collateral!N4/L6)^12) -> 42.931536 | H6: 30.46 | I6: 24.06 | K6: 16879462 | L6: 14862275 | M6: 589
A7: 10/2025 | B7: 6.5 | C7: 7.291 | D7: 352 | E7: 4 | F7: 27.26 | G7: =100*(1-(1-Collateral!N5/L7)^12) -> 27.892917 | H7: 21.93 | I7: 20.11 | K7: 16006212 | L7: 14682080 | M7: 531
A8: 09/2025 | B8: 6.5 | C8: 7.284 | D8: 352 | E8: 4 | F8: 20.47 | G8: =100*(1-(1-Collateral!N6/L8)^12) -> 20.827058 | H8: 18.36 | I8: 17.59 | K8: 14265919 | L8: 13348259 | M8: 462
A9: 08/2025 | B9: 6.5 | C9: 7.28 | D9: 353 | E9: 3 | F9: 17.72 | G9: =100*(1-(1-Collateral!N7/L9)^12) -> 17.989127 | H9: 17.07 | I9: 15.27 | K9: 12597246 | L9: 11947862 | M9: 396
A10: 07/2025 | B10: 6.5 | C10: 7.282 | D10: 354 | E10: 3 | F10: 16.79 | G10: =100*(1-(1-Collateral!N8/L10)^12) -> 17.023529 | H10: 18.23 | I10: 12.38 | K10: 10706609 | L10: 10261362 | M10: 332
A11: 06/2025 | B11: 6.5 | C11: 7.289 | D11: 354 | E11: 2 | F11: 16.63 | G11: =100*(1-(1-Collateral!N9/L11)^12) -> 16.859809 | H11: 16.8 | K11: 7933717 | L11: 7655155 | M11: 241
A12: 05/2025 | B12: 6.5 | C12: 7.4 | D12: 346 | E12: 9 | F12: 30.94 | G12: =100*(1-(1-Collateral!N10/L12)^12) -> 31.748029 | H12: 22.98 | I12: 20.61 | J12: 18.53 | K12: 17744028 | L12: 14918285 | M12: 1024
A13: 04/2025 | B13: 6.5 | C13: 7.402 | D13: 347 | E13: 8 | F13: 23.62 | G13: =100*(1-(1-Collateral!N11/L13)^12) -> 24.091226 | H13: 17.72 | I13: 19.87 | J13: 16.88 | K13: 17915189 | L13: 15532481 | M13: 1025
A14: 03/2025 | B14: 6.5 | C14: 7.403 | D14: 348 | E14: 7 | F14: 13.53 | G14: =100*(1-(1-Collateral!N12/L14)^12) -> 13.684331 | H14: 15.94 | I14: 18.84 | J14: 15.88 | K14: 17992546 | L14: 15964732 | M14: 1017
A15: 02/2025 | B15: 6.5 | C15: 7.411 | D15: 349 | E15: 7 | F15: 15.92 | G15: =100*(1-(1-Collateral!N13/L15)^12) -> 16.136578 | H15: 18.43 | I15: 19.02 | J15: 15.11 | K15: 22458321 | L15: 20161842 | M15: 960
A16: 01/2025 | B16: 6.5 | C16: 7.431 | D16: 350 | E16: 6 | F16: 18.95 | G16: =100*(1-(1-Collateral!N14/L16)^12) -> 19.257386 | H16: 21.68 | I16: 18.39 | K16: 24365243 | L16: 22066943 | M16: 832
A17: 12/2024 | B17: 6.5 | C17: 7.436 | D17: 351 | E17: 5 | F17: 19.75 | G17: =100*(1-(1-Collateral!N15/L17)^12) -> 20.081365 | H17: 21.32 | I17: 17.05 | K17: 24032419 | L17: 22015375 | M17: 763
A18: 11/2024 | B18: 6.5 | C18: 7.44 | D18: 352 | E18: 5 | F18: 27.76 | G18: =100*(1-(1-Collateral!N16/L18)^12) -> 28.411207 | H18: 20.35 | I18: 16.65 | K18: 25338865 | L18: 23503177 | M18: 705
A19: 10/2024 | B19: 6.5 | C19: 7.441 | D19: 353 | E19: 4 | F19: 17.71 | G19: =100*(1-(1-Collateral!N17/L19)^12) -> 17.979473 | H19: 15.5 | I19: 14.2 | K19: 25506579 | L19: 24271618 | M19: 648
A20: 09/2024 | B20: 6.5 | C20: 7.44 | D20: 354 | E20: 3 | F20: 15.06 | G20: =100*(1-(1-Collateral!N18/L20)^12) -> 15.253079 | H20: 13.12 | I20: 13.21 | K20: 23172648 | L20: 22348664 | M20: 550
A21: 08/2024 | B21: 6.5 | C21: 7.44 | D21: 355 | E21: 2 | F21: 13.74 | G21: =100*(1-(1-Collateral!N19/L21)^12) -> 13.896888 | H21: 12.97 | I21: 12.2 | K21: 18877621 | L21: 18361098 | M21: 430
A22: 07/2024 | B22: 6.5 | C22: 7.439 | D22: 356 | E22: 2 | F22: 10.47 | G22: =100*(1-(1-Collateral!N20/L22)^12) -> 10.566451 | H22: 12.92 | K22: 13556227 | L22: 13265215 | M22: 313
A23: 06/2024 | B23: 6.5 | C23: 7.443 | D23: 356 | E23: 2 | F23: 14.19 | G23: =100*(1-(1-Collateral!N21/L23)^12) -> 14.359612 | H23: 13.07 | K23: 6858487 | L23: 6696383 | M23: 193
A24: 05/2024 | B24: 6.5 | C24: 7.404 | D24: 349 | E24: 6 | F24: 14.35 | G24: =100*(1-(1-Collateral!N22/L24)^12) -> 14.52058 | H24: 14.21 | I24: 12.72 | J24: 12.8 | K24: 46459694 | L24: 43041409 | M24: 1203
A25: 04/2024 | B25: 6.5 | C25: 7.401 | D25: 351 | E25: 6 | F25: 13.42 | G25: =100*(1-(1-Collateral!N23/L25)^12) -> 13.568804 | H25: 14.13 | I25: 12.08 | J25: 12.51 | K25: 49119988 | L25: 46068484 | M25: 1201
A26: 03/2024 | B26: 6.5 | C26: 7.4 | D26: 352 | E26: 5 | F26: 14.73 | G26: =100*(1-(1-Collateral!N24/L26)^12) -> 14.909064 | H26: 12.87 | I26: 11.7 | J26: 11.85 | K26: 49442171 | L26: 46927440 | M26: 1177
A27: 02/2024 | B27: 6.5 | C27: 7.392 | D27: 353 | E27: 4 | F27: 13.97 | G27: =100*(1-(1-Collateral!N25/L27)^12) -> 14.139204 | H27: 11.14 | I27: 11.28 | J27: 10.86 | K27: 50293509 | L27: 48174550 | M27: 1094
A28: 01/2024 | B28: 6.5 | C28: 7.383 | D28: 354 | E28: 3 | F28: 9.69 | G28: =100*(1-(1-Collateral!N26/L28)^12) -> 9.7706377 | H28: 10.08 | I28: 10.73 | J28: 11.65 | K28: 43998684 | L28: 42492385 | M28: 944
A29: 12/2023 | B29: 6.5 | C29: 7.363 | D29: 354 | E29: 3 | F29: 9.7 | G29: =100*(1-(1-Collateral!N27/L29)^12) -> 9.7769134 | H29: 10.69 | I29: 12.13 | K29: 35037819 | L29: 33921640 | M29: 771
A30: 11/2023 | B30: 6.5 | C30: 7.34 | D30: 354 | E30: 3 | F30: 10.85 | G30: =100*(1-(1-Collateral!N28/L30)^12) -> 10.945658 | H30: 11.47 | I30: 13.52 | K30: 25345189 | L30: 24542910 | M30: 591
A31: 10/2023 | B31: 6.5 | C31: 7.335 | D31: 355 | E31: 3 | F31: 11.51 | G31: =100*(1-(1-Collateral!N29/L31)^12) -> 11.617088 | H31: 11.37 | I31: 14.07 | K31: 19045535 | L31: 18470353 | M31: 453
A32: 09/2023 | B32: 6.5 | C32: 7.324 | D32: 355 | E32: 2 | F32: 12.07 | G32: =100*(1-(1-Collateral!N30/L32)^12) -> 12.197374 | H32: 13.28 | I32: 13.13 | K32: 16403344 | L32: 15936675 | M32: 341
A33: 08/2023 | B33: 6.5 | C33: 7.372 | D33: 348 | E33: 8 | F33: 13.69 | G33: =100*(1-(1-Collateral!N31/L33)^12) -> 13.84408 | H33: 16.31 | I33: 16.39 | J33: 14.82 | K33: 6399443 | L33: 5746932 | M33: 175
A34: 07/2023 | B34: 6.5 | C34: 7.354 | D34: 350 | E34: 7 | F34: 16.16 | G34: =100*(1-(1-Collateral!N32/L34)^12) -> 16.379313 | H34: 16.71 | I34: 15.93 | J34: 13.79 | K34: 6725493 | L34: 6121093 | M34: 174
A35: 06/2023 | B35: 6.5 | C35: 7.352 | D35: 351 | E35: 6 | F35: 18.7 | G35: =100*(1-(1-Collateral!N33/L35)^12) -> 18.995835 | H35: 17.32 | I35: 14.39 | J35: 12.53 | K35: 6770681 | L35: 6258549 | M35: 175
A36: 05/2023 | B36: 6.5 | C36: 7.349 | D36: 352 | E36: 5 | F36: 15.21 | G36: =100*(1-(1-Collateral!N34/L36)^12) -> 15.406044 | H36: 16.25 | I36: 12.35 | K36: 6799043 | L36: 6394407 | M36: 174
A37: 04/2023 | B37: 6.5 | C37: 7.345 | D37: 353 | E37: 4 | F37: 17.91 | G37: =100*(1-(1-Collateral!N35/L37)^12) -> 18.184869 | H37: 15 | I37: 9.82 | K37: 6984363 | L37: 6663645 | M37: 169
A38: 03/2023 | B38: 6.5 | C38: 7.316 | D38: 355 | E38: 3 | F38: 15.2 | G38: =100*(1-(1-Collateral!N36/L38)^12) -> 15.393788 | H38: 11.35 | I38: 12.83 | K38: 7887017 | L38: 7648245 | M38: 159
A39: 02/2023 | B39: 6.5 | C39: 7.292 | D39: 356 | E39: 2 | F39: 10.95 | G39: =100*(1-(1-Collateral!N37/L39)^12) -> 11.050768 | H39: 8.39 | I39: 9.53 | K39: 7968947 | L39: 7821041 | M39: 129
A40: 01/2023 | B40: 6.5 | C40: 7.241 | D40: 357 | E40: 2 | F40: 8.74 | G40: =100*(1-(1-Collateral!N38/L40)^12) -> 8.8071807 | H40: 4.88 | I40: 7.96 | K40: 6387771 | L40: 6315626 | M40: 90
A41: 12/2022 | B41: 6.5 | C41: 7.074 | D41: 358 | E41: 1 | F41: 5.63 | G41: =100*(1-(1-Collateral!N39/L41)^12) -> 5.6616376 | H41: 12.44 | I41: 6.56 | K41: 3215016 | L41: 3196232 | M41: 39
...

Sheet Paydown
A1: Date | B1: Factor | C1: Recomputation Factor | D1: Coupon | E1: Pass-through Rate | F1: Principal | H1: Interest | I1: Interest Recomputation | J1: Balance | K1: Balance Recomputation | L1: Cashflow | M1: Cashflow Recomputation
A2: Total | F2: 81221269097 | H2: 19755172597 | J2: =SUM(J4:J268) -> 3.5659182e+12 | L2: 100976441694 | M2: =SUM(M4:M268) -> 1.0097644e+11
A3: 02/25/2026 | D3: 6.5
A4: 01/26/2026 | B4: 0.82859842 | C4: =Summary!L4/Summary!K4 -> 0.82859844 | D4: 6.5 | F4: 5.8581814e+08 | G4: =Collateral!K2 -> 585818 | H4: 84344439 | I4: =Collateral!O2 -> 84344 | J4: 1.4985463e+10 | K4: =Collateral!I2*1000 -> 14985463000 | L4: 6.7016258e+08 | M4: =H4+F4 -> 6.7016258e+08
A5: 12/26/2025 | B5: 0.85648975 | C5: =Summary!L5/Summary!K5 -> 0.8564898 | D5: 6.5 | F5: 4.9904399e+08 | G5: =Collateral!K3 -> 499044 | H5: 83999915 | I5: =Collateral!O3 -> 84000 | J5: 1.5008633e+10 | K5: =Collateral!I3*1000 -> 15008633000 | L5: 5.8304391e+08 | M5: =H5+F5 -> 5.8304391e+08
A6: 11/25/2025 | B6: 0.88049461 | C6: =Summary!L6/Summary!K6 -> 0.88049459 | D6: 6.5 | F6: 6.9145327e+08 | G6: =Collateral!K4 -> 691453 | H6: 84249361 | I6: =Collateral!O4 -> 84249 | J6: 1.4862275e+10 | K6: =Collateral!I4*1000 -> 14862275000 | L6: 7.7570263e+08 | M6: =H6+F6 -> 7.7570263e+08
A7: 10/27/2025 | B7: 0.91727386 | C7: =Summary!L7/Summary!K7 -> 0.91727387 | D7: 6.5 | F7: 4.0698124e+08 | G7: =Collateral!K5 -> 406981 | H7: 81732413 | I7: =Collateral!O5 -> 81732 | J7: 1.468208e+10 | K7: =Collateral!I5*1000 -> 14682080000 | L7: 4.8871365e+08 | M7: =H7+F7 -> 4.8871365e+08
A8: 09/25/2025 | B8: 0.93567468 | C8: =Summary!L8/Summary!K8 -> 0.93567467 | D8: 6.5 | F8: 2.6827594e+08 | G8: =Collateral!K6 -> 268276 | H8: 73756232 | I8: =Collateral!O6 -> 73756 | J8: 1.3348259e+10 | K8: =Collateral!I6*1000 -> 13348259000 | L8: 3.4203217e+08 | M8: =H8+F8 -> 3.4203217e+08
A9: 08/25/2025 | B9: 0.94845033 | C9: =Summary!L9/Summary!K9 -> 0.94845032 | D9: 6.5 | F9: 2.0561826e+08 | G9: =Collateral!K7 -> 205618 | H9: 65831353 | I9: =Collateral!O7 -> 65831 | J9: 1.1947862e+10 | K9: =Collateral!I7*1000 -> 11947862000 | L9: 2.7144961e+08 | M9: =H9+F9 -> 2.7144961e+08
A10: 07/25/2025 | B10: 0.95841388 | C10: =Summary!L10/Summary!K10 -> 0.95841382 | D10: 6.5 | F10: 1.6668558e+08 | G10: =Collateral!K8 -> 166686 | H10: 56485260 | I10: =Collateral!O8 -> 56485 | J10: 1.0261362e+10 | K10: =Collateral!I8*1000 -> 10261362000 | L10: 2.2317084e+08 | M10: =H10+F10 -> 2.2317084e+08
A11: 06/25/2025 | B11: 0.96488887 | C11: =Summary!L11/Summary!K11 -> 0.96488884 | D11: 6.5 | F11: 1.2306879e+08 | G11: =Collateral!K9 -> 123069 | H11: 42132045 | I11: =Collateral!O9 -> 42132 | J11: 7.6551549e+09 | K11: =Collateral!I9*1000 -> 7655155000 | L11: 1.6520083e+08 | M11: =H11+F11 -> 1.6520083e+08
A12: 05/27/2025 | B12: 0.84074966 | C12: =Summary!L12/Summary!K12 -> 0.84074963 | D12: 6.5 | F12: 4.8012528e+08 | G12: =Collateral!K10 -> 480125 | H12: 83405173 | I12: =Collateral!O10 -> 83405 | J12: 1.4918285e+10 | K12: =Collateral!I10*1000 -> 14918285000 | L12: 5.6353045e+08 | M12: =H12+F12 -> 5.6353045e+08
A13: 04/25/2025 | B13: 0.86700069 | C13: =Summary!L13/Summary!K13 -> 0.86700068 | D13: 6.5 | F13: 3.6576314e+08 | G13: =Collateral!K11 -> 365763 | H13: 86112601 | I13: =Collateral!O11 -> 86113 | J13: 1.5532481e+10 | K13: =Collateral!I11*1000 -> 15532481000 | L13: 4.5187574e+08 | M13: =H13+F13 -> 4.5187574e+08
A14: 03/25/2025 | B14: 0.88729695 | C14: =Summary!L14/Summary!K14 -> 0.887297 | D14: 6.5 | F14: 2.0774956e+08 | G14: =Collateral!K12 -> 207750 | H14: 87598049 | I14: =Collateral!O12 -> 87598 | J14: 1.5964732e+10 | K14: =Collateral!I12*1000 -> 15964732000 | L14: 2.9534761e+08 | M14: =H14+F14 -> 2.9534761e+08
A15: 02/25/2025 | B15: 0.89774486 | C15: =Summary!L15/Summary!K15 -> 0.89774485 | D15: 6.5 | F15: 3.1001422e+08 | G15: =Collateral!K13 -> 310014 | H15: 1.1088723e+08 | I15: =Collateral!O13 -> 110887 | J15: 2.0161842e+10 | K15: =Collateral!I13*1000 -> 20161842000 | L15: 4.2090146e+08 | M15: =H15+F15 -> 4.2090146e+08
... A267: 02/25/2004 | B267: 0.20699081 | C267: =Summary!L267/Summary!K267 -> 0.20699081 | D267: 6.5 | F267: 1.6210559e+09 | G267: =Collateral!K265 -> 1621056 | H267: 2.2443122e+08 | I267: =Collateral!O265 -> 224431 | J267: 3.9812478e+10 | K267: =Collateral!I265*1000 -> 39812478000 | L267: 1.8454871e+09 | M267: =H267+F267 -> 1.8454871e+09
A268: 01/26/2004 | B268: 0.2154371 | C268: =Summary!L268/Summary!K268 -> 0.2154371 | F268: 2.2178453e+09 | G268: =Collateral!K266 -> 2217846 | H268: 2.3660909e+08 | I268: =Collateral!O266 -> 236609 | J268: 4.1463914e+10 | K268: =Collateral!I266*1000 -> 41463914000 | L268: 2.4544544e+09 | M268: =H268+F268 -> 2.4544544e+09

Sheet Collateral
A1: Date | B1: TBA W2D Mapping | C1: # Pools | D1: WAC | E1: WAM+ | F1: WAM | G1: WALA | H1: Amt Issued (M) | I1: Balance (M) | J1: Total (M) | K1: Recomputation Total (M) | L1: Sched (M) | M1: Recomputation Sched (M) | N1: Unsched (M) | O1: Net Interest (M) | P1: Recomputation Net Interest (M)
A2: 01/2026 | B2: FNCL 6.5 2025 W2D FLOAT | C2: 663 | D2: 7.297 | E2: =F2+G2 -> 356 | F2: 349 | G2: 7 | H2: 18085314 | I2: 14985463 | J2: 585818 | K2: =L2+N2 -> 585818 | L2: 12912 | M2: =(D2/100/12)/((1+D2/100/12)^F2-1)*I2 -> 12489.441 | N2: 572906 | O2: 84344 | P2: =D2/100/12*I2 -> 91124.103
A3: 12/2025 | B3: FNCL 6.5 2025 W2D FLOAT | C3: 630 | D3: 7.296 | E3: =F3+G3 -> 356 | F3: 350 | G3: 6 | H3: 17523423 | I3: 15008633 | J3: 499044 | K3: =L3+N3 -> 499044 | L3: 12793 | M3: =(D3/100/12)/((1+D3/100/12)^F3-1)*I3 -> 12425.246 | N3: 486251 | O3: 84000 | P3: =D3/100/12*I3 -> 91252.489
A4: 11/2025 | B4: FNCL 6.5 2025 W2D FLOAT | C4: 589 | D4: 7.293 | E4: =F4+G4 -> 356 | F4: 351 | G4: 5 | H4: 16879462 | I4: 14862275 | J4: 691453 | K4: =L4+N4 -> 691453 | L4: 12729 | M4: =(D4/100/12)/((1+D4/100/12)^F4-1)*I4 -> 12226.745 | N4: 678724 | O4: 84249 | P4: =D4/100/12*I4 -> 90325.476
A5: 10/2025 | B5: FNCL 6.5 2025 W2D FLOAT | C5: 531 | D5: 7.291 | E5: =F5+G5 -> 356 | F5: 352 | G5: 4 | H5: 16006212 | I5: 14682080 | J5: 406981 | K5: =L5+N5 -> 406981 | L5: 12275 | M5: =(D5/100/12)/((1+D5/100/12)^F5-1)*I5 -> 12000.378 | N5: 394706 | O5: 81732 | P5: =D5/100/12*I5 -> 89205.871
A6: 09/2025 | B6: FNCL 6.5 2025 W2D FLOAT | C6: 462 | D6: 7.284 | E6: =F6+G6 -> 356 | F6: 352 | G6: 4 | H6: 14265919 | I6: 13348259 | J6: 268276 | K6: =L6+N6 -> 268276 | L6: 11013 | M6: =(D6/100/12)/((1+D6/100/12)^F6-1)*I6 -> 10924.977 | N6: 257263 | O6: 73756 | P6: =D6/100/12*I6 -> 81023.932
A7: 08/2025 | B7: FNCL 6.5 2025 W2D FLOAT | C7: 396 | D7: 7.28 | E7: =F7+G7 -> 356 | F7: 353 | G7: 3 | H7: 12597246 | I7: 11947862 | J7: 205618 | K7: =L7+N7 -> 205618 | L7: 9784 | M7: =(D7/100/12)/((1+D7/100/12)^F7-1)*I7 -> 9719.4615 | N7: 195834 | O7: 65831 | P7: =D7/100/12*I7 -> 72483.696
A8: 07/2025 | B8: FNCL 6.5 2025 W2D FLOAT | C8: 332 | D8: 7.282 | E8: =F8+G8 -> 357 | F8: 354 | G8: 3 | H8: 10706609 | I8: 10261362 | J8: 166686 | K8: =L8+N8 -> 166686 | L8: 8345 | M8: =(D8/100/12)/((1+D8/100/12)^F8-1)*I8 -> 8287.2403 | N8: 158341 | O8: 56485 | P8: =D8/100/12*I8 -> 62269.365
A9: 06/2025 | B9: FNCL 6.5 2025 W2D FLOAT | C9: 241 | D9: 7.289 | E9: =F9+G9 -> 356 | F9: 354 | G9: 2 | H9: 7933717 | I9: 7655155 | J9: 123069 | K9: =L9+N9 -> 123069 | L9: 6182 | M9: =(D9/100/12)/((1+D9/100/12)^F9-1)*I9 -> 6173.9952 | N9: 116887 | O9: 42132 | P9: =D9/100/12*I9 -> 46498.687
A10: 05/2025 | B10: FNCL 6.5 2024 W2D FLOAT | C10: 1024 | D10: 7.4 | E10: =F10+G10 -> 355 | F10: 346 | G10: 9 | H10: 17744028 | I10: 14918285 | J10: 480125 | K10: =L10+N10 -> 480125 | L10: 12749 | M10: =(D10/100/12)/((1+D10/100/12)^F10-1)*I10 -> 12447.677 | N10: 467376 | O10: 83405 | P10: =D10/100/12*I10 -> 91996.091
A11: 04/2025 | B11: FNCL 6.5 2024 W2D FLOAT | C11: 1025 | D11: 7.402 | E11: =F11+G11 -> 355 | F11: 347 | G11: 8 | H11: 17915189 | I11: 15532481 | J11: 365763 | K11: =L11+N11 -> 365763 | L11: 13051 | M11: =(D11/100/12)/((1+D11/100/12)^F11-1)*I11 -> 12865.14 | N11: 352712 | O11: 86113 | P11: =D11/100/12*I11 -> 95809.52
A12: 03/2025 | B12: FNCL 6.5 2024 W2D FLOAT | C12: 1017 | D12: 7.403 | E12: =F12+G12 -> 355 | F12: 348 | G12: 7 | H12: 17992546 | I12: 15964732 | J12: 207750 | K12: =L12+N12 -> 207750 | L12: 13166 | M12: =(D12/100/12)/((1+D12/100/12)^F12-1)*I12 -> 13128.773 | N12: 194584 | O12: 87598 | P12: =D12/100/12*I12 -> 98489.092
A13: 02/2025 | B13: FNCL 6.5 2024 W2D FLOAT | C13: 960 | D13: 7.411 | E13: =F13+G13 -> 356 | F13: 349 | G13: 7 | H13: 22458321 | I13: 20161842 | J13: 310014 | K13: =L13+N13 -> 310014 | L13: 16497 | M13: =(D13/100/12)/((1+D13/100/12)^F13-1)*I13 -> 16439.891 | N13: 293517 | O13: 110887 | P13: =D13/100/12*I13 -> 124516.18
... A266: 01/2004 | B266: FNCL 6.5 2001 W2D | C266: 10326 | D266: 7.012 | E266: =F266+G266 -> 354 | F266: 325 | G266: 29 | H266: 192464133 | I266: 41463914 | J266: 2217845 | K266: =L266+N266 -> 2217846 | L266: 44865 | M266: =(D266/100/12)/((1+D266/100/12)^F266-1)*I266 -> 42936.302 | N266: 2172981 | O266: 236609 | P266: =D266/100/12*I266 -> 242287.47

Sheet Sheet3
M17: =1083350*0.065/12 -> 5868.1458
F18: 1082558 | G18: =F19-F18 -> 792.04
F19: 1083350
