Workbook

Sheet Sheet2
A1: Row Labels | B1: Count of Name
A2: [QW.Framework.DBTable] | B2: 34
A3: [QW.Security.VolCube] | B3: 31
A4: [QW.Framework.CalendarQLNet] | B4: 25
A5: [QW.Data.LoaderDataProv] | B5: 21
A6: [QW.Security.SecurityFetcher] | B6: 20
A7: [Spring.Objects.Factory.Config.PropertyRetrievingFactoryObject] | B7: 15
A8: [QW.Framework.Spring.FactoryObjectCheckFile] | B8: 14
A9: [QW.Framework.DBTableTS] | B9: 14
A10: [QW.Framework.Date.CalendarList] | B10: 14
A11: [QW.Security.Curve.CurveFitByModel] | B11: 12
A12: [QW.Framework.DBConnSql] | B12: 12
A13: [QW.Framework.Spring.AddSuffixFactoryObject] | B13: 10
... A226: Grand Total | B226: 600
B1048576: =SUM(B2:B1048575) -> 1200

Sheet Bloomberg

Sheet QWSecurity Spring Object
A1: Nblignes | B1: Name | C1: Value | D1: Types | E1: BBM
A2: M | B2: ["MarketServerContractFactory"] | C2: [QW.MarketModelWCF.MarketServerContractFactory] | D2: Deamon
A3: M | B3: ["tblMacInfo"] | C3: [QW.Framework.DBTable] | D3: DBTable
A4: M | B4: ["QWPriceServerSubListener"] | C4: [QW.Framework.ActiveMQ.Subscriber] | D4: Other
A5: M | B5: ["CubicFlatEnds"] | C5: [QW.Analytics.Functions.InterpolatorQLNetCubicFlatEnds] | D5: Math
A6: M | B6: ["tblSecMstRequestDev"] | C6: [QW.Framework.DBTable] | D6: DBTable
A7: M | B7: ["tblStratList"] | C7: [QW.Framework.DBTable] | D7: DBTable
A8: M | B8: ["tblFR"] | C8: [QW.Framework.DBTableTS] | D8: DBTable
A9: M | B9: ["QWPriceServerPubWriter"] | C9: [QW.Framework.ActiveMQ.Publisher] | D9: Other
A10: M | B10: ["Street"] | C10: [QW.Security.Rate.RateTypeCompounded] | D10: RateTypeConvention
A11: m | B11: ["CalKR"] | C11: [QW.Framework.CalendarQLNet] | D11: Calendar
A12: M | B12: ["CalNO"] | C12: [QW.Framework.CalendarQLNet] | D12: Calendar
A13: M | B13: ["CurveCalibratedConvexity"] | C13: [QW.Security.Curve.CalibratedConvexityCurve] | D13: Curve
A14: m | B14: ["MarketContext"] | C14: [QW.Security.MarketContext] | D14: Context
A15: =10820-8828 -> 1992 | B15: ["CurveLoadersWrapper"] | C15: [QW.Framework.Placeholder] | D15: Curve | E15: BPSWSA,BPSWSB,BPSWSC,BPSWSD,BPSWSE,BPSWSF,BPSWSG,BPSWSH,BPSWSI,BPSWSJ,BPSWSK,EUSWEA,EUSWEB,EUSWEC,OISEF,CDSOA,CDSOB,CDSOC,CDSOD,CDSOE,CDSOF,CDSOG,CDSOH,CDSOI,CDSOJ,CDSOK,EESWEA,EESWEB,EESWEC,EESWED,EESWEE,EESWEF,EESWEG,EESWEH,EESWEI,EESWEJ,EESWEK,VIX,UX1,UX2,UX3,UX4,UX5,UX6,UX7,V2X,FVS1,FVS2,FVS3,BP0001M,BP0002M,BP0003M,EUR001M,EUR002M,EUR003M,EUSF1A,EUSF2A,EUSF3A,EUSF4A,EUSF5A,EUSF6A,EUSF7A,EUSF8A,EUSF9A,NDSF1A,NDSF2A,NDSF3A,NDSF4A,NDSF5A,NDSF6A,ADSF1A,ADSF2A,ADSF3A,ADSF4A,ADSF5A,ADSF6A,ADSF7A,EUSWEA,EUSWEB,EUSWEC
A16: =14280-13069 -> 1211 | B16: ["MarketCoordinator"] | C16: [QW.Security.MarketCoordinator] | D16: Context
A17: =4254-3429 -> 825 | B17: ["RateLoader"] | C17: [QW.Security.Rate.Loader] | D17: InstrumentLoader
A18: =6191-5427 -> 764 | B18: ["SecurityProvider"] | C18: [QW.Security.SecurityProvider] | D18: Loader
A19: =1297-712 -> 585 | B19: ["CommodityFutureLoader"] | C19: [QW.Security.Dummy.Loader] | D19: InstrumentLoader
A20: =1993-1659 -> 334 | B20: ["IndexFutureLoader"] | C20: [QW.Security.Dummy.Loader] | D20: InstrumentLoader
A21: =4891-4565 -> 326 | B21: ["RateFutureLoader"] | C21: [QW.Security.RateFuture.Loader] | D21: InstrumentLoader
A22: =2303-2047 -> 256 | B22: ["SwapIndexPropertyMap"] | C22: [QW.Framework.RegexDictionaryGeneric<IDict_str_obj>, QWFramework] | D22: InstrumentStaticData | E22: FEDL12M,FEDL01,SOFRRATE,MUTKCALM,ESTRON,ESTRON12M,EONIA,EONIA12M,CAONREPO,OISCAD12M,SONI,US0001M,US0003M,USA0003M,USQ0003M,EUR006M,BP0006M,BP0003M,EUR003M,ADBB3M,ADBB6M,NIBOR6M,SF0006M,STIB3M,CDOR03,NZOCRS,NDBB3M,KWCDC,TOISTOIS,JY0003M,JY0006M,RBACOR,HIHD03M
A23: =1582-1343 -> 239 | B23: ["CurrencyFutureLoader"] | C23: [QW.Security.Dummy.Loader] | D23: InstrumentLoader
A24: =2539-2303 -> 236 | B24: ["SwapPropertyMap"] | C24: [QW.Framework.RegexDictionaryGeneric<IDict_str_obj>, QWFramework] | D24: InstrumentStaticData | E24: USSWIM[0-9]+S$,EUSW[0-9]+V3$,BPSA[0-9]+V3$,USSO,USOSFR,JYSO,USSN,USSV,CDSO,EUSWE,EESWE,SFSWT,SFSW,BPSWS,USSW[0-9]+V1,USSQA,USSA,US,EU,BPBN,BP,SAFD,ANFD,QWUS,QWBP,QWEU,ADSWAP[0-9],ADSW[0-9]+Q,ADSV,SKSW[0-9],NKSW[0-9],CDSW,NDSWAP,NDSO,NDSV,NDSP,KWS,JYSW,JYSV,ADSO,HDSW"
A25: =6763-6588 -> 175 | B25: ["EnfusionSwapSecurityFetcher"] | C25: [QW.Security.SecurityFetcher] | D25: Fetcher
A26: =3245-3077 -> 168 | B26: ["BondLoader"] | C26: [QW.Security.Bond.Loader] | D26: InstrumentLoader
A27: =7060-6907 -> 153 | B27: ["EnfusionSwaptionSecurityFetcher"] | C27: [QW.Security.SecurityFetcher] | D27: Fetcher
A28: =7211-7060 -> 151 | B28: ["EnfusionSwaptionTradeFetcher"] | C28: [QW.Security.SecurityFetcher] | D28: Fetcher
A29: =7504-7356 -> 148 | B29: ["EnfusionSwaptionSecurityUnderlyingFetcher"] | C29: [QW.Security.SecurityFetcher] | D29: Fetcher
A30: =7356-7211 -> 145 | B30: ["EnfusionSwaptionTradeUnderlyingFetcher"] | C30: [QW.Security.SecurityFetcher] | D30: Fetcher
A31: =698-563 -> 135 | B31: ["CommodityRollingForwardLoader"] | C31: [QW.Security.Dummy.Loader] | D31: InstrumentLoader | E31: LMAH,LMAA,LMNA,LMCA,LMPB,LMNI,LMSN,LMZS,LMFM
A32: =6588-6457 -> 131 | B32: ["EnfusionSwapTradeFetcher"] | C32: [QW.Security.SecurityFetcher] | D32: Fetcher
A33: =5404-5282 -> 122 | B33: ["AlphaIndexLoader"] | C33: [QW.Security.Loader] | D33: InstrumentLoader | E33: CB CIXBCAD1,BABXDOT1,BACXCTNB,CIEQDUV5,CIFXTODH,CIIRVUT2,CICXSKBE,BACVCT1X,MLCVBB1X,MLFICOTF
A34: =3066-2964 -> 102 | B34: ["BillLoader"] | C34: [QW.Security.Bill.Loader] | D34: InstrumentLoader
A35: =3367-3266 -> 101 | B35: ["BondFutureLoader"] | C35: [QW.Security.BondFuture.Loader] | D35: InstrumentLoader
A36: =12300-12203 -> 97 | B36: ["CloseSubMap"] | C36: [QW.Framework.RegexDictionaryGeneric<IDict_str_str>, QWFramework] | D36: RegexMap
A37: =6457-6360 -> 97 | B37: ["TRSwapTradeFetcher"] | C37: [QW.Security.SecurityFetcher] | D37: Fetcher
A38: =6359-6268 -> 91 | B38: ["SwapTradeFetcher"] | C38: [QW.Security.SecurityFetcher] | D38: Fetcher
A39: =6825-6736 -> 89 | B39: ["CapFloorTradeFetcher"] | C39: [QW.Security.SecurityFetcher] | D39: Fetcher
A40: =5279-5194 -> 85 | B40: ["DummyLoader"] | C40: [QW.Security.Dummy.Loader] | D40: InstrumentLoader
...

Sheet Loader
A1: Benchmarks | B1: newCurve | C1: Loader
A2: (^GC.GE|^GC.FR|^GC.IT|^GC.BE|^GC.IR|^GC.EUR) | B2: Curve | C2: LoaderBMS
A3: (EN|GE|CA|IT|FR|JN)ZS | B3: CurveZS | C3: QW.Security.Curve.CurveLoaderDB
A4: (EU)MLESF9 | B4: CurveMLES_F_9 | C4: QW.Security.Curve.CurveLoaderDB
A5: (GE|CA|FR|JN|SP|NE|BE|EN)MLESF9 | B5: CurveMLES_F_9 | C5: QW.Security.Curve.CurveLoaderDB
A6: (GE|CA|FR|JN|SP|NE|BE|EN)MLESFL | B6: CurveMLES_F_L | C6: QW.Security.Curve.CurveLoaderDB
A7: (GE|CA|IT|FR|JN|SP|NE|BE|EN)MLES5 | B7: CurveMLES_5_9 | C7: QW.Security.Curve.CurveLoaderDB
A8: (GE|CA|IT|FR|JN|SP|NE|BE|EN)MLESF | B8: CurveMLES_F_8 | C8: QW.Security.Curve.CurveLoaderDB
A9: (GE|CA|IT|FR|JN|SP|NE|BE|EN)MLESW2 | B9: CurveMLES_5_9 | C9: QW.Security.Curve.CurveLoaderDB
A10: (GE|CA|IT|FR|JN|SP|NE|BE|EN)MLESW2 | B10: CurveMLES_2_9 | C10: QW.Security.Curve.CurveLoaderDB
A11: (IT)MLESF9 | B11: CurveMLES_F_9 | C11: QW.Security.Curve.CurveLoaderDB
A12: (IT)MLESFL | B12: CurveMLES_F_L | C12: QW.Security.Curve.CurveLoaderDB
... A147: USBUCKETS | B147: CurveBootstrap | C147: QW.Security.Curve.CurveLoaderActiveSubset
A148: (GE|CA|IT|FR|JN|SP|NE|BE|EN)MLES

Sheet Sheet1
A1: IDPattern | B1: newCurve | C1: Type of Curve
A2: OLD.GC.EUR | B2: Curve | C2: Curve
A3: GC.GBP | B3: Curve | C3: Curve
A4: OLD.GC.EN | B4: Curve | C4: Curve
A5: GC.EN | B5: Curve | C5: Curve
A6: GC.CA | B6: Curve | C6: Curve
A7: (^GC.GE|^GC.FR|^GC.IT|^GC.BE|^GC.IR|^GC.EUR) | B7: Curve | C7: Curve
A8: SOFR | B8: Curve | C8: Curve
A9: SOFR23 | B9: Curve | C9: Curve
A10: SFR3M | B10: Curve | C10: Curve
A11: GC.US | B11: Curve | C11: Curve
A12: VIX | B12: Curve | C12: Curve
... A61: USSW1M | B61: CurveSmooth | C61: QW.Security.Curve.CurveFitByModel
A62: USEDSW_UFLAT | B62: CurveFlatFwd | C62: =VLOOKUP(B62,ICurves!A:C,3,0) -> #N/A
A63: USEDSWFLAT | B63: CurveCalibratedConvexity | C63: QW.Security.Curve.CalibratedConvexityCurve
A64: EUSWF | B64: CurveSmooth | C64: QW.Security.Curve.CurveFitByModel
A65: EUEDSW_U | B65: CurveSmooth | C65: QW.Security.Curve.CurveFitByModel
A66: EUEDSW | B66: CurveCalibratedConvexity | C66: QW.Security.Curve.CalibratedConvexityCurve
A67: BPSWF | B67: CurveSmooth | C67: QW.Security.Curve.CurveFitByModel
A68: BPEDSW_U | B68: CurveSmooth | C68: QW.Security.Curve.CurveFitByModel
A69: BPEDSW | B69: CurveCalibratedConvexity | C69: QW.Security.Curve.CalibratedConvexityCurve
A70: NORMED | B70: CurveFlatForward | C70: =VLOOKUP(B70,ICurves!A:C,3,0) -> QW.Security.Curve.Curve
A71: QWUSIBOR | B71: CurveScenario | C71: QW.Security.Curve.CurveFitByModel
A72: QWANNUALFWD | B72: CurveScenario | C72: QW.Security.Curve.CurveFitByModel
A73: QWSEMIFWD | B73: CurveScenario | C73: QW.Security.Curve.CurveFitByModel
A74: QWANNUALSPOT | B74: CurveScenario | C74: QW.Security.Curve.CurveFitByModel
A75: QWSEMISPOT | B75: CurveScenario | C75: QW.Security.Curve.CurveFitByModel
A76: QWUSIBORCT | B76: CurveScenario | C76: QW.Security.Curve.CurveFitByModel
A77: QWBPIBOR | B77: CurveScenario | C77: QW.Security.Curve.CurveFitByModel
A78: QWEUIBOR | B78: CurveScenario | C78: QW.Security.Curve.CurveFitByModel
A79: AUDLIBORSWAP | B79: CurveSmooth | C79: QW.Security.Curve.CurveFitByModel
A80: CADLIBORSWAP | B80: CurveBootstrap | C80: QW.Security.Curve.Curve
A81: HKDLIBORSWAP | B81: CurveSmooth | C81: QW.Security.Curve.CurveFitByModel
A82: KRWSWAP | B82: CurveSmooth | C82: QW.Security.Curve.CurveFitByModel
... A122: OISFFLIBOR | B122: CurveBasis | C122: QW.Security.Curve.BasisCurve
A123: USMLES | B123: CurveMLES_Opt_9 | C123: #N/A
A124: (GE|CA|IT|FR|JN|SP|NE|BE|EN)MLES | B124: CurveMLES_Opt_9 | C124: #N/A
A125: USMLESQ | B125: CurveMLES_5_9 | C125: QW.Security.Curve.CurveFitByModel
A126: USBUCKETS | B126: CurveBootstrap | C126: QW.Security.Curve.Curve
A127: USACTIVESP | B127: CurveBootstrap | C127: QW.Security.Curve.Curve
...

Sheet ICurves
A1: Alias | B1: object id | C1: Icurve Type | D1: ICurveFitter Type | E1: isUsed
A2: Curve | B2: CurveFlatForward | C2: QW.Security.Curve.Curve | D2: CurveFitter | E2: =VLOOKUP(A2,Loader!B:B,1,0) -> Curve
A3: CurveFlatForward | B3: CurveFlatForward | C3: QW.Security.Curve.Curve | D3: CurveFitter | E3: =VLOOKUP(A3,Loader!B:B,1,0) -> CurveFlatForward
A4: CurveBootstrap | B4: CurveBootstrap | C4: QW.Security.Curve.Curve | D4: CurveFitterBootstrap | E4: =VLOOKUP(A4,Loader!B:B,1,0) -> CurveBootstrap
A5: RepoCurve | B5: RepoCurve | C5: QW.Security.Curve.Curve | D5: CurveFitter | E5: =VLOOKUP(A5,Loader!B:B,1,0) -> RepoCurve
A6: CurveMLES_2_9 | B6: CurveMLES_2_9 | C6: QW.Security.Curve.CurveFitByModel | D6: StubTerms=1d, Alpha=0.02, Degree=9, WeightAtt=1.0/Math.Pow($this.DV01,2.0) | E6: =VLOOKUP(A6,Loader!B:B,1,0) -> CurveMLES_2_9
A7: CurveMLES_F_L | B7: CurveMLES_F_L | C7: QW.Security.Curve.CurveFitByModel | D7: StubTerms=1d,Alpha=0.05, Degree=9,TargetTerm=60,AlphaFromLast=true, WeightAtt=1.0/Math.Pow($this.DV01,2.0) | E7: =VLOOKUP(A7,Loader!B:B,1,0) -> CurveMLES_F_L
A8: CurveMLES_F_8 | B8: CurveMLES_F_8 | C8: QW.Security.Curve.CurveFitByModel | D8: StubTerms=1d, Alpha=0.05, Degree=8, WeightAtt=1.0/Math.Pow($this.DV01,2.0) | E8: =VLOOKUP(A8,Loader!B:B,1,0) -> CurveMLES_F_8
A9: CurveMLES_F_9 | B9: CurveMLES_F_9 | C9: QW.Security.Curve.CurveFitByModel | D9: StubTerms=1d, Alpha=0.05, Degree=9, WeightAtt=1.0/Math.Pow($this.DV01,2.0) | E9: =VLOOKUP(A9,Loader!B:B,1,0) -> CurveMLES_F_9
A10: CurveMLES_F_9_NG | B10: CurveMLES_F_9_NG | C10: QW.Security.Curve.CurveFitByModel | D10: None | E10: =VLOOKUP(A10,Loader!B:B,1,0) -> #N/A
A11: CurveMLES_2_15 | B11: CurveMLES_2_15 | C11: QW.Security.Curve.CurveFitByModel | D11: Alpha=0.02, Degree=15, WeightAtt=1.0/Math.Pow($this.DV01,2.0) | E11: =VLOOKUP(A11,Loader!B:B,1,0) -> #N/A
A12: CurveMLES_2_12 | B12: CurveMLES_2_12 | C12: QW.Security.Curve.CurveFitByModel | D12: Alpha=0.02, Degree=12, WeightAtt=1.0/Math.Pow($this.DV01,2.0) | E12: =VLOOKUP(A12,Loader!B:B,1,0) -> #N/A
A13: CurveMLES_4_15 | B13: CurveMLES_4_15 | C13: QW.Security.Curve.CurveFitByModel | D13: Alpha=0.04, Degree=15, WeightAtt=1.0/Math.Pow($this.DV01,2.0) | E13: =VLOOKUP(A13,Loader!B:B,1,0) -> #N/A
... A22: CurveZS | B22: CurveZS | C22: QW.Security.Curve.CurveFitByModel | D22: CurveFitterZS | E22: =VLOOKUP(A22,Loader!B:B,1,0) -> CurveZS
A23: CurveScenario | B23: CurveSmooth | C23: QW.Security.Curve.CurveFitByModel | D23: =D17 -> Alpha=0.04, Degree=15, WeightAtt=1.0/Math.Pow($this.DV01,2.0) | E23: =VLOOKUP(A23,Loader!B:B,1,0) -> CurveScenario
A24: CurveCalibratedConvexity | B24: CurveCalibratedConvexity | C24: QW.Security.Curve.CalibratedConvexityCurve | D24: None car herite pas de Curve | E24: =VLOOKUP(A24,Loader!B:B,1,0) -> CurveCalibratedConvexity
A25: CurveNSS | B25: CurveNSS | C25: QW.Security.Curve.CurveFitByModelOpt | D25: CurveFitterNSSFast | E25: =VLOOKUP(A25,Loader!B:B,1,0) -> CurveNSS
A26: CurveNS | B26: CurveNS | C26: QW.Security.Curve.CurveFitByModelOpt | D26: CurveFitterNSFast | E26: =VLOOKUP(A26,Loader!B:B,1,0) -> CurveNS
A27: CurveMLES_Opt_9 | B27: CurveMLES_Opt_9 | C27: QW.Security.Curve.CurveFitByModelOpt | D27: CurveFitterMLES_Opt_9 | E27: =VLOOKUP(A27,Loader!B:B,1,0) -> CurveMLES_Opt_9
A28: CurveBasis | B28: CurveBasis | C28: QW.Security.Curve.BasisCurve | D28: Alpha=0.04, Degree=15, WeightAtt=1.0/Math.Pow($this.DV01,2.0) | E28: =VLOOKUP(A28,Loader!B:B,1,0) -> CurveBasis

Sheet ICurveFitter
A1: Fitter | B1: Type | C1: Heritag | D1: Model
A2: CurveFitter | B2: QW.Framework.Spring.AddSuffixFactoryObject | C2: ICurveFitter | D2: AddRateDFs, AddFutureDFs, AddSwapDFs
A3: CurveFitterBootstrap | B3: QW.Security.Curve.CurveFitterBootstrap | C3: ICurveFitter | D3: AddBondDFs and AddSwapDFs
A4: CurveFitterNSL | B4: QW.Security.Curve.CurveFitterModel | C4: ICurveFitterModel | D4: NSLocked
A5: CurveFitterZS | B5: QW.Security.Curve.CurveFitterModel | C5: ICurveFitterModel | D5: ZeroSpline
A6: CurveFitterNSSFast | B6: QW.Security.Curve.CurveFitterOptimize | C6: ICurveFitterModel | D6: NSSFast
A7: CurveFitterNSFast | B7: QW.Security.Curve.CurveFitterOptimize | C7: ICurveFitterModel | D7: NSFast
A8: CurveFitterMLES_Opt_9 | B8: QW.Security.Curve.CurveFitterOptimize | C8: ICurveFitterModel | D8: MLESFunc_5_9

Sheet DiscountFunction
A1: NSSFast | B1: NSSFast | C1: QW.Security.Curve.NSSFast | D1: None car herite de zeroFit | E1: =VLOOKUP(A1,Loader!B:B,1,0) -> #N/A
A2: NSFast | B2: NSFast | C2: QW.Security.Curve.NSSFast | D2: None car herite de zeroFit | E2: =VLOOKUP(A2,Loader!B:B,1,0) -> #N/A
A3: NSLocked | B3: NSFast | C3: QW.Security.Curve.NSSFast | D3: None car herite de zeroFit | E3: =VLOOKUP(A3,Loader!B:B,1,0) -> #N/A
B4: ZeroSpline | C4: QW.Security.Curve.ZeroSpline | D4: None car herite de zeroFit | E4: =VLOOKUP(A4,Loader!B:B,1,0) -> #N/A

Sheet FXCurve
B1: 41554
B2: 41555 | J2: EUR/USD | K2: 1.3578
B3: 41556 | I3: Fxinstant | K3: =K2-M7-M8 -> 1.3577915
I4: Fxinstant | K4: =K2*E5/E6 -> 1.3577915
D5: DF(USD, 09/10/2013) | E5: 0.99998969
A6: ON | D6: DF(EUR, 09/10/2013) | E6: 0.99999592 | I6: aturity | J6: Couple | K6: Master | L6: Calendar | M6: Rate | N6: Begin | O6: End
A7: 1W | D7: DF*(EUR/USD, 09/10/2013 | E7: =E6*K3/K2 -> 0.99998969 | I7: ON | J7: EUR/USD | K7: EUTA | L7: USNY | M7: 4.75e-06 | N7: 41465 | O7: 41496
I8: TN | J8: EUR/USD | K8: EUTA | L8: USNY | M8: 3.7e-06 | N8: 41496 | O8: 41527
D9: DF(USD, 16/10/2013) | E9: 0.99992861 | I9: 1W | J9: EUR/USD | K9: EUTA | L9: USNY | M9: 2.35e-05 | N9: 41527 | O9: 16/10/2013 | P9: =K2+M9 -> 1.3578235
D10: DF(EUR, 16/10/2013) | E10: 0.99997667 | I10: 2W | J10: EUR/USD | K10: EUTA | L10: USNY | M10: 4.85e-05 | N10: 41527 | O10: 23/10/2013
I11: 3W | J11: EUR/USD | K11: EUTA | L11: USNY | M11: 7.1e-05 | N11: 41527 | O11: 30/10/2013
I12: 1M | J12: EUR/USD | K12: EUTA | L12: USNY | M12: 0.0001195 | N12: 41527 | O12: 41619
D13: Ma formule | E13: =P9/K2*E6/E5*E9 -> 0.99995214 | I13: 2M | J13: EUR/USD | K13: EUTA | L13: USNY | M13: 0.0002245 | N13: 41527 | O13: 41529
D14: Formule du pdf | E14: =E10/(1+M9/K2)*E5/E6 -> 0.99995314 | I14: 3M | J14: EUR/USD | K14: EUTA | L14: USNY | M14: 0.0003 | N14: 41527 | O14: 41883
I15: 4M | J15: EUR/USD | K15: EUTA | L15: USNY | M15: 0.0041 | N15: 41527 | O15: 41914
I16: 5M | J16: EUR/USD | K16: EUTA | L16: USNY | M16: 0.000505 | N16: 41527 | O16: 41915
I17: 6M | J17: EUR/USD | K17: EUTA | L17: USNY | M17: 0.00635 | N17: 41527 | O17: 41886
I18: 7M | J18: EUR/USD | K18: EUTA | L18: USNY | M18: 0.0007575 | N18: 41527 | O18: 41887
I19: 8M | J19: EUR/USD | K19: EUTA | L19: USNY | M19: 0.000895 | N19: 41527 | O19: 41888
I20: 9M | J20: EUR/USD | K20: EUTA | L20: USNY | M20: 0.001025 | N20: 41527 | O20: 41889
I21: 10M | J21: EUR/USD | K21: EUTA | L21: USNY | M21: 0.001175 | N21: 41527 | O21: 41951
I22: 11M | J22: EUR/USD | K22: EUTA | L22: USNY | M22: 0.001335 | N22: 41527 | O22: 41891
I23: 1Y | J23: EUR/USD | K23: EUTA | L23: USNY | M23: 0.0015 | N23: 41527 | O23: 41892
I24: 18M | J24: EUR/USD | K24: EUTA | L24: USNY | M24: 0.0028 | N24: 41527 | O24: 42251
I25: 2Y | J25: EUR/USD | K25: EUTA | L25: USNY | M25: 0.004798 | N25: 41527 | O25: 42257
I26: 3Y | J26: EUR/USD | K26: EUTA | L26: USNY | M26: 0.012871 | N26: 41527 | O26: 42684
... I33: 10Y | J33: EUR/USD | K33: EUTA | L33: USNY | M33: 0.14391 | N33: 41527 | O33: 45209
