Workbook

Sheet 1085913817 MMFuture
B1: TradeID (equivalent du JMS) | C1: 1085913817
B2: TradeDate | C2: 46064
B3: Date | C3: 46134
B4: Description | C4: 3-Mon SOFR JUN26
B5: Instrument Id (equivalent du BDRId) | C5: 96739479
B6: Instrument Type | C6: Future | F6: 45946 | G6: sell | H6: 96.835 | I6: -95
B7: Notional Quantity | C7: -63 | F7: 46064 | G7: buy | H7: 96.55 | I7: 32
B8: Native Average Cost | C8: =H6 -> 96.835
B9: Fair Value | C9: 96.3325
B10: Native NMV | C10: 79143.75
A11: BookNMV | B11: $ NMV | C11: 79143.75
A12: DirtyNMV | B12: Dirty NMV | C12: 79143.75
A13: BookDirtyNMV | B13: $ Dirty NMV | C13: 79143.75
A14: BookPNLReferenceDate | B14: $ P&L | C14: 101943.75 | D14: =D15+D44 -> 101943.75
A15: BookTotalNPV_ReferenceDate | B15: $ Total Unrealized | C15: 79143.75 | D15: =2500*(C7)*(C9-C8) -> 79143.75
A16: BookNPV_ReferenceDate | B16: $ Trading Unrealized | C16: 79143.75 | D16: =2500*(C7)*(C9-C8) -> 79143.75
A17: BookFXUnrealized_ReferenceDate | B17: $ FX Unrealized Contribution | C17: 0
A18: BookAccruedInterest | B18: $ Accrued Interest | C18: 0
A19: BookTRSAccruedInterest | B19: $ Financing Accrued Interest | C19: 0
A20: BookUnrealizedFeesAndCommissions | B20: $ Unrealized Fees and Commissions | C20: 0
A21: BookAccruedDividendFees | B21: $ Accrued Dividends Fees | C21: 0
A22: BookAccruedDividendsWithholdingTax | B22: $ Accrued Dividends Withholding Tax | C22: 0
A23: BookAccruedDividends | B23: $ Accrued Dividends | C23: 0
A24: TRSFXAdjustment | B24: TRS FX Unrealized Adjustment | C24: 0
A25: BookAccruedCostOfCarry | B25: $ Accrued Cost Of Carry | C25: 0
A26: BookAccruedDelayedCompensation | B26: $ Accrued Delayed Compensation | C26: 0
A27: BookOtherAccruedInterest | B27: $ Other Accrued Interest | C27: 0
A28: BookOtherAccruedDividends | B28: $ Other Accrued Dividends | C28: 0
... A43: BookPNLUnrealizedAdjustment | B43: $ P&L Unrealized Adjustment | C43: 0
A44: BookTotalRealized_ReferenceDate | B44: $ Total Realized Reference Date | C44: 22800 | D44: =SUM(D45:D66) -> 22800
A45: BookTradingRealized_ReferenceDate | B45: $ Trading Realized | C45: 22800 | D45: =(H6-H7)*I7*2500 -> 22800
A46: BookFXRealized_ReferenceDate | B46: $ FX Realized | C46: 0
A47: BookRealizedAccruedInterest | B47: $ Realized Accrued Interest | C47: 0
A48: BookInterest | B48: $ Interest | C48: 0
A49: BookUnsettledTRSEarnedInterest | B49: $ Unsettled Financing Interest | C49: 0
A50: BookTRSEarnedInterest | B50: $ Financing Interest | C50: 0
A51: BookRealizedCommissions | B51: $ Realized Commissions | C51: 0
A52: BookRealizedFees | B52: $ Realized Fees | C52: 0
A53: BookRealizedTaxes | B53: $ Realized Taxes | C53: 0
A54: BookPaidDividendFees | B54: $ Paid Dividends Fees | C54: 0
...

Sheet GBP Curve
L1: 1
G2: ='GILT Bond at 04-22'!D101 -> ctx.46134.chjkh | K2: {=_xll.qwCurvePrice('GILT Bond at 04-22'!D101,E7,G3)} -> 74.225501 | O2: =SUM(M:M) -> 74.472619
G3: {=_xll.qwRelevantCurve('GILT Bond at 04-22'!D101,'GILT Bond at 04-22'!D5)} -> GB00BLPK7334
G4: {=_xll.qwCurveCouponYieldImpact('GILT Bond at 04-22'!D101,E7,G3)} -> -0.00017772184
B5: {=_xll.qwCurveYield('GILT Bond at 04-22'!D101,E7,'GILT Bond at 04-22'!D5)} -> 0.036707025 | G5: ='GILT Bond at 04-22'!B8 -> 155300000 | AA5: SoniaSwap
G6: {=_xll.qwBondDV01Calc(G3,'GILT Bond at 04-22'!D1,'GILT Bond at 04-22'!B92)} -> 0.071335563 | H6: =G6*G5 -> 11078413 | AA6: {=_xll.qwCurveBenchmarks('GILT Bond at 04-22'!D101,AA5)} -> BPSWS1Z
E7: {=_xll.qwCurveNew('GILT Bond at 04-22'!D101,"SoniaSwap",_xlfn.ANCHORARRAY(AA6))} -> CRV.SONIASWAP | G7: {=_xll.qwCurveZSpread('GILT Bond at 04-22'!D101,E7,'GILT Bond at 04-22'!D5)*0} -> 0 | K7: {=_xll.qwBondAccruedInterest(G2,'GILT Bond at 04-22'!D5)} -> 0.25483425 | AA7: BPSWS2Z
AA8: BPSWSA
K9: {=_xll.qwBondDirtyPrice(G2,'GILT Bond at 04-22'!D5)} -> 63.078834 | AA9: BPSWSB
AA10: BPSWSC
AA11: BPSWSD
C12: ='GILT Bond at 04-22'!D1 -> 46134 | D12: {=_xll.qwCurveDF('GILT Bond at 04-22'!$D$101,$E$7,$C$12,C12)} -> 1 | E12: {=_xll.qwCurveRateZero('GILT Bond at 04-22'!$D$101,$E$7,$C$14,C12)} -> 0.037812233 | AA12: BPSWSE
C13: =C12+1 -> 46135 | D13: {=_xll.qwCurveDF('GILT Bond at 04-22'!$D$101,$E$7,$C$12,C13)} -> 0.9998964 | E13: {=_xll.qwCurveRateZero('GILT Bond at 04-22'!$D$101,$E$7,$C$14,C13)} -> 0.037814192 | F13: {=_xll.qwCurveSpreadSet('GILT Bond at 04-22'!D101,E7,C13,C21,G7)} -> 0 | I13: {=_xll.qwCashFlows('GILT Bond at 04-22'!D101,'GILT Bond at 04-22'!D5)} -> 46135 | J13: -63.078834 | AA13: BPSWSF
C14: =C13+1 -> 46136 | D14: {=_xll.qwCurveDF('GILT Bond at 04-22'!$D$101,$E$7,$C$12,C14)} -> 0.99979281 | E14: {=_xll.qwCurveRateZero('GILT Bond at 04-22'!$D$101,$E$7,$C$14,C14)} -> #NUM! | I14: 46234 | J14: 0.5625 | K14: {=_xll.qwCurveRateZero('GILT Bond at 04-22'!$D$101,$E$7,$C$12,I14)} -> 0.03891336 | L14: =1/(1+(K14+$G$7/10000)*(I14-$C$12)/365) -> 0.98945127 | M14: =L14*J14 -> 0.55656634 | AA14: BPSWSG
C15: =C14+1 -> 46137 | D15: {=_xll.qwCurveDF('GILT Bond at 04-22'!$D$101,$E$7,$C$12,C15)} -> 0.99968923 | E15: {=_xll.qwCurveRateZero('GILT Bond at 04-22'!$D$101,$E$7,$C$14,C15)} -> 0.03781811 | I15: 46419 | J15: 0.5625 | K15: {=_xll.qwCurveRateZero('GILT Bond at 04-22'!$D$101,$E$7,$C$12,I15)} -> 0.041431096 | L15: =1/(1+(K15+$G$7/10000)*(I15-$C$12)/365) -> 0.96866344 | M15: =L15*J15 -> 0.54487318 | AA15: BPSWSH
C16: =C15+1 -> 46138 | D16: {=_xll.qwCurveDF('GILT Bond at 04-22'!$D$101,$E$7,$C$12,C16)} -> 0.99958566 | E16: {=_xll.qwCurveRateZero('GILT Bond at 04-22'!$D$101,$E$7,$C$14,C16)} -> 0.037820069 | I16: 46601 | J16: 0.5625 | K16: {=_xll.qwCurveRateZero('GILT Bond at 04-22'!$D$101,$E$7,$C$12,I16)} -> 0.04213075 | L16: =1/(1+(K16+$G$7/10000)*(I16-$C$12)/365) -> 0.94885278 | M16: =L16*J16 -> 0.53372969 | AA16: BPSWSI
C17: =C16+1 -> 46139 | D17: {=_xll.qwCurveDF('GILT Bond at 04-22'!$D$101,$E$7,$C$12,C17)} -> 0.9994821 | E17: {=_xll.qwCurveRateZero('GILT Bond at 04-22'!$D$101,$E$7,$C$14,C17)} -> 0.037822029 | I17: 46783 | J17: 0.5625 | K17: {=_xll.qwCurveRateZero('GILT Bond at 04-22'!$D$101,$E$7,$C$12,I17)} -> 0.042225557 | L17: =1/(1+(K17+$G$7/10000)*(I17-$C$12)/365) -> 0.93016289 | M17: =L17*J17 -> 0.52321663 | AA17: BPSWSJ
C18: =C17+1 -> 46140 | D18: {=_xll.qwCurveDF('GILT Bond at 04-22'!$D$101,$E$7,$C$12,C18)} -> 0.99937856 | E18: {=_xll.qwCurveRateZero('GILT Bond at 04-22'!$D$101,$E$7,$C$14,C18)} -> 0.037823988 | I18: 46965 | J18: 0.5625 | K18: {=_xll.qwCurveRateZero('GILT Bond at 04-22'!$D$101,$E$7,$C$12,I18)} -> 0.042091067 | L18: =1/(1+(K18+$G$7/10000)*(I18-$C$12)/365) -> 0.91255093 | M18: =L18*J18 -> 0.5133099 | AA18: BPSWSK
C19: =C18+1 -> 46141 | D19: {=_xll.qwCurveDF('GILT Bond at 04-22'!$D$101,$E$7,$C$12,C19)} -> 0.99927502 | E19: {=_xll.qwCurveRateZero('GILT Bond at 04-22'!$D$101,$E$7,$C$14,C19)} -> 0.037825948 | I19: 47149 | J19: 0.5625 | K19: {=_xll.qwCurveRateZero('GILT Bond at 04-22'!$D$101,$E$7,$C$12,I19)} -> 0.041970377 | L19: =1/(1+(K19+$G$7/10000)*(I19-$C$12)/365) -> 0.89548592 | M19: =L19*J19 -> 0.50371083 | AA19: BPSWS1
C20: =C19+1 -> 46142 | D20: {=_xll.qwCurveDF('GILT Bond at 04-22'!$D$101,$E$7,$C$12,C20)} -> 0.99917152 | E20: {=_xll.qwCurveRateZero('GILT Bond at 04-22'!$D$101,$E$7,$C$14,C20)} -> 0.037826601 | I20: 47330 | J20: 0.5625 | K20: {=_xll.qwCurveRateZero('GILT Bond at 04-22'!$D$101,$E$7,$C$12,I20)} -> 0.041914628 | L20: =1/(1+(K20+$G$7/10000)*(I20-$C$12)/365) -> 0.87924287 | M20: =L20*J20 -> 0.49457411 | AA20: BPSWS1F
C21: =C20+1 -> 46143 | D21: {=_xll.qwCurveDF('GILT Bond at 04-22'!$D$101,$E$7,$C$12,C21)} -> 0.99906802 | E21: {=_xll.qwCurveRateZero('GILT Bond at 04-22'!$D$101,$E$7,$C$14,C21)} -> 0.037827628 | I21: 47514 | J21: 0.5625 | K21: {=_xll.qwCurveRateZero('GILT Bond at 04-22'!$D$101,$E$7,$C$12,I21)} -> 0.041909592 | L21: =1/(1+(K21+$G$7/10000)*(I21-$C$12)/365) -> 0.86322039 | M21: =L21*J21 -> 0.48556147 | AA21: BPSWS2
C22: =C21+1 -> 46144 | D22: {=_xll.qwCurveDF('GILT Bond at 04-22'!$D$101,$E$7,$C$12,C22)} -> 0.99896373 | E22: {=_xll.qwCurveRateZero('GILT Bond at 04-22'!$D$101,$E$7,$C$14,C22)} -> 0.037866225 | I22: 47695 | J22: 0.5625 | K22: {=_xll.qwCurveRateZero('GILT Bond at 04-22'!$D$101,$E$7,$C$12,I22)} -> 0.041969625 | L22: =1/(1+(K22+$G$7/10000)*(I22-$C$12)/365) -> 0.84782261 | M22: =L22*J22 -> 0.47690022 | AA22: BPSWS3
C23: =C22+1 -> 46145 | D23: {=_xll.qwCurveDF('GILT Bond at 04-22'!$D$101,$E$7,$C$12,C23)} -> 0.99885944 | E23: {=_xll.qwCurveRateZero('GILT Bond at 04-22'!$D$101,$E$7,$C$14,C23)} -> 0.037896688 | I23: 47879 | J23: 0.5625 | K23: {=_xll.qwCurveRateZero('GILT Bond at 04-22'!$D$101,$E$7,$C$12,I23)} -> 0.042080649 | L23: =1/(1+(K23+$G$7/10000)*(I23-$C$12)/365) -> 0.83251463 | M23: =L23*J23 -> 0.46828948 | AA23: BPSWS4
C24: =C23+1 -> 46146 | D24: {=_xll.qwCurveDF('GILT Bond at 04-22'!$D$101,$E$7,$C$12,C24)} -> 0.99875516 | E24: {=_xll.qwCurveRateZero('GILT Bond at 04-22'!$D$101,$E$7,$C$14,C24)} -> 0.037921456 | I24: 48060 | J24: 0.5625 | K24: {=_xll.qwCurveRateZero('GILT Bond at 04-22'!$D$101,$E$7,$C$12,I24)} -> 0.042234785 | L24: =1/(1+(K24+$G$7/10000)*(I24-$C$12)/365) -> 0.81775456 | M24: =L24*J24 -> 0.45998694 | AA24: BPSWS5
C25: =C24+1 -> 46147 | D25: {=_xll.qwCurveDF('GILT Bond at 04-22'!$D$101,$E$7,$C$12,C25)} -> 0.99865089 | E25: {=_xll.qwCurveRateZero('GILT Bond at 04-22'!$D$101,$E$7,$C$14,C25)} -> 0.037942084 | I25: 48246 | J25: 0.5625 | K25: {=_xll.qwCurveRateZero('GILT Bond at 04-22'!$D$101,$E$7,$C$12,I25)} -> 0.042429853 | L25: =1/(1+(K25+$G$7/10000)*(I25-$C$12)/365) -> 0.80288272 | M25: =L25*J25 -> 0.45162153 | AA25: BPSWS6
... C27: =C26+1 -> 46149 | D27: {=_xll.qwCurveDF('GILT Bond at 04-22'!$D$101,$E$7,$C$12,C27)} -> 0.99844255 | E27: {=_xll.qwCurveRateZero('GILT Bond at 04-22'!$D$101,$E$7,$C$14,C27)} -> 0.037970372 | I27: 48610 | J27: 0.5625 | K27: {=_xll.qwCurveRateZero('GILT Bond at 04-22'!$D$101,$E$7,$C$12,I27)} -> 0.042896455 | L27: =1/(1+(K27+$G$7/10000)*(I27-$C$12)/365) -> 0.77459889 | M27: =L27*J27 -> 0.43571188 | AA27: BPSWS8
C28: =I39 -> 50801 | D28: {=_xll.qwCurveDF('GILT Bond at 04-22'!$D$101,$E$7,$C$12,C28)} -> 0.62909473 | E28: {=_xll.qwCurveRateZero('GILT Bond at 04-22'!$D$101,$E$7,$C$14,C28)} -> 0.046104732 | I28: 48792 | J28: 0.5625 | K28: {=_xll.qwCurveRateZero('GILT Bond at 04-22'!$D$101,$E$7,$C$12,I28)} -> 0.043160593 | L28: =1/(1+(K28+$G$7/10000)*(I28-$C$12)/365) -> 0.76085915 | M28: =L28*J28 -> 0.42798327 | AA28: BPSWS9
I29: 48975 | J29: 0.5625 | K29: {=_xll.qwCurveRateZero('GILT Bond at 04-22'!$D$101,$E$7,$C$12,I29)} -> 0.043442865 | L29: =1/(1+(K29+$G$7/10000)*(I29-$C$12)/365) -> 0.74730584 | M29: =L29*J29 -> 0.42035954 | AA29: BPSWS10
I30: 49156 | J30: 0.5625 | K30: {=_xll.qwCurveRateZero('GILT Bond at 04-22'!$D$101,$E$7,$C$12,I30)} -> 0.043724776 | L30: =1/(1+(K30+$G$7/10000)*(I30-$C$12)/365) -> 0.73420513 | M30: =L30*J30 -> 0.41299038 | AA30: BPSWS12
I31: 49340 | J31: 0.5625 | K31: {=_xll.qwCurveRateZero('GILT Bond at 04-22'!$D$101,$E$7,$C$12,I31)} -> 0.044016596 | L31: =1/(1+(K31+$G$7/10000)*(I31-$C$12)/365) -> 0.72117682 | M31: =L31*J31 -> 0.40566196 | AA31: BPSWS15
I32: 49521 | J32: 0.5625 | K32: {=_xll.qwCurveRateZero('GILT Bond at 04-22'!$D$101,$E$7,$C$12,I32)} -> 0.044302212 | L32: =1/(1+(K32+$G$7/10000)*(I32-$C$12)/365) -> 0.70866687 | M32: =L32*J32 -> 0.39862511 | AA32: BPSWS20
I33: 49705 | J33: 0.5625 | K33: {=_xll.qwCurveRateZero('GILT Bond at 04-22'!$D$101,$E$7,$C$12,I33)} -> 0.044594452 | L33: =1/(1+(K33+$G$7/10000)*(I33-$C$12)/365) -> 0.69623698 | M33: =L33*J33 -> 0.3916333 | AA33: BPSWS25
I34: 49887 | J34: 0.5625 | K34: {=_xll.qwCurveRateZero('GILT Bond at 04-22'!$D$101,$E$7,$C$12,I34)} -> 0.044863839 | L34: =1/(1+(K34+$G$7/10000)*(I34-$C$12)/365) -> 0.68432283 | M34: =L34*J34 -> 0.38493159 | AA34: BPSWS30
I35: 50073 | J35: 0.5625 | K35: {=_xll.qwCurveRateZero('GILT Bond at 04-22'!$D$101,$E$7,$C$12,I35)} -> 0.045127071 | L35: =1/(1+(K35+$G$7/10000)*(I35-$C$12)/365) -> 0.6724943 | M35: =L35*J35 -> 0.37827804 | AA35: BPSWS40
I36: 50252 | J36: 0.5625 | K36: {=_xll.qwCurveRateZero('GILT Bond at 04-22'!$D$101,$E$7,$C$12,I36)} -> 0.045395772 | L36: =1/(1+(K36+$G$7/10000)*(I36-$C$12)/365) -> 0.66130402 | M36: =L36*J36 -> 0.37198351 | AA36: BPSWS50
I37: 50437 | J37: 0.5625 | K37: {=_xll.qwCurveRateZero('GILT Bond at 04-22'!$D$101,$E$7,$C$12,I37)} -> 0.045687948 | L37: =1/(1+(K37+$G$7/10000)*(I37-$C$12)/365) -> 0.64993428 | M37: =L37*J37 -> 0.36558804
I38: 50619 | J38: 0.5625 | K38: {=_xll.qwCurveRateZero('GILT Bond at 04-22'!$D$101,$E$7,$C$12,I38)} -> 0.045918504 | L38: =1/(1+(K38+$G$7/10000)*(I38-$C$12)/365) -> 0.63929157 | M38: =L38*J38 -> 0.35960151
I39: 50801 | J39: 100.5625 | K39: {=_xll.qwCurveRateZero('GILT Bond at 04-22'!$D$101,$E$7,$C$12,I39)} -> 0.046110732 | L39: =1/(1+(K39+$G$7/10000)*(I39-$C$12)/365) -> 0.62909473 | M39: =L39*J39 -> 63.263339

Sheet Sheet1

Sheet GILT Bond at 04-22
A1: ValueDate | B1: 46133 | D1: 46134
A2: Maturity Date | B2: 50801 | D2: 50801
A3: TradeID | B3: 1096094587 | D3: 1096094587 | G3: Total Pnl in $ | H3: =E14-C14 -> 50614.885 | J3: GBP/USD at 25/11/2025 | K3: 1.3211
A4: TradeDate | B4: 46072 | D4: 46072 | J4: GBP/USD at 26/11/2025 | K4: 1.32335 | N4: 45869 | O4: 46053
A5: Description | B5: GBGV 1.125 01/31/39 | D5: GB00BLPK7334 | G5: Native Daily P&L | H5: =E13-C13 -> -6044.6878 | J5: GBP/USD at 27/11/2025 | K5: 1.32375 | N5: =O4 -> 46053 | O5: 46233 | P5: 46234
A6: Instrument Id | B6: 130794850 | D6: 130794850 | G6: $ P&L SB | H6: =H5*K11 -> -8163.9554 | J6: GBP/USD at 02/2/2026 | K6: 1.366
A7: Instrument Type | B7: Bond | D7: Bond | G7: MIG P&L Less Carry | H7: =E17-C17 -> -16764.252 | J7: GBP/USD at 18/02/2026 | K7: 1.3499001
A8: Notional Quantity | B8: 155300000 | D8: 155300000 | G8: Bond Carry | H8: =E19-C19 -> 6720.0837 | J8: GBP/USD at 19/02/2026 | K8: 1.3452
A9: Native Average Cost | B9: 0.65065255 | D9: =(M15*N15+M16*N16)/(N15+N16)/100 -> 0.65065255 | G9: $ P&L | H9: =H7+H8 -> -10044.168 | J9: GBP/USD at 20/02/2026 | K9: 1.34875
A10: Fair Value | B10: 0.62831 | D10: 0.62824 | G10: $ P&L FX | H10: =E18-C18 -> 60627.805 | J10: GBPUSD at 21/04/2026 | K10: 1.35
A11: Native NMV | B11: 97576543 | C11: =C12/K10 -> 97576543 | D11: 97565672 | E11: =E12/K11 -> 97565672 | G11: DV01 | H11: =E81 -> -149551.39 | J11: GBP/USD at 22/04/2026 | K11: 1.3506
A12: $ NMV | B12: 1.3172833e+08 | C12: =B8*B10*K10 -> 1.3172833e+08 | D12: 1.317722e+08 | E12: =D8*D10*K11 -> 1.317722e+08
A13: Dirty NMV | B13: 97967474 | C13: =C11+(B1-O4+1)/(P5-O4)*(N15*0.01125/2)+(B1-O4)/(P5-O4)*((N16)*0.01125/2) -> 97964733 | D13: 97961430 | E13: =E11+(D1-O4+1)/(P5-O4)*(N15*0.01125/2)+(D1-O4)/(P5-O4)*((N16)*0.01125/2) -> 97958689
A14: $ Dirty NMV | B14: 1.3225609e+08 | C14: =C13*K10 -> 1.3225239e+08 | D14: 1.3230671e+08 | E14: =E13*K11 -> 1.32303e+08 | J14: Trade Date | K14: SettleDate | M14: Trade Price | N14: Nominal
A15: $ P&L | B15: -2505323.9 | C15: =C16+C45 -> -2505528.7 | D15: -2454707.3 | E15: =E16+E45 -> -2454945 | J15: 45986 | K15: 45987 | L15: 46054 | M15: 64.5636 | N15: 67100000
A16: $ Total Unrealized | B16: -2701128.2 | C16: =SUM(C17:C44) -> -2701391.3 | D16: -2650511.7 | E16: =SUM(E17:E44) -> -2650807.7 | J16: 46072 | K16: 46073 | M16: 65.4469 | N16: 88200000
A17: $ Trading Unrealized | B17: -4684227.8 | C17: =(B8)*(B10-B9)*K10 -> -4684227.8 | D17: -4700992.1 | E17: =(D8)*(D10-D9)*K11 -> -4700992.1
A18: $ FX Unrealized Contribution | B18: 1529086.9 | C18: =N15*(M15)*(K10-K3)/100+(N16)*(M16)*(K10-K8)/100 -> 1529086.9 | D18: 1589714.7 | E18: =N15*(M15)*(K11-K3)/100+(N16)*(M16)*(K11-K8)/100 -> 1589714.7
A19: $ Accrued Interest | B19: 454012.78 | C19: =C68*K10 -> 453749.64 | D19: 460765.75 | E19: =E68*K11 -> 460469.72
A20: $ Financing Accrued Interest | B20: 0 | D20: 0
A21: $ Unrealized Fees and Commissions | B21: 0 | D21: 0
A22: $ Accrued Dividends Fees | B22: 0 | D22: 0
A23: $ Accrued Dividends Withholding Tax | B23: 0 | D23: 0
A24: $ Accrued Dividends | B24: 0 | D24: 0
A25: TRS FX Unrealized Adjustment | B25: 0 | D25: 0
A26: $ Accrued Cost Of Carry | B26: 0 | D26: 0
A27: $ Accrued Delayed Compensation | B27: 0 | D27: 0
A28: $ Other Accrued Interest | B28: 0 | D28: 0
A29: $ Other Accrued Dividends | B29: 0 | D29: 0
A30: $ Other Accrued Dividends Withholding Tax | B30: 0 | D30: 0
A31: $ Other Financing Accrued Interest | B31: 0 | D31: 0
... A44: $ P&L Unrealized Adjustment | B44: 0 | D44: 0
A45: $ Total Realized Reference Date | B45: 195804.32 | C45: =+C48+C49 -> 195862.65 | D45: 195804.32 | E45: =+E48+E49 -> 195862.65
A46: $ Trading Realized | B46: 0 | D46: 0
A47: $ FX Realized | B47: 0 | D47: 0
A48: $ Realized Accrued Interest | B48: -319775.31 | C48: =C49*(-1+(L15-J15)/179) -> -319716.97 | D48: -319775.31 | E48: =E49*(-1+(L15-J15)/179) -> -319716.97
A49: $ Interest | B49: 515579.62 | C49: =N15*0.01125/2*K6 -> 515579.62 | D49: 515579.62 | E49: =N15*0.01125/2*K6 -> 515579.62
A50: $ Unsettled Financing Interest | B50: 0 | D50: 0
A51: $ Financing Interest | B51: 0 | D51: 0
A52: $ Realized Commissions | B52: 0 | D52: 0
...

Sheet LONG GILT JUN6  at 04-22
A1: ValueDate | B1: 46133 | D1: 46134
A2: Maturity Date | B2: 46199 | D2: 46199
A3: TradeID | B3: 1103462747 | D3: 1103462747
A4: TradeDate | B4: 46133 | D4: 46133
A5: Description | B5: LONG GILT JUN6 | D5: LONG GILT JUN6 | I5: Total Pnl in $ | J5: =E14-C14 -> 19180.104
A6: Instrument Id | B6: 228548439 | D6: 228548439
A7: Instrument Type | B7: Future | D7: Future | I7: Native Daily P&L | J7: =E11-C11 -> 12920
A8: Notional Quantity | B8: -646 | D8: -646 | I8: $ P&L SB | J8: =J7*Q10 -> 17449.752 | P8: GBP/USD au 2/25/2026 | Q8: 1.3551
A9: Native Average Cost | B9: 92.344272 | D9: 92.344272 | I9: MIG P&L Less Carry | J9: =E17-C17 -> 19180.104 | P9: GBPUSD au 21/04/2026 | Q9: 1.35
A10: Fair Value | B10: 87.88 | D10: 87.86 | I10: Bond Carry | J10: 0 | P10: GBP/USD au 4/22/2026 | Q10: 1.3506
A11: Native NMV | B11: 2883920 | C11: =(B10-B9)*1000*B8 -> 2883920 | D11: 2896840 | E11: =(D10-D9)*1000*D8 -> 2896840 | I11: $ P&L | J11: =J9+J10 -> 19180.104
A12: $ NMV | B12: 3893292 | C12: =C11*Q9 -> 3893292 | D12: 3912472.1 | E12: =E11*Q10 -> 3912472.1 | I12: $ P&L FX | J12: 0
A13: Dirty NMV | B13: 2883920 | C13: =(B10-B9)*1000*B8 -> 2883920 | D13: 2896840 | E13: =(D10-D9)*1000*D8 -> 2896840 | I13: DV01 | J13: =-D81 -> -86379.905 | N13: Trade Date | O13: SettletDate | P13: Qte
A14: $ Dirty NMV | B14: 3893292 | C14: =C13*Q9 -> 3893292 | D14: 3912472.1 | E14: =E13*Q10 -> 3912472.1 | N14: 46076 | O14: 46076 | P14: -370 | Q14: 92.35
A15: $ P&L | B15: 3856362 | C15: =C16+C45 -> 3856362 | D15: 3875542.2 | E15: =E16+E45 -> 3875542.2 | N15: 46076 | O15: 46076 | P15: -370 | Q15: 92.34
A16: $ Total Unrealized | B16: 3893292 | C16: =SUM(C17:C44) -> 3893292 | D16: 3912472.1 | E16: =SUM(E17:E44) -> 3912472.1 | N16: 46078 | O16: 46078 | P16: 94 | Q16: 92.639921
A17: $ Trading Unrealized | B17: 3893292 | C17: =C74*Q9 -> 3893292 | D17: 3912472.1 | E17: =E74*Q10 -> 3912472.1
A18: $ FX Unrealized Contribution | B18: 0 | D18: 0
A19: $ Accrued Interest | B19: 0 | D19: 0
A20: $ Financing Accrued Interest | B20: 0 | D20: 0
A21: $ Unrealized Fees and Commissions | B21: 0 | D21: 0
A22: $ Accrued Dividends Fees | B22: 0 | D22: 0
A23: $ Accrued Dividends Withholding Tax | B23: 0 | D23: 0
A24: $ Accrued Dividends | B24: 0 | D24: 0
A25: TRS FX Unrealized Adjustment | B25: 0 | D25: 0
A26: $ Accrued Cost Of Carry | B26: 0 | D26: 0
A27: $ Accrued Delayed Compensation | B27: 0 | D27: 0
A28: $ Other Accrued Interest | B28: 0 | D28: 0
A29: $ Other Accrued Dividends | B29: 0 | D29: 0
... A44: $ P&L Unrealized Adjustment | B44: 0 | D44: 0
A45: $ Total Realized Reference Date | B45: -36929.95 | C45: =SUM(C46:C67) -> -36929.95 | D45: -36929.95 | E45: =SUM(E46:E67) -> -36929.95
A46: $ Trading Realized | B46: -36929.95 | C46: =E73*Q8 -> -36929.95 | D46: -36929.95 | E46: =E73*Q8 -> -36929.95
A47: $ FX Realized | B47: 0 | D47: 0
A48: $ Realized Accrued Interest | B48: 0 | D48: 0
A49: $ Interest | B49: 0 | D49: 0
A50: $ Unsettled Financing Interest | B50: 0 | D50: 0
A51: $ Financing Interest | B51: 0 | D51: 0
A52: $ Realized Commissions | B52: 0 | D52: 0
A53: $ Realized Fees | B53: 0 | D53: 0
A54: $ Realized Taxes | B54: 0 | D54: 0
...
